Workbook

Sheet README
A1: T6-6 · 표 6-6. 행동크기 상한에 따른 단계별 정책가치 변화와 동등성 검정
A2: 논문 인쇄값을 계산 입력으로 쓰지 않고, 선택 실행의 실제 산출물에서 값을 계산한 Excel입니다.
A4: 항목 | B4: 내용
A5: 선택 실행 | B5: V11_FINAL_FROZEN_REPLAY_RESUME
A6: 실행 방식 | B6: FrozenReplay
A7: 논문 항목 읽기 | B7: 논문 DOCX에서 번호·제목·위치만 동적으로 읽음
A8: 논문 위치 | B8: 6.7 파운데이션 모델별 자기 재검토와 외부 정책 참조의 변화 · 인쇄면 83
A9: 관측·집계 단위 | B9: cohort_id + budget_label + component
A10: 선택 조건 | B10: [[{"column": "oracle", "op": "equals", "value": "alpha"}], [{"column": "oracle", "op": "equals", "value": "alpha"}]]
A11: 계산 방법 | B11: 선택 실행 산출물에 명시된 조건을 적용하고 논문 분석단위로 행·열을 정리
A12: 생산 코드 | B12: src/credit_recourse/analysis/c4r_tost_equivalence.py
A13: 실제 입력 산출물 | B13: embedded://selected-run-output/data/analysis/paper_repro/05_extension_e3_e4/e3_c4r_journal/tost_alpha/c4r_tost_interactions_alpha.csv embedded://selected-run-output/data/analysis/paper_repro/05_extension_e3_e4/e3_c4r_journal/tost_alpha/c4r_tost_within_arm_alpha.csv

Sheet SOURCE
A1: T6-6 · 실제 입력 산출물
A2: 선택 실행에서 읽은 실제 중간·최종 산출물입니다. 아래 ANALYSIS가 이 셀들을 직접 참조합니다.
A4: 입력 1: embedded://selected-run-output/data/analysis/paper_repro/05_extension_e3_e4/e3_c4r_journal/tost_alpha/c4r_tost_interactions_alpha.csv
A5: 파일 크기(bytes) | B5: 7640 | C5: 생산 코드 | D5: src/credit_recourse/analysis/c4r_tost_equivalence.py | E5: SHA256 | F5: 6B23FE889E2D671C06781790660CB3270AD2ACAAD50D1BD14BF5287707D9E12B | G5: 읽기 상태 | H5: OK
A6: n_pairs | B6: mean_gap | C6: sd_gap | D6: se_gap | E6: equivalence_margin | F6: alpha | G6: t_lower | H6: p_lower_mean_gt_minus_margin | I6: t_upper | J6: p_upper_mean_lt_plus_margin | K6: p_tost | L6: ci_level | M6: ci_low | N6: ci_high | O6: equivalent | P6: ci_within_margin | Q6: wilcoxon_p_two_sided | R6: mean_outside_margin | S6: decision | T6: test_family | U6: cohort_id | V6: budget_label | W6: reference_budget_label | X6: component | Y6: oracle | Z6: score_column
A7: 575 | B7: 0.051400802 | C7: 0.46767931 | D7: 0.019503576 | E7: 0.109 | F7: 0.05 | G7: 8.2241742 | H7: 6.596074e-16 | I7: -2.9532635 | J7: 0.0016365287 | K7: 0.0016365287 | L7: 0.9 | M7: 0.019268416 | N7: 0.083533189 | O7: True | P7: True | Q7: 0.014084535 | R7: False | S7: PRACTICALLY_EQUIVALENT | T7: finite_minus_unbounded_interaction_vs_zero | U7: gemini31flashlite | V7: 0p75 | W7: unbounded | X7: self_revision | Y7: alpha | Z7: self_revision_alpha
A8: 575 | B8: -0.40338958 | C8: 0.95825028 | D8: 0.039961799 | E8: 0.109 | F8: 0.05 | G8: -7.3667748 | H8: 1 | I8: -12.821985 | J8: 1.4200574e-33 | K8: 1 | L8: 0.9 | M8: -0.46922715 | N8: -0.33755201 | O8: False | P8: False | Q8: 1.0621616e-22 | R8: True | S8: NOT_EQUIVALENT_OR_INCONCLUSIVE | T8: finite_minus_unbounded_interaction_vs_zero | U8: gemini31flashlite | V8: 0p75 | W8: unbounded | X8: reference_content_conditional | Y8: alpha | Z8: reference_content_conditional_alpha
A9: 575 | B9: -0.35198878 | C9: 0.96712961 | D9: 0.040332093 | E9: 0.109 | F9: 0.05 | G9: -6.0247004 | H9: 1 | I9: -11.429825 | J9: 1.0590022e-27 | K9: 1 | L9: 0.9 | M9: -0.41843641 | N9: -0.28554114 | O9: False | P9: False | Q9: 2.1646778e-18 | R9: True | S9: NOT_EQUIVALENT_OR_INCONCLUSIVE | T9: finite_minus_unbounded_interaction_vs_zero | U9: gemini31flashlite | V9: 0p75 | W9: unbounded | X9: package | Y9: alpha | Z9: package_alpha
A10: 575 | B10: 0.051564999 | C10: 0.60579271 | D10: 0.025263302 | E10: 0.109 | F10: 0.05 | G10: 6.3556616 | H10: 2.1161657e-10 | I10: -2.2734558 | J10: 0.011683641 | K10: 0.011683641 | L10: 0.9 | M10: 0.0099433905 | N10: 0.093186608 | O10: True | P10: True | Q10: 0.063373622 | R10: False | S10: PRACTICALLY_EQUIVALENT | T10: finite_minus_unbounded_interaction_vs_zero | U10: gemini31flashlite | V10: 1p27 | W10: unbounded | X10: self_revision | Y10: alpha | Z10: self_revision_alpha
A11: 575 | B11: -0.35723828 | C11: 0.99891879 | D11: 0.041657793 | E11: 0.109 | F11: 0.05 | G11: -5.9589877 | H11: 1 | I11: -11.192102 | J11: 9.7080802e-27 | K11: 1 | L11: 0.9 | M11: -0.42587002 | N11: -0.28860654 | O11: False | P11: False | Q11: 3.3655069e-17 | R11: True | S11: NOT_EQUIVALENT_OR_INCONCLUSIVE | T11: finite_minus_unbounded_interaction_vs_zero | U11: gemini31flashlite | V11: 1p27 | W11: unbounded | X11: reference_content_conditional | Y11: alpha | Z11: reference_content_conditional_alpha
A12: 575 | B12: -0.30567328 | C12: 0.99902758 | D12: 0.04166233 | E12: 0.109 | F12: 0.05 | G12: -4.72065 | H12: 0.99999852 | I12: -9.9531945 | J12: 6.1407127e-22 | K12: 0.99999852 | L12: 0.9 | M12: -0.37431249 | N12: -0.23703406 | O12: False | P12: False | Q12: 4.5164129e-13 | R12: True | S12: NOT_EQUIVALENT_OR_INCONCLUSIVE | T12: finite_minus_unbounded_interaction_vs_zero | U12: gemini31flashlite | V12: 1p27 | W12: unbounded | X12: package | Y12: alpha | Z12: package_alpha
A13: 575 | B13: 0.043286547 | C13: 0.55814093 | D13: 0.023276086 | E13: 0.109 | F13: 0.05 | G13: 6.5426183 | H13: 6.7004313e-11 | I13: -2.8232175 | J13: 0.0024596899 | K13: 0.0024596899 | L13: 0.9 | M13: 0.0049389021 | N13: 0.081634192 | O13: True | P13: True | Q13: 0.045526115 | R13: False | S13: PRACTICALLY_EQUIVALENT | T13: finite_minus_unbounded_interaction_vs_zero | U13: gemini31flashlite | V13: 2p00 | W13: unbounded | X13: self_revision | Y13: alpha | Z13: self_revision_alpha
A14: 575 | B14: -0.32092238 | C14: 0.97699551 | D14: 0.040743529 | E14: 0.109 | F14: 0.05 | G14: -5.2013751 | H14: 0.99999986 | I14: -10.551918 | J14: 3.2674655e-24 | K14: 0.99999986 | L14: 0.9 | M14: -0.38804786 | N14: -0.2537969 | O14: False | P14: False | Q14: 3.9168011e-15 | R14: True | S14: NOT_EQUIVALENT_OR_INCONCLUSIVE | T14: finite_minus_unbounded_interaction_vs_zero | U14: gemini31flashlite | V14: 2p00 | W14: unbounded | X14: reference_content_conditional | Y14: alpha | Z14: reference_content_conditional_alpha
A15: 575 | B15: -0.27763583 | C15: 0.9647974 | D15: 0.040234833 | E15: 0.109 | F15: 0.05 | G15: -4.1912895 | H15: 0.99998394 | I15: -9.6094803 | J15: 1.1283556e-20 | K15: 0.99998394 | L15: 0.9 | M15: -0.34392323 | N15: -0.21134844 | O15: False | P15: False | Q15: 8.3964874e-12 | R15: True | S15: NOT_EQUIVALENT_OR_INCONCLUSIVE | T15: finite_minus_unbounded_interaction_vs_zero | U15: gemini31flashlite | V15: 2p00 | W15: unbounded | X15: package | Y15: alpha | Z15: package_alpha
A16: 575 | B16: -0.14641126 | C16: 0.5080833 | D16: 0.021188538 | E16: 0.109 | F16: 0.05 | G16: -1.7656365 | H16: 0.96100577 | I16: -12.054218 | J16: 2.7507871e-30 | K16: 0.96100577 | L16: 0.9 | M16: -0.18131964 | N16: -0.11150287 | O16: False | P16: False | Q16: 5.1513308e-14 | R16: True | S16: NOT_EQUIVALENT_OR_INCONCLUSIVE | T16: finite_minus_unbounded_interaction_vs_zero | U16: gpt54mini | V16: 0p75 | W16: unbounded | X16: self_revision | Y16: alpha | Z16: self_revision_alpha
A17: 575 | B17: -0.058451251 | C17: 0.81443245 | D17: 0.033964181 | E17: 0.109 | F17: 0.05 | G17: 1.4882958 | H17: 0.06861103 | I17: -4.9302308 | J17: 5.3833193e-07 | K17: 0.06861103 | L17: 0.9 | M17: -0.11440767 | N17: -0.0024948351 | O17: False | P17: False | Q17: 0.19242939 | R17: False | S17: NOT_EQUIVALENT_OR_INCONCLUSIVE | T17: finite_minus_unbounded_interaction_vs_zero | U17: gpt54mini | V17: 0p75 | W17: unbounded | X17: reference_content_conditional | Y17: alpha | Z17: reference_content_conditional_alpha
A18: 575 | B18: -0.20486251 | C18: 0.78464247 | D18: 0.032721853 | E18: 0.109 | F18: 0.05 | G18: -2.9296173 | H18: 0.99823566 | I18: -9.5918318 | J18: 1.3077412e-20 | K18: 0.99823566 | L18: 0.9 | M18: -0.25877217 | N18: -0.15095284 | O18: False | P18: False | Q18: 2.8980121e-11 | R18: True | S18: NOT_EQUIVALENT_OR_INCONCLUSIVE | T18: finite_minus_unbounded_interaction_vs_zero | U18: gpt54mini | V18: 0p75 | W18: unbounded | X18: package | Y18: alpha | Z18: package_alpha
... A24: 575 | B24: -0.13814324 | C24: 0.92731983 | D24: 0.03867191 | E24: 0.109 | F24: 0.05 | G24: -0.75360227 | H24: 0.77430146 | I24: -6.3907688 | J24: 1.708719e-10 | K24: 0.77430146 | L24: 0.9 | M24: -0.2018557 | N24: -0.07443078 | O24: False | P24: False | Q24: 1.2261255e-05 | R24: True | S24: NOT_EQUIVALENT_OR_INCONCLUSIVE | T24: finite_minus_unbounded_interaction_vs_zero | U24: gpt54mini | V24: 2p00 | W24: unbounded | X24: package | Y24: alpha | Z24: package_alpha
A27: 입력 2: embedded://selected-run-output/data/analysis/paper_repro/05_extension_e3_e4/e3_c4r_journal/tost_alpha/c4r_tost_within_arm_alpha.csv
A28: 파일 크기(bytes) | B28: 9457 | C28: 생산 코드 | D28: src/credit_recourse/analysis/c4r_tost_equivalence.py | E28: SHA256 | F28: 478A437DAA582C1F6A30C7B13325FFE5712B5A3565E226087013598EDE353768 | G28: 읽기 상태 | H28: OK
A29: n_pairs | B29: mean_gap | C29: sd_gap | D29: se_gap | E29: equivalence_margin | F29: alpha | G29: t_lower | H29: p_lower_mean_gt_minus_margin | I29: t_upper | J29: p_upper_mean_lt_plus_margin | K29: p_tost | L29: ci_level | M29: ci_low | N29: ci_high | O29: equivalent | P29: ci_within_margin | Q29: wilcoxon_p_two_sided | R29: mean_outside_margin | S29: decision | T29: test_family | U29: cohort_id | V29: budget_label | W29: component | X29: oracle | Y29: score_column
A30: 575 | B30: 0.070328854 | C30: 0.43707825 | D30: 0.018227423 | E30: 0.109 | F30: 0.05 | G30: 9.8384097 | H30: 1.6362046e-21 | I30: -2.1215916 | J30: 0.017149944 | K30: 0.017149944 | L30: 0.9 | M30: 0.040298945 | N30: 0.10035876 | O30: True | P30: True | Q30: 7.7132895e-05 | R30: False | S30: PRACTICALLY_EQUIVALENT | T30: within_arm_component_vs_zero | U30: gemini31flashlite | V30: 0p75 | W30: self_revision | X30: alpha | Y30: self_revision_alpha
A31: 575 | B31: -0.00098336451 | C31: 0.50701197 | D31: 0.021143861 | E31: 0.109 | F31: 0.05 | G31: 5.1086524 | H31: 2.2116054e-07 | I31: -5.201669 | J31: 1.3762068e-07 | K31: 2.2116054e-07 | L31: 0.9 | M31: -0.035818141 | N31: 0.033851412 | O31: True | P31: True | Q31: 0.67705344 | R31: False | S31: PRACTICALLY_EQUIVALENT | T31: within_arm_component_vs_zero | U31: gemini31flashlite | V31: 0p75 | W31: reference_content_conditional | X31: alpha | Y31: reference_content_conditional_alpha
A32: 575 | B32: 0.069345489 | C32: 0.53149198 | D32: 0.022164748 | E32: 0.109 | F32: 0.05 | G32: 8.0463577 | H32: 2.4593471e-15 | I32: -1.7890802 | J32: 0.03706453 | K32: 0.03706453 | L32: 0.9 | M32: 0.032828788 | N32: 0.10586219 | O32: True | P32: True | Q32: 8.8566801e-05 | R32: False | S32: PRACTICALLY_EQUIVALENT | T32: within_arm_component_vs_zero | U32: gemini31flashlite | V32: 0p75 | W32: package | X32: alpha | Y32: package_alpha
A33: 575 | B33: 0.07049305 | C33: 0.57920358 | D33: 0.024154459 | E33: 0.109 | F33: 0.05 | G33: 7.4310523 | H33: 1.9651096e-13 | I33: -1.5941963 | J33: 0.05572126 | K33: 0.05572126 | L33: 0.9 | M33: 0.030698274 | N33: 0.11028783 | O33: False | P33: False | Q33: 0.0026702809 | R33: False | S33: NOT_EQUIVALENT_OR_INCONCLUSIVE | T33: within_arm_component_vs_zero | U33: gemini31flashlite | V33: 1p27 | W33: self_revision | X33: alpha | Y33: self_revision_alpha
A34: 575 | B34: 0.045167937 | C34: 0.61820553 | D34: 0.025780953 | E34: 0.109 | F34: 0.05 | G34: 5.9799162 | H34: 1.9634174e-09 | I34: -2.4759389 | J34: 0.0067879799 | K34: 0.0067879799 | L34: 0.9 | M34: 0.0026934925 | N34: 0.087642381 | O34: True | P34: True | Q34: 0.017939618 | R34: False | S34: PRACTICALLY_EQUIVALENT | T34: within_arm_component_vs_zero | U34: gemini31flashlite | V34: 1p27 | W34: reference_content_conditional | X34: alpha | Y34: reference_content_conditional_alpha
A35: 575 | B35: 0.11566099 | C35: 0.61812022 | D35: 0.025777395 | E35: 0.109 | F35: 0.05 | G35: 8.7154263 | H35: 1.5538342e-17 | I35: 0.2584042 | J35: 0.6019062 | K35: 0.6019062 | L35: 0.9 | M35: 0.073192404 | N35: 0.15812957 | O35: False | P35: False | Q35: 6.8831305e-07 | R35: True | S35: NOT_EQUIVALENT_OR_INCONCLUSIVE | T35: within_arm_component_vs_zero | U35: gemini31flashlite | V35: 1p27 | W35: package | X35: alpha | Y35: package_alpha
A36: 575 | B36: 0.062214598 | C36: 0.52293949 | D36: 0.021808084 | E36: 0.109 | F36: 0.05 | G36: 7.8509691 | H36: 1.017955e-14 | I36: -2.1453238 | J36: 0.016172927 | K36: 0.016172927 | L36: 0.9 | M36: 0.026285504 | N36: 0.098143692 | O36: True | P36: True | Q36: 0.0021915476 | R36: False | S36: PRACTICALLY_EQUIVALENT | T36: within_arm_component_vs_zero | U36: gemini31flashlite | V36: 2p00 | W36: self_revision | X36: alpha | Y36: self_revision_alpha
A37: 575 | B37: 0.081483834 | C37: 0.56360972 | D37: 0.02350415 | E37: 0.109 | F37: 0.05 | G37: 8.1042638 | H37: 1.6060149e-15 | I37: -1.1706939 | J37: 0.12110381 | K37: 0.12110381 | L37: 0.9 | M37: 0.042760451 | N37: 0.12020722 | O37: False | P37: False | Q37: 0.000491999 | R37: False | S37: NOT_EQUIVALENT_OR_INCONCLUSIVE | T37: within_arm_component_vs_zero | U37: gemini31flashlite | V37: 2p00 | W37: reference_content_conditional | X37: alpha | Y37: reference_content_conditional_alpha
A38: 575 | B38: 0.14369843 | C38: 0.60577101 | D38: 0.025262398 | E38: 0.109 | F38: 0.05 | G38: 10.002947 | H38: 4.0057493e-22 | I38: 1.373521 | J38: 0.91493667 | K38: 0.91493667 | L38: 0.9 | M38: 0.10207831 | N38: 0.18531855 | O38: False | P38: False | Q38: 1.6687549e-08 | R38: True | S38: NOT_EQUIVALENT_OR_INCONCLUSIVE | T38: within_arm_component_vs_zero | U38: gemini31flashlite | V38: 2p00 | W38: package | X38: alpha | Y38: package_alpha
A39: 575 | B39: 0.018928051 | C39: 0.17778224 | D39: 0.0074140318 | E39: 0.109 | F39: 0.05 | G39: 17.254856 | H39: 2.3505859e-54 | I39: -12.148849 | J39: 1.0978654e-30 | K39: 1.0978654e-30 | L39: 0.9 | M39: 0.0067133404 | N39: 0.031142762 | O39: True | P39: True | Q39: 0.004733027 | R39: False | S39: PRACTICALLY_EQUIVALENT | T39: within_arm_component_vs_zero | U39: gemini31flashlite | V39: unbounded | W39: self_revision | X39: alpha | Y39: self_revision_alpha
A40: 575 | B40: 0.40240621 | C40: 0.83577459 | D40: 0.03485421 | E40: 0.109 | F40: 0.05 | G40: 14.672724 | H40: 6.3442002e-42 | I40: 8.4180997 | J40: 1 | K40: 1 | L40: 0.9 | M40: 0.34498346 | N40: 0.45982896 | O40: False | P40: False | Q40: 1.5434023e-30 | R40: True | S40: NOT_EQUIVALENT_OR_INCONCLUSIVE | T40: within_arm_component_vs_zero | U40: gemini31flashlite | V40: unbounded | W40: reference_content_conditional | X40: alpha | Y40: reference_content_conditional_alpha
A41: 575 | B41: 0.42133426 | C41: 0.83194684 | D41: 0.034694581 | E41: 0.109 | F41: 0.05 | G41: 15.285795 | H41: 8.3667848e-45 | I41: 9.0023932 | J41: 1 | K41: 1 | L41: 0.9 | M41: 0.3641745 | N41: 0.47849402 | O41: False | P41: False | Q41: 2.8375875e-33 | R41: True | S41: NOT_EQUIVALENT_OR_INCONCLUSIVE | T41: within_arm_component_vs_zero | U41: gemini31flashlite | V41: unbounded | W41: package | X41: alpha | Y41: package_alpha
... A53: 575 | B53: 0.17607408 | C53: 0.60174362 | D53: 0.025094444 | E53: 0.109 | F53: 0.05 | G53: 11.360048 | H53: 2.0353331e-27 | I53: 2.6728656 | J53: 0.99613275 | K53: 0.99613275 | L53: 0.9 | M53: 0.13473066 | N53: 0.21741749 | O53: False | P53: False | Q53: 1.2372351e-12 | R53: True | S53: NOT_EQUIVALENT_OR_INCONCLUSIVE | T53: within_arm_component_vs_zero | U53: gpt54mini | V53: unbounded | W53: package | X53: alpha | Y53: package_alpha

Sheet CALCULATION
A1: T6-6 · 분석 과정
A2: 필터·분석단위와 실제 계산 결과입니다. 수치 셀은 SOURCE를 직접 참조합니다.
A4: 항목 | B4: 내용
A5: 계산 방법 | B5: 선택 실행 산출물에 명시된 조건을 적용하고 논문 분석단위로 행·열을 정리
A6: 생산 코드 | B6: src/credit_recourse/analysis/c4r_tost_equivalence.py
A7: 선택 실행 | B7: V11_FINAL_FROZEN_REPLAY_RESUME
A11: 이 표·그림과 연결된 본문 핵심 수치
A12: 수치 ID | B12: 본문 주장 | C12: 논문 표시값 | D12: 재계산값 | E12: 확인 결과 | F12: 계산식 | G12: 실제 입력 산출물
A13: NC0215-02 | B13: 행동크기 상한에 따라 각 단계의 결과가 얼마나 달라졌는지는 상한조건의 값에서 총 행동크기 무지시 조건의 값을 빼서 확인하였다. 행동크기 0.75에서 C6−C4는 무지시 조건보다 0.205 낮았으며, 자기 재검토에서 −0.146, 외부 정책 참조를 추가한 뒤에는 −0.058의 차이가 나타났다. 행동크기 1.27에서는 C6−C4가 0.089 낮았고, 두 단계의 차이는 각각 −0.088과 −0.002였다. 행동크기 2.00에서는 C6−C4가 0.138 낮았으며, 자기 재검토에서 −0.156, 외부 정책 참조를 추가한 뒤에는 +0.018의 차이가 나타났다. 세 상한조건 모두 자기 재검토에서 더 큰 감소가 나타났다. | C13: 0.205 | D13: 0.205 | E13: 논문값과 일치 | F13: ABS(finite-budget (C6-C4) minus unbounded-budget (C6-C4)), same firms | G13: embedded://selected-run-output/data/analysis/paper_repro/05_extension_e3_e4/e3_c4r_journal/tost_alpha/c4r_tost_interactions_alpha.csv
A14: NC0215-03 | B14: 행동크기 상한에 따라 각 단계의 결과가 얼마나 달라졌는지는 상한조건의 값에서 총 행동크기 무지시 조건의 값을 빼서 확인하였다. 행동크기 0.75에서 C6−C4는 무지시 조건보다 0.205 낮았으며, 자기 재검토에서 −0.146, 외부 정책 참조를 추가한 뒤에는 −0.058의 차이가 나타났다. 행동크기 1.27에서는 C6−C4가 0.089 낮았고, 두 단계의 차이는 각각 −0.088과 −0.002였다. 행동크기 2.00에서는 C6−C4가 0.138 낮았으며, 자기 재검토에서 −0.156, 외부 정책 참조를 추가한 뒤에는 +0.018의 차이가 나타났다. 세 상한조건 모두 자기 재검토에서 더 큰 감소가 나타났다. | C14: −0.146 | D14: -0.146 | E14: 논문값과 일치 | F14: finite-budget component minus unbounded-budget component, same firms | G14: embedded://selected-run-output/data/analysis/paper_repro/05_extension_e3_e4/e3_c4r_journal/tost_alpha/c4r_tost_interactions_alpha.csv
A15: NC0215-04 | B15: 행동크기 상한에 따라 각 단계의 결과가 얼마나 달라졌는지는 상한조건의 값에서 총 행동크기 무지시 조건의 값을 빼서 확인하였다. 행동크기 0.75에서 C6−C4는 무지시 조건보다 0.205 낮았으며, 자기 재검토에서 −0.146, 외부 정책 참조를 추가한 뒤에는 −0.058의 차이가 나타났다. 행동크기 1.27에서는 C6−C4가 0.089 낮았고, 두 단계의 차이는 각각 −0.088과 −0.002였다. 행동크기 2.00에서는 C6−C4가 0.138 낮았으며, 자기 재검토에서 −0.156, 외부 정책 참조를 추가한 뒤에는 +0.018의 차이가 나타났다. 세 상한조건 모두 자기 재검토에서 더 큰 감소가 나타났다. | C15: −0.058 | D15: -0.058 | E15: 논문값과 일치 | F15: finite-budget component minus unbounded-budget component, same firms | G15: embedded://selected-run-output/data/analysis/paper_repro/05_extension_e3_e4/e3_c4r_journal/tost_alpha/c4r_tost_interactions_alpha.csv
A16: NC0215-06 | B16: 행동크기 상한에 따라 각 단계의 결과가 얼마나 달라졌는지는 상한조건의 값에서 총 행동크기 무지시 조건의 값을 빼서 확인하였다. 행동크기 0.75에서 C6−C4는 무지시 조건보다 0.205 낮았으며, 자기 재검토에서 −0.146, 외부 정책 참조를 추가한 뒤에는 −0.058의 차이가 나타났다. 행동크기 1.27에서는 C6−C4가 0.089 낮았고, 두 단계의 차이는 각각 −0.088과 −0.002였다. 행동크기 2.00에서는 C6−C4가 0.138 낮았으며, 자기 재검토에서 −0.156, 외부 정책 참조를 추가한 뒤에는 +0.018의 차이가 나타났다. 세 상한조건 모두 자기 재검토에서 더 큰 감소가 나타났다. | C16: 0.089 | D16: 0.089 | E16: 논문값과 일치 | F16: ABS(finite-budget (C6-C4) minus unbounded-budget (C6-C4)), same firms | G16: embedded://selected-run-output/data/analysis/paper_repro/05_extension_e3_e4/e3_c4r_journal/tost_alpha/c4r_tost_interactions_alpha.csv
A17: NC0215-07 | B17: 행동크기 상한에 따라 각 단계의 결과가 얼마나 달라졌는지는 상한조건의 값에서 총 행동크기 무지시 조건의 값을 빼서 확인하였다. 행동크기 0.75에서 C6−C4는 무지시 조건보다 0.205 낮았으며, 자기 재검토에서 −0.146, 외부 정책 참조를 추가한 뒤에는 −0.058의 차이가 나타났다. 행동크기 1.27에서는 C6−C4가 0.089 낮았고, 두 단계의 차이는 각각 −0.088과 −0.002였다. 행동크기 2.00에서는 C6−C4가 0.138 낮았으며, 자기 재검토에서 −0.156, 외부 정책 참조를 추가한 뒤에는 +0.018의 차이가 나타났다. 세 상한조건 모두 자기 재검토에서 더 큰 감소가 나타났다. | C17: −0.088 | D17: -0.088 | E17: 논문값과 일치 | F17: finite-budget component minus unbounded-budget component, same firms | G17: embedded://selected-run-output/data/analysis/paper_repro/05_extension_e3_e4/e3_c4r_journal/tost_alpha/c4r_tost_interactions_alpha.csv
A18: NC0215-08 | B18: 행동크기 상한에 따라 각 단계의 결과가 얼마나 달라졌는지는 상한조건의 값에서 총 행동크기 무지시 조건의 값을 빼서 확인하였다. 행동크기 0.75에서 C6−C4는 무지시 조건보다 0.205 낮았으며, 자기 재검토에서 −0.146, 외부 정책 참조를 추가한 뒤에는 −0.058의 차이가 나타났다. 행동크기 1.27에서는 C6−C4가 0.089 낮았고, 두 단계의 차이는 각각 −0.088과 −0.002였다. 행동크기 2.00에서는 C6−C4가 0.138 낮았으며, 자기 재검토에서 −0.156, 외부 정책 참조를 추가한 뒤에는 +0.018의 차이가 나타났다. 세 상한조건 모두 자기 재검토에서 더 큰 감소가 나타났다. | C18: −0.002 | D18: -0.002 | E18: 논문값과 일치 | F18: finite-budget component minus unbounded-budget component, same firms | G18: embedded://selected-run-output/data/analysis/paper_repro/05_extension_e3_e4/e3_c4r_journal/tost_alpha/c4r_tost_interactions_alpha.csv
A19: NC0215-10 | B19: 행동크기 상한에 따라 각 단계의 결과가 얼마나 달라졌는지는 상한조건의 값에서 총 행동크기 무지시 조건의 값을 빼서 확인하였다. 행동크기 0.75에서 C6−C4는 무지시 조건보다 0.205 낮았으며, 자기 재검토에서 −0.146, 외부 정책 참조를 추가한 뒤에는 −0.058의 차이가 나타났다. 행동크기 1.27에서는 C6−C4가 0.089 낮았고, 두 단계의 차이는 각각 −0.088과 −0.002였다. 행동크기 2.00에서는 C6−C4가 0.138 낮았으며, 자기 재검토에서 −0.156, 외부 정책 참조를 추가한 뒤에는 +0.018의 차이가 나타났다. 세 상한조건 모두 자기 재검토에서 더 큰 감소가 나타났다. | C19: 0.138 | D19: 0.138 | E19: 논문값과 일치 | F19: ABS(finite-budget (C6-C4) minus unbounded-budget (C6-C4)), same firms | G19: embedded://selected-run-output/data/analysis/paper_repro/05_extension_e3_e4/e3_c4r_journal/tost_alpha/c4r_tost_interactions_alpha.csv
A20: NC0215-11 | B20: 행동크기 상한에 따라 각 단계의 결과가 얼마나 달라졌는지는 상한조건의 값에서 총 행동크기 무지시 조건의 값을 빼서 확인하였다. 행동크기 0.75에서 C6−C4는 무지시 조건보다 0.205 낮았으며, 자기 재검토에서 −0.146, 외부 정책 참조를 추가한 뒤에는 −0.058의 차이가 나타났다. 행동크기 1.27에서는 C6−C4가 0.089 낮았고, 두 단계의 차이는 각각 −0.088과 −0.002였다. 행동크기 2.00에서는 C6−C4가 0.138 낮았으며, 자기 재검토에서 −0.156, 외부 정책 참조를 추가한 뒤에는 +0.018의 차이가 나타났다. 세 상한조건 모두 자기 재검토에서 더 큰 감소가 나타났다. | C20: −0.156 | D20: -0.156 | E20: 논문값과 일치 | F20: finite-budget component minus unbounded-budget component, same firms | G20: embedded://selected-run-output/data/analysis/paper_repro/05_extension_e3_e4/e3_c4r_journal/tost_alpha/c4r_tost_interactions_alpha.csv
A21: NC0215-12 | B21: 행동크기 상한에 따라 각 단계의 결과가 얼마나 달라졌는지는 상한조건의 값에서 총 행동크기 무지시 조건의 값을 빼서 확인하였다. 행동크기 0.75에서 C6−C4는 무지시 조건보다 0.205 낮았으며, 자기 재검토에서 −0.146, 외부 정책 참조를 추가한 뒤에는 −0.058의 차이가 나타났다. 행동크기 1.27에서는 C6−C4가 0.089 낮았고, 두 단계의 차이는 각각 −0.088과 −0.002였다. 행동크기 2.00에서는 C6−C4가 0.138 낮았으며, 자기 재검토에서 −0.156, 외부 정책 참조를 추가한 뒤에는 +0.018의 차이가 나타났다. 세 상한조건 모두 자기 재검토에서 더 큰 감소가 나타났다. | C21: +0.018 | D21: 0.018 | E21: 논문값과 일치 | F21: finite-budget component minus unbounded-budget component, same firms | G21: embedded://selected-run-output/data/analysis/paper_repro/05_extension_e3_e4/e3_c4r_journal/tost_alpha/c4r_tost_interactions_alpha.csv
A22: NC0218-03 | B22: Gemini 3.1 Flash-Lite에서는 자기 재검토보다 외부 정책 참조를 반영하는 단계에서 더 큰 차이가 나타났다. 자기 재검토의 변화는 행동크기 0.75에서 +0.070, 1.27에서 +0.070, 2.00에서 +0.062였고, 총 행동크기 무지시 조건에서는 +0.019였다. 각 상한조건과 무지시 조건의 차이는 +0.051, +0.052, +0.043이었으며, 동등성 검정에서는 세 차이 모두 이 분석에서 사용한 범위 안에 있었다. | C22: +0.070 | D22: 0.07 | E22: 논문값과 일치 | F22: MEAN_i(policy_value_alpha(C4R_i) - policy_value_alpha(C4_i)) | G22: embedded://selected-run-output/data/analysis/paper_repro/05_extension_e3_e4/e3_c4r_journal/v3_matched/c4r_matched_v3_contrasts.csv
A23: NC0218-05 | B23: Gemini 3.1 Flash-Lite에서는 자기 재검토보다 외부 정책 참조를 반영하는 단계에서 더 큰 차이가 나타났다. 자기 재검토의 변화는 행동크기 0.75에서 +0.070, 1.27에서 +0.070, 2.00에서 +0.062였고, 총 행동크기 무지시 조건에서는 +0.019였다. 각 상한조건과 무지시 조건의 차이는 +0.051, +0.052, +0.043이었으며, 동등성 검정에서는 세 차이 모두 이 분석에서 사용한 범위 안에 있었다. | C23: +0.070 | D23: 0.07 | E23: 논문값과 일치 | F23: MEAN_i(policy_value_alpha(C4R_i) - policy_value_alpha(C4_i)) | G23: embedded://selected-run-output/data/analysis/paper_repro/05_extension_e3_e4/e3_c4r_journal/v3_matched/c4r_matched_v3_contrasts.csv
A24: NC0218-07 | B24: Gemini 3.1 Flash-Lite에서는 자기 재검토보다 외부 정책 참조를 반영하는 단계에서 더 큰 차이가 나타났다. 자기 재검토의 변화는 행동크기 0.75에서 +0.070, 1.27에서 +0.070, 2.00에서 +0.062였고, 총 행동크기 무지시 조건에서는 +0.019였다. 각 상한조건과 무지시 조건의 차이는 +0.051, +0.052, +0.043이었으며, 동등성 검정에서는 세 차이 모두 이 분석에서 사용한 범위 안에 있었다. | C24: +0.062 | D24: 0.062 | E24: 논문값과 일치 | F24: MEAN_i(policy_value_alpha(C4R_i) - policy_value_alpha(C4_i)) | G24: embedded://selected-run-output/data/analysis/paper_repro/05_extension_e3_e4/e3_c4r_journal/v3_matched/c4r_matched_v3_contrasts.csv
... A38: NC0219-16 | B38: 반면 외부 정책 참조를 추가한 뒤의 변화는 총 행동크기 무지시 조건에서 +0.402였지만, 행동크기 0.75에서는 −0.001, 1.27에서는 +0.045, 2.00에서는 +0.081이었다. 무지시 조건과 비교하면 각각 0.403, 0.357, 0.321 낮았다. 행동크기 상한이 작을수록 Candidate-IQL의 행동정보를 최종 행동에 반영하여 얻은 정책가치가 크게 줄어든 것이다. 이에 따라 C6−C4도 총 행동크기 무지시 조건보다 행동크기 0.75에서 0.352, 1.27에서 0.306, 2.00에서 0.278 낮았다. Gemini 3.1 Flash-Lite에서는 자기 재검토 결과가 크게 달라졌다기보다, 외부 정책 참조를 최종 행동에 반영하여 얻은 정책가치가 줄어든 것이 전체 차이의 대부분을 차지하였다. | C38: 0.278 | D38: 0.278 | E38: 논문값과 일치 | F38: ABS(finite-budget component minus unbounded-budget component), same firms | G38: embedded://selected-run-output/data/analysis/paper_repro/05_extension_e3_e4/e3_c4r_journal/tost_alpha/c4r_tost_interactions_alpha.csv
A41: 계산 데이터: within_arm_tost
A42: 입력 파일 | B42: data/analysis/paper_repro/05_extension_e3_e4/e3_c4r_journal/tost_alpha/c4r_tost_within_arm_alpha.csv
A43: 선택 조건 | B43: [{"column": "oracle", "op": "equals", "value": "alpha"}]
A44: 분석 단위 | B44: cohort_id; budget_label; component
A45: 집계 | B45: PRODUCER_AGGREGATE_NO_REAGGREGATION
A46: cohort_id | B46: budget_label | C46: component | D46: n_pairs | E46: mean_gap | F46: ci_low | G46: ci_high | H46: p_tost | I46: equivalent | J46: decision
A47: ='SOURCE'!U30 | B47: ='SOURCE'!V30 | C47: ='SOURCE'!W30 | D47: ='SOURCE'!A30 | E47: ='SOURCE'!B30 | F47: ='SOURCE'!M30 | G47: ='SOURCE'!N30 | H47: ='SOURCE'!K30 | I47: ='SOURCE'!O30 | J47: ='SOURCE'!S30
A48: ='SOURCE'!U31 | B48: ='SOURCE'!V31 | C48: ='SOURCE'!W31 | D48: ='SOURCE'!A31 | E48: ='SOURCE'!B31 | F48: ='SOURCE'!M31 | G48: ='SOURCE'!N31 | H48: ='SOURCE'!K31 | I48: ='SOURCE'!O31 | J48: ='SOURCE'!S31
A49: ='SOURCE'!U32 | B49: ='SOURCE'!V32 | C49: ='SOURCE'!W32 | D49: ='SOURCE'!A32 | E49: ='SOURCE'!B32 | F49: ='SOURCE'!M32 | G49: ='SOURCE'!N32 | H49: ='SOURCE'!K32 | I49: ='SOURCE'!O32 | J49: ='SOURCE'!S32
A50: ='SOURCE'!U33 | B50: ='SOURCE'!V33 | C50: ='SOURCE'!W33 | D50: ='SOURCE'!A33 | E50: ='SOURCE'!B33 | F50: ='SOURCE'!M33 | G50: ='SOURCE'!N33 | H50: ='SOURCE'!K33 | I50: ='SOURCE'!O33 | J50: ='SOURCE'!S33
A51: ='SOURCE'!U34 | B51: ='SOURCE'!V34 | C51: ='SOURCE'!W34 | D51: ='SOURCE'!A34 | E51: ='SOURCE'!B34 | F51: ='SOURCE'!M34 | G51: ='SOURCE'!N34 | H51: ='SOURCE'!K34 | I51: ='SOURCE'!O34 | J51: ='SOURCE'!S34
A52: ='SOURCE'!U35 | B52: ='SOURCE'!V35 | C52: ='SOURCE'!W35 | D52: ='SOURCE'!A35 | E52: ='SOURCE'!B35 | F52: ='SOURCE'!M35 | G52: ='SOURCE'!N35 | H52: ='SOURCE'!K35 | I52: ='SOURCE'!O35 | J52: ='SOURCE'!S35
A53: ='SOURCE'!U36 | B53: ='SOURCE'!V36 | C53: ='SOURCE'!W36 | D53: ='SOURCE'!A36 | E53: ='SOURCE'!B36 | F53: ='SOURCE'!M36 | G53: ='SOURCE'!N36 | H53: ='SOURCE'!K36 | I53: ='SOURCE'!O36 | J53: ='SOURCE'!S36
A54: ='SOURCE'!U37 | B54: ='SOURCE'!V37 | C54: ='SOURCE'!W37 | D54: ='SOURCE'!A37 | E54: ='SOURCE'!B37 | F54: ='SOURCE'!M37 | G54: ='SOURCE'!N37 | H54: ='SOURCE'!K37 | I54: ='SOURCE'!O37 | J54: ='SOURCE'!S37
A55: ='SOURCE'!U38 | B55: ='SOURCE'!V38 | C55: ='SOURCE'!W38 | D55: ='SOURCE'!A38 | E55: ='SOURCE'!B38 | F55: ='SOURCE'!M38 | G55: ='SOURCE'!N38 | H55: ='SOURCE'!K38 | I55: ='SOURCE'!O38 | J55: ='SOURCE'!S38
A56: ='SOURCE'!U39 | B56: ='SOURCE'!V39 | C56: ='SOURCE'!W39 | D56: ='SOURCE'!A39 | E56: ='SOURCE'!B39 | F56: ='SOURCE'!M39 | G56: ='SOURCE'!N39 | H56: ='SOURCE'!K39 | I56: ='SOURCE'!O39 | J56: ='SOURCE'!S39
A57: ='SOURCE'!U40 | B57: ='SOURCE'!V40 | C57: ='SOURCE'!W40 | D57: ='SOURCE'!A40 | E57: ='SOURCE'!B40 | F57: ='SOURCE'!M40 | G57: ='SOURCE'!N40 | H57: ='SOURCE'!K40 | I57: ='SOURCE'!O40 | J57: ='SOURCE'!S40
A58: ='SOURCE'!U41 | B58: ='SOURCE'!V41 | C58: ='SOURCE'!W41 | D58: ='SOURCE'!A41 | E58: ='SOURCE'!B41 | F58: ='SOURCE'!M41 | G58: ='SOURCE'!N41 | H58: ='SOURCE'!K41 | I58: ='SOURCE'!O41 | J58: ='SOURCE'!S41
... A70: ='SOURCE'!U53 | B70: ='SOURCE'!V53 | C70: ='SOURCE'!W53 | D70: ='SOURCE'!A53 | E70: ='SOURCE'!B53 | F70: ='SOURCE'!M53 | G70: ='SOURCE'!N53 | H70: ='SOURCE'!K53 | I70: ='SOURCE'!O53 | J70: ='SOURCE'!S53
...

Sheet PAPER_TABLE
A1: T6-6 · 논문 표 작업용 결과
A2: ANALYSIS에서 계산된 값만 연결한 최종 작업표입니다. Excel에서 정렬·피벗·표시형식만 조정하면 됩니다.
A4: 계산 결과: within_arm_tost
A5: ='CALCULATION'!A46 | B5: ='CALCULATION'!B46 | C5: ='CALCULATION'!C46 | D5: ='CALCULATION'!D46 | E5: ='CALCULATION'!E46 | F5: ='CALCULATION'!F46 | G5: ='CALCULATION'!G46 | H5: ='CALCULATION'!H46 | ... J5: ='CALCULATION'!J46
A6: ='CALCULATION'!A47 | B6: ='CALCULATION'!B47 | C6: ='CALCULATION'!C47 | D6: ='CALCULATION'!D47 | E6: ='CALCULATION'!E47 | F6: ='CALCULATION'!F47 | G6: ='CALCULATION'!G47 | H6: ='CALCULATION'!H47 | ... J6: ='CALCULATION'!J47
A7: ='CALCULATION'!A48 | B7: ='CALCULATION'!B48 | C7: ='CALCULATION'!C48 | D7: ='CALCULATION'!D48 | E7: ='CALCULATION'!E48 | F7: ='CALCULATION'!F48 | G7: ='CALCULATION'!G48 | H7: ='CALCULATION'!H48 | ... J7: ='CALCULATION'!J48
A8: ='CALCULATION'!A49 | B8: ='CALCULATION'!B49 | C8: ='CALCULATION'!C49 | D8: ='CALCULATION'!D49 | E8: ='CALCULATION'!E49 | F8: ='CALCULATION'!F49 | G8: ='CALCULATION'!G49 | H8: ='CALCULATION'!H49 | ... J8: ='CALCULATION'!J49
A9: ='CALCULATION'!A50 | B9: ='CALCULATION'!B50 | C9: ='CALCULATION'!C50 | D9: ='CALCULATION'!D50 | E9: ='CALCULATION'!E50 | F9: ='CALCULATION'!F50 | G9: ='CALCULATION'!G50 | H9: ='CALCULATION'!H50 | ... J9: ='CALCULATION'!J50
A10: ='CALCULATION'!A51 | B10: ='CALCULATION'!B51 | C10: ='CALCULATION'!C51 | D10: ='CALCULATION'!D51 | E10: ='CALCULATION'!E51 | F10: ='CALCULATION'!F51 | G10: ='CALCULATION'!G51 | H10: ='CALCULATION'!H51 | ... J10: ='CALCULATION'!J51
A11: ='CALCULATION'!A52 | B11: ='CALCULATION'!B52 | C11: ='CALCULATION'!C52 | D11: ='CALCULATION'!D52 | E11: ='CALCULATION'!E52 | F11: ='CALCULATION'!F52 | G11: ='CALCULATION'!G52 | H11: ='CALCULATION'!H52 | ... J11: ='CALCULATION'!J52
A12: ='CALCULATION'!A53 | B12: ='CALCULATION'!B53 | C12: ='CALCULATION'!C53 | D12: ='CALCULATION'!D53 | E12: ='CALCULATION'!E53 | F12: ='CALCULATION'!F53 | G12: ='CALCULATION'!G53 | H12: ='CALCULATION'!H53 | ... J12: ='CALCULATION'!J53
A13: ='CALCULATION'!A54 | B13: ='CALCULATION'!B54 | C13: ='CALCULATION'!C54 | D13: ='CALCULATION'!D54 | E13: ='CALCULATION'!E54 | F13: ='CALCULATION'!F54 | G13: ='CALCULATION'!G54 | H13: ='CALCULATION'!H54 | ... J13: ='CALCULATION'!J54
A14: ='CALCULATION'!A55 | B14: ='CALCULATION'!B55 | C14: ='CALCULATION'!C55 | D14: ='CALCULATION'!D55 | E14: ='CALCULATION'!E55 | F14: ='CALCULATION'!F55 | G14: ='CALCULATION'!G55 | H14: ='CALCULATION'!H55 | ... J14: ='CALCULATION'!J55
A15: ='CALCULATION'!A56 | B15: ='CALCULATION'!B56 | C15: ='CALCULATION'!C56 | D15: ='CALCULATION'!D56 | E15: ='CALCULATION'!E56 | F15: ='CALCULATION'!F56 | G15: ='CALCULATION'!G56 | H15: ='CALCULATION'!H56 | ... J15: ='CALCULATION'!J56
A16: ='CALCULATION'!A57 | B16: ='CALCULATION'!B57 | C16: ='CALCULATION'!C57 | D16: ='CALCULATION'!D57 | E16: ='CALCULATION'!E57 | F16: ='CALCULATION'!F57 | G16: ='CALCULATION'!G57 | H16: ='CALCULATION'!H57 | ... J16: ='CALCULATION'!J57
... A29: ='CALCULATION'!A70 | B29: ='CALCULATION'!B70 | C29: ='CALCULATION'!C70 | D29: ='CALCULATION'!D70 | E29: ='CALCULATION'!E70 | F29: ='CALCULATION'!F70 | G29: ='CALCULATION'!G70 | H29: ='CALCULATION'!H70 | ... J29: ='CALCULATION'!J70
A32: 계산 결과: interaction_tost
A33: ='CALCULATION'!A78 | B33: ='CALCULATION'!B78 | C33: ='CALCULATION'!C78 | D33: ='CALCULATION'!D78 | E33: ='CALCULATION'!E78 | F33: ='CALCULATION'!F78 | G33: ='CALCULATION'!G78 | H33: ='CALCULATION'!H78 | ... K33: ='CALCULATION'!K78
A34: ='CALCULATION'!A79 | B34: ='CALCULATION'!B79 | C34: ='CALCULATION'!C79 | D34: ='CALCULATION'!D79 | E34: ='CALCULATION'!E79 | F34: ='CALCULATION'!F79 | G34: ='CALCULATION'!G79 | H34: ='CALCULATION'!H79 | ... K34: ='CALCULATION'!K79
A35: ='CALCULATION'!A80 | B35: ='CALCULATION'!B80 | C35: ='CALCULATION'!C80 | D35: ='CALCULATION'!D80 | E35: ='CALCULATION'!E80 | F35: ='CALCULATION'!F80 | G35: ='CALCULATION'!G80 | H35: ='CALCULATION'!H80 | ... K35: ='CALCULATION'!K80
A36: ='CALCULATION'!A81 | B36: ='CALCULATION'!B81 | C36: ='CALCULATION'!C81 | D36: ='CALCULATION'!D81 | E36: ='CALCULATION'!E81 | F36: ='CALCULATION'!F81 | G36: ='CALCULATION'!G81 | H36: ='CALCULATION'!H81 | ... K36: ='CALCULATION'!K81
A37: ='CALCULATION'!A82 | B37: ='CALCULATION'!B82 | C37: ='CALCULATION'!C82 | D37: ='CALCULATION'!D82 | E37: ='CALCULATION'!E82 | F37: ='CALCULATION'!F82 | G37: ='CALCULATION'!G82 | H37: ='CALCULATION'!H82 | ... K37: ='CALCULATION'!K82
A38: ='CALCULATION'!A83 | B38: ='CALCULATION'!B83 | C38: ='CALCULATION'!C83 | D38: ='CALCULATION'!D83 | E38: ='CALCULATION'!E83 | F38: ='CALCULATION'!F83 | G38: ='CALCULATION'!G83 | H38: ='CALCULATION'!H83 | ... K38: ='CALCULATION'!K83
A39: ='CALCULATION'!A84 | B39: ='CALCULATION'!B84 | C39: ='CALCULATION'!C84 | D39: ='CALCULATION'!D84 | E39: ='CALCULATION'!E84 | F39: ='CALCULATION'!F84 | G39: ='CALCULATION'!G84 | H39: ='CALCULATION'!H84 | ... K39: ='CALCULATION'!K84
A40: ='CALCULATION'!A85 | B40: ='CALCULATION'!B85 | C40: ='CALCULATION'!C85 | D40: ='CALCULATION'!D85 | E40: ='CALCULATION'!E85 | F40: ='CALCULATION'!F85 | G40: ='CALCULATION'!G85 | H40: ='CALCULATION'!H85 | ... K40: ='CALCULATION'!K85
A41: ='CALCULATION'!A86 | B41: ='CALCULATION'!B86 | C41: ='CALCULATION'!C86 | D41: ='CALCULATION'!D86 | E41: ='CALCULATION'!E86 | F41: ='CALCULATION'!F86 | G41: ='CALCULATION'!G86 | H41: ='CALCULATION'!H86 | ... K41: ='CALCULATION'!K86
A42: ='CALCULATION'!A87 | B42: ='CALCULATION'!B87 | C42: ='CALCULATION'!C87 | D42: ='CALCULATION'!D87 | E42: ='CALCULATION'!E87 | F42: ='CALCULATION'!F87 | G42: ='CALCULATION'!G87 | H42: ='CALCULATION'!H87 | ... K42: ='CALCULATION'!K87
A43: ='CALCULATION'!A88 | B43: ='CALCULATION'!B88 | C43: ='CALCULATION'!C88 | D43: ='CALCULATION'!D88 | E43: ='CALCULATION'!E88 | F43: ='CALCULATION'!F88 | G43: ='CALCULATION'!G88 | H43: ='CALCULATION'!H88 | ... K43: ='CALCULATION'!K88
A44: ='CALCULATION'!A89 | B44: ='CALCULATION'!B89 | C44: ='CALCULATION'!C89 | D44: ='CALCULATION'!D89 | E44: ='CALCULATION'!E89 | F44: ='CALCULATION'!F89 | G44: ='CALCULATION'!G89 | H44: ='CALCULATION'!H89 | ... K44: ='CALCULATION'!K89
... A51: ='CALCULATION'!A96 | B51: ='CALCULATION'!B96 | C51: ='CALCULATION'!C96 | D51: ='CALCULATION'!D96 | E51: ='CALCULATION'!E96 | F51: ='CALCULATION'!F96 | G51: ='CALCULATION'!G96 | H51: ='CALCULATION'!H96 | ... K51: ='CALCULATION'!K96
