Workbook

Sheet README
A1: T4-2 · 표 4-2. 검사 3의 DEV·OOT·POST 결과
A2: 논문 인쇄값을 계산 입력으로 쓰지 않고, 선택 실행의 실제 산출물에서 값을 계산한 Excel입니다.
A4: 항목 | B4: 내용
A5: 선택 실행 | B5: V11_FINAL_FROZEN_REPLAY_RESUME
A6: 실행 방식 | B6: FrozenReplay
A7: 논문 항목 읽기 | B7: 논문 DOCX에서 번호·제목·위치만 동적으로 읽음
A8: 논문 위치 | B8: 4.2 Simulator의 회계항등식 준수와 평가결과 검증 · 인쇄면 47
A9: 관측·집계 단위 | B9: property + metric + split
A10: 선택 조건 | B10: [[{"column": "property", "op": "in", "values": ["P1_wedge", "P2_rank", "P3_direction"]}, {"column": "metric", "op": "in", "values": ["median", "spearman", "agreement"]}, {"column": "split", "op": "in", "values": ["dev", "oot", "post"]}], [{"column": "property", "op": "equals", "value": "P1_wedge"}, {"column": "metric", "op": "equals", "value": "share_positive"}, {"column": "split", "op": "equals", "value": "overall"}]]
A11: 계산 방법 | B11: 선택 실행 산출물에 명시된 조건을 적용하고 논문 분석단위로 행·열을 정리
A12: 생산 코드 | B12: src/credit_recourse/analysis/paper_repro_analysis.py
A13: 실제 입력 산출물 | B13: frozen_outputs/analysis/paper_repro/01_substrate_validation/test3_counterfactual_fidelity/test3_property_summary.csv frozen_outputs/analysis/paper_repro/01_substrate_validation/test3_counterfactual_fidelity/test3_rows.csv

Sheet SOURCE
A1: T4-2 · 실제 입력 산출물
A2: 선택 실행에서 읽은 실제 중간·최종 산출물입니다. 아래 ANALYSIS가 이 셀들을 직접 참조합니다.
A4: 입력 1: frozen_outputs/analysis/paper_repro/01_substrate_validation/test3_counterfactual_fidelity/test3_property_summary.csv
A5: 파일 크기(bytes) | B5: 1347 | C5: 생산 코드 | D5: src/credit_recourse/analysis/paper_repro_analysis.py | E5: SHA256 | F5: 0A507B39A6D90E9448B10A1DF7DC7867A7C4307282C52234EFC84CA2CCC82744 | G5: 읽기 상태 | H5: OK
A6: property | B6: metric | C6: split | D6: value | E6: n | F6: ci95_lo | G6: ci95_hi
A7: P1_wedge | B7: median | C7: overall | D7: 10.822667 | E7: 2324
A8: P1_wedge | B8: share_positive | C8: overall | D8: 0.97590361 | E8: 2324
A9: P2_rank | B9: spearman | C9: overall | D9: 0.90321396 | E9: 2324
A10: P3_direction | B10: agreement | C10: overall | D10: 0.71805897 | E10: 1628 | F10: 0.69570888 | G10: 0.73938241
A11: P1_wedge | B11: median | C11: dev | D11: 10.841762 | E11: 975
A12: P1_wedge | B12: share_positive | C12: dev | D12: 0.9774359 | E12: 975
A13: P2_rank | B13: spearman | C13: dev | D13: 0.90653295 | E13: 975
A14: P3_direction | B14: agreement | C14: dev | D14: 0.71203438 | E14: 698 | F14: 0.67735339 | G14: 0.74439428
A15: P1_wedge | B15: median | C15: oot | D15: 10.699914 | E15: 925
A16: P1_wedge | B16: share_positive | C16: oot | D16: 0.9772973 | E16: 925
A17: P2_rank | B17: spearman | C17: oot | D17: 0.90338756 | E17: 925
A18: P3_direction | B18: agreement | C18: oot | D18: 0.71689498 | E18: 657 | F18: 0.68126307 | G18: 0.75000527
A19: P1_wedge | B19: median | C19: post | D19: 11.15475 | E19: 424
A20: P1_wedge | B20: share_positive | C20: post | D20: 0.96933962 | E20: 424
A21: P2_rank | B21: spearman | C21: post | D21: 0.8917268 | E21: 424
A22: P3_direction | B22: agreement | C22: post | D22: 0.73626374 | E22: 273 | F22: 0.68097393 | G22: 0.78499674
A23: P1_wedge | B23: yearly_median_max_abs_dev_from_dev | C23: all_years | D23: 2.2554123
A24: P1_wedge | B24: dev_to_oot_median_shift | C24: dev→oot | D24: -0.14184791
A25: P3_direction | B25: direction_oot_revenue_not_at_bound | C25: oot | D25: 0.69631902 | E25: 326
A26: P3_direction | B26: direction_oot_revenue_at_bound | C26: oot | D26: 0.73716012 | E26: 331
A29: 입력 2: frozen_outputs/analysis/paper_repro/01_substrate_validation/test3_counterfactual_fidelity/test3_rows.csv
A30: 파일 크기(bytes) | B30: 278139 | C30: 생산 코드 | D30: src/credit_recourse/analysis/paper_repro_analysis.py | E30: SHA256 | F30: E5137FFAF32A324AD51434B625DFA4AAABD5FBC4DE6E5C6223843B09546DA34F | G30: 읽기 상태 | H30: OK
A31: firm_id | B31: fiscal_year | C31: target_year | D31: split | E31: sim_t | F31: emp_t | G31: emp_tm1 | H31: wedge | I31: d_emp | J31: d_sim_adjusted | K31: direction_match
A32: 20 | B32: 2020 | C32: 2021 | D32: oot | E32: 78.615273 | F32: 72.031866 | H32: 6.5834068
A33: 20 | B33: 2021 | C33: 2022 | D33: oot | E33: 78.615273 | F33: 67.915359 | G33: 72.031866 | H33: 10.699914 | I33: -4.1165076 | J33: -4.2583555 | K33: 1
A34: 20 | B34: 2022 | C34: 2023 | D34: oot | E34: 80.229752 | F34: 66.380973 | G34: 67.915359 | H34: 13.848779 | I34: -1.5343859 | J34: 1.472631 | K34: 0
A35: 20 | B35: 2023 | C35: 2024 | D35: post | E35: 79.009371 | F35: 69.529838 | G35: 66.380973 | H35: 9.4795328 | I35: 3.1488649 | J35: 1.7866352 | K35: 1
A36: 100 | B36: 2010 | C36: 2011 | D36: dev | E36: 70.137819 | F36: 61.709409 | H36: 8.4284092
A37: 100 | B37: 2014 | C37: 2015 | D37: dev | E37: 83.933637 | F37: 74.031655 | H37: 9.9019822
A38: 100 | B38: 2015 | C38: 2016 | D38: dev | E38: 85.452939 | F38: 74.942428 | G38: 74.031655 | H38: 10.51051 | I38: 0.91077313 | J38: 0.57952106 | K38: 1
A39: 100 | B39: 2016 | C39: 2017 | D39: dev | E39: 84.803522 | F39: 76.084346 | G39: 74.942428 | H39: 8.7191766 | I39: 1.1419176 | J39: -0.98066819 | K39: 0
A40: 100 | B40: 2017 | C40: 2018 | D40: dev | E40: 85.458674 | F40: 76.360432 | G40: 76.084346 | H40: 9.0982421 | I40: 0.27608621 | J40: -1.4674341 | K40: 0
A41: 100 | B41: 2018 | C41: 2019 | D41: dev | E41: 83.069891 | F41: 75.547017 | G41: 76.360432 | H41: 7.5228748 | I41: -0.81341541 | J41: -4.132303 | K41: 1
A42: 100 | B42: 2019 | C42: 2020 | D42: oot | E42: 78.652548 | F42: 72.52969 | G42: 75.547017 | H42: 6.1228579 | I42: -3.0173268 | J42: -7.7362313 | K42: 1
A43: 100 | B43: 2020 | C43: 2021 | D43: oot | E43: 76.34328 | F43: 68.81168 | G43: 72.52969 | H43: 7.5315997 | I43: -3.7180098 | J43: -7.0281725 | K43: 1
...

Sheet CALCULATION
A1: T4-2 · 분석 과정
A2: 필터·분석단위와 실제 계산 결과입니다. 수치 셀은 SOURCE를 직접 참조합니다.
A4: 항목 | B4: 내용
A5: 계산 방법 | B5: 선택 실행 산출물에 명시된 조건을 적용하고 논문 분석단위로 행·열을 정리
A6: 생산 코드 | B6: src/credit_recourse/analysis/paper_repro_analysis.py
A7: 선택 실행 | B7: V11_FINAL_FROZEN_REPLAY_RESUME
A11: 이 표·그림과 연결된 본문 핵심 수치
A12: 수치 ID | B12: 본문 주장 | C12: 논문 표시값 | D12: 재계산값 | E12: 확인 결과 | F12: 계산식 | G12: 실제 입력 산출물
A13: NC0117-01 | B13: Simulator 신용평점과 실제 상태를 다시 계산한 신용평점의 차이 중앙값은 DEV 10.842점, OOT 10.700점, POST 11.155점이었다. 전체 자료의 97.6%에서 Simulator 신용평점이 더 높았다. 따라서 Simulator를 실제 다음 해 신용평점의 절대값을 예측하는 모형으로 사용할 수는 없다. 다만 세 기간에서 차이의 크기가 비슷하게 나타났다는 점은 이러한 차이가 특정 기간에만 발생한 현상은 아님을 보여준다. | C13: 10.842점 | D13: 10.842 | E13: 논문값과 일치 | F13: MEDIAN(simulator_score - observed_state_score) on DEV | G13: frozen_outputs/analysis/paper_repro/01_substrate_validation/test3_counterfactual_fidelity/test3_property_summary.csv
A14: NC0117-02 | B14: Simulator 신용평점과 실제 상태를 다시 계산한 신용평점의 차이 중앙값은 DEV 10.842점, OOT 10.700점, POST 11.155점이었다. 전체 자료의 97.6%에서 Simulator 신용평점이 더 높았다. 따라서 Simulator를 실제 다음 해 신용평점의 절대값을 예측하는 모형으로 사용할 수는 없다. 다만 세 기간에서 차이의 크기가 비슷하게 나타났다는 점은 이러한 차이가 특정 기간에만 발생한 현상은 아님을 보여준다. | C14: 10.700점 | D14: 10.7 | E14: 논문값과 일치 | F14: MEDIAN(simulator_score - observed_state_score) on OOT | G14: frozen_outputs/analysis/paper_repro/01_substrate_validation/test3_counterfactual_fidelity/test3_property_summary.csv
A15: NC0117-03 | B15: Simulator 신용평점과 실제 상태를 다시 계산한 신용평점의 차이 중앙값은 DEV 10.842점, OOT 10.700점, POST 11.155점이었다. 전체 자료의 97.6%에서 Simulator 신용평점이 더 높았다. 따라서 Simulator를 실제 다음 해 신용평점의 절대값을 예측하는 모형으로 사용할 수는 없다. 다만 세 기간에서 차이의 크기가 비슷하게 나타났다는 점은 이러한 차이가 특정 기간에만 발생한 현상은 아님을 보여준다. | C15: 11.155점 | D15: 11.155 | E15: 논문값과 일치 | F15: MEDIAN(simulator_score - observed_state_score) on POST | G15: frozen_outputs/analysis/paper_repro/01_substrate_validation/test3_counterfactual_fidelity/test3_property_summary.csv
A16: NC0117-04 | B16: Simulator 신용평점과 실제 상태를 다시 계산한 신용평점의 차이 중앙값은 DEV 10.842점, OOT 10.700점, POST 11.155점이었다. 전체 자료의 97.6%에서 Simulator 신용평점이 더 높았다. 따라서 Simulator를 실제 다음 해 신용평점의 절대값을 예측하는 모형으로 사용할 수는 없다. 다만 세 기간에서 차이의 크기가 비슷하게 나타났다는 점은 이러한 차이가 특정 기간에만 발생한 현상은 아님을 보여준다. | C16: 97.6% | D16: 97.6 | E16: 논문값과 일치 | F16: 100 * MEAN(simulator_score - observed_state_score > 0) | G16: frozen_outputs/analysis/paper_repro/01_substrate_validation/test3_counterfactual_fidelity/test3_property_summary.csv
A17: NC0119-01 | B17: OOT에서 Simulator 신용평점과 실제 상태 신용평점의 기업 순위상관은 0.903이었다. Simulator가 신용평점을 실제보다 높게 계산하더라도 상대적으로 우량한 기업과 취약한 기업의 순서는 대체로 유지되었다. | C17: 0.903 | D17: 0.903 | E17: 논문값과 일치 | F17: SPEARMAN(simulator_score, observed_state_score) on OOT | G17: frozen_outputs/analysis/paper_repro/01_substrate_validation/test3_counterfactual_fidelity/test3_property_summary.csv
A18: NC0120-02 | B18: P3에서는 DEV의 신용평점 차이 중앙값 10.8418점을 보정값으로 정해 OOT와 POST에도 그대로 적용하였다. OOT 657개 사례 중 471개의 상승·하락 방향이 일치하여 방향일치율은 71.7%였다. DEV는 71.2%, POST는 73.6%였다. 이는 Simulator로 생성한 재무정보 기반 점수와 실제 재무정보의 신용평점 변화방향을 비교한 결과다. | C18: 657개 | D18: 657 | E18: 논문값과 일치 | F18: COUNT(valid OOT direction-comparison rows) | G18: frozen_outputs/analysis/paper_repro/01_substrate_validation/test3_counterfactual_fidelity/test3_property_summary.csv
A19: NC0120-03 | B19: P3에서는 DEV의 신용평점 차이 중앙값 10.8418점을 보정값으로 정해 OOT와 POST에도 그대로 적용하였다. OOT 657개 사례 중 471개의 상승·하락 방향이 일치하여 방향일치율은 71.7%였다. DEV는 71.2%, POST는 73.6%였다. 이는 Simulator로 생성한 재무정보 기반 점수와 실제 재무정보의 신용평점 변화방향을 비교한 결과다. | C19: 471개 | D19: 471 | E19: 논문값과 일치 | F19: OOT 행 중 방향 판정이 가능한 행을 고른 뒤 direction_match = 1인 기업-연도 행의 개수; 선택 실행의 Oracle 반사실 적합도 행자료에서 재계산 | G19: frozen_outputs/analysis/paper_repro/01_substrate_validation/test3_counterfactual_fidelity/test3_rows.csv embedded://thesis-output-calculation/derived/reviewer_core_direct_calculations.csv
A20: NC0120-04 | B20: P3에서는 DEV의 신용평점 차이 중앙값 10.8418점을 보정값으로 정해 OOT와 POST에도 그대로 적용하였다. OOT 657개 사례 중 471개의 상승·하락 방향이 일치하여 방향일치율은 71.7%였다. DEV는 71.2%, POST는 73.6%였다. 이는 Simulator로 생성한 재무정보 기반 점수와 실제 재무정보의 신용평점 변화방향을 비교한 결과다. | C20: 71.7% | D20: 71.7 | E20: 논문값과 일치 | F20: 100 * MEAN(direction_match) on OOT after fixed DEV wedge adjustment | G20: frozen_outputs/analysis/paper_repro/01_substrate_validation/test3_counterfactual_fidelity/test3_property_summary.csv
A21: NC0120-05 | B21: P3에서는 DEV의 신용평점 차이 중앙값 10.8418점을 보정값으로 정해 OOT와 POST에도 그대로 적용하였다. OOT 657개 사례 중 471개의 상승·하락 방향이 일치하여 방향일치율은 71.7%였다. DEV는 71.2%, POST는 73.6%였다. 이는 Simulator로 생성한 재무정보 기반 점수와 실제 재무정보의 신용평점 변화방향을 비교한 결과다. | C21: 71.2% | D21: 71.2 | E21: 논문값과 일치 | F21: 100 * MEAN(direction_match) on DEV | G21: frozen_outputs/analysis/paper_repro/01_substrate_validation/test3_counterfactual_fidelity/test3_property_summary.csv
A22: NC0120-06 | B22: P3에서는 DEV의 신용평점 차이 중앙값 10.8418점을 보정값으로 정해 OOT와 POST에도 그대로 적용하였다. OOT 657개 사례 중 471개의 상승·하락 방향이 일치하여 방향일치율은 71.7%였다. DEV는 71.2%, POST는 73.6%였다. 이는 Simulator로 생성한 재무정보 기반 점수와 실제 재무정보의 신용평점 변화방향을 비교한 결과다. | C22: 73.6% | D22: 73.6 | E22: 논문값과 일치 | F22: 100 * MEAN(direction_match) on POST | G22: frozen_outputs/analysis/paper_repro/01_substrate_validation/test3_counterfactual_fidelity/test3_property_summary.csv
A25: 계산 데이터: test3_dev_oot_post
A26: 입력 파일 | B26: data/analysis/paper_repro/01_substrate_validation/test3_counterfactual_fidelity/test3_property_summary.csv
A27: 선택 조건 | B27: [{"column": "property", "op": "in", "values": ["P1_wedge", "P2_rank", "P3_direction"]}, {"column": "metric", "op": "in", "values": ["median", "spearman", "agreement"]}, {"column": "split", "op": "in", "values": ["dev", "oot", "post"]}]
A28: 분석 단위 | B28: property; metric; split
A29: 집계 | B29: PRODUCER_AGGREGATE_NO_REAGGREGATION
A30: property | B30: metric | C30: split | D30: value | E30: n | F30: ci95_lo | G30: ci95_hi
A31: ='SOURCE'!A11 | B31: ='SOURCE'!B11 | C31: ='SOURCE'!C11 | D31: ='SOURCE'!D11 | E31: ='SOURCE'!E11 | F31: ='SOURCE'!F11 | G31: ='SOURCE'!G11
A32: ='SOURCE'!A13 | B32: ='SOURCE'!B13 | C32: ='SOURCE'!C13 | D32: ='SOURCE'!D13 | E32: ='SOURCE'!E13 | F32: ='SOURCE'!F13 | G32: ='SOURCE'!G13
A33: ='SOURCE'!A14 | B33: ='SOURCE'!B14 | C33: ='SOURCE'!C14 | D33: ='SOURCE'!D14 | E33: ='SOURCE'!E14 | F33: ='SOURCE'!F14 | G33: ='SOURCE'!G14
A34: ='SOURCE'!A15 | B34: ='SOURCE'!B15 | C34: ='SOURCE'!C15 | D34: ='SOURCE'!D15 | E34: ='SOURCE'!E15 | F34: ='SOURCE'!F15 | G34: ='SOURCE'!G15
A35: ='SOURCE'!A17 | B35: ='SOURCE'!B17 | C35: ='SOURCE'!C17 | D35: ='SOURCE'!D17 | E35: ='SOURCE'!E17 | F35: ='SOURCE'!F17 | G35: ='SOURCE'!G17
A36: ='SOURCE'!A18 | B36: ='SOURCE'!B18 | C36: ='SOURCE'!C18 | D36: ='SOURCE'!D18 | E36: ='SOURCE'!E18 | F36: ='SOURCE'!F18 | G36: ='SOURCE'!G18
A37: ='SOURCE'!A19 | B37: ='SOURCE'!B19 | C37: ='SOURCE'!C19 | D37: ='SOURCE'!D19 | E37: ='SOURCE'!E19 | F37: ='SOURCE'!F19 | G37: ='SOURCE'!G19
A38: ='SOURCE'!A21 | B38: ='SOURCE'!B21 | C38: ='SOURCE'!C21 | D38: ='SOURCE'!D21 | E38: ='SOURCE'!E21 | F38: ='SOURCE'!F21 | G38: ='SOURCE'!G21
A39: ='SOURCE'!A22 | B39: ='SOURCE'!B22 | C39: ='SOURCE'!C22 | D39: ='SOURCE'!D22 | E39: ='SOURCE'!E22 | F39: ='SOURCE'!F22 | G39: ='SOURCE'!G22
A42: 계산 데이터: test3_wedge_share_positive
A43: 입력 파일 | B43: data/analysis/paper_repro/01_substrate_validation/test3_counterfactual_fidelity/test3_property_summary.csv
A44: 선택 조건 | B44: [{"column": "property", "op": "equals", "value": "P1_wedge"}, {"column": "metric", "op": "equals", "value": "share_positive"}, {"column": "split", "op": "equals", "value": "overall"}]
A45: 분석 단위 | B45: property; metric; split
A46: 집계 | B46: PRODUCER_AGGREGATE_NO_REAGGREGATION
A47: property | B47: metric | C47: split | D47: value | E47: n
A48: ='SOURCE'!A8 | B48: ='SOURCE'!B8 | C48: ='SOURCE'!C8 | D48: ='SOURCE'!D8 | E48: ='SOURCE'!E8

Sheet PAPER_TABLE
A1: T4-2 · 논문 표 작업용 결과
A2: ANALYSIS에서 계산된 값만 연결한 최종 작업표입니다. Excel에서 정렬·피벗·표시형식만 조정하면 됩니다.
A4: 계산 결과: test3_dev_oot_post
A5: ='CALCULATION'!A30 | B5: ='CALCULATION'!B30 | C5: ='CALCULATION'!C30 | D5: ='CALCULATION'!D30 | E5: ='CALCULATION'!E30 | F5: ='CALCULATION'!F30 | G5: ='CALCULATION'!G30
A6: ='CALCULATION'!A31 | B6: ='CALCULATION'!B31 | C6: ='CALCULATION'!C31 | D6: ='CALCULATION'!D31 | E6: ='CALCULATION'!E31 | F6: ='CALCULATION'!F31 | G6: ='CALCULATION'!G31
A7: ='CALCULATION'!A32 | B7: ='CALCULATION'!B32 | C7: ='CALCULATION'!C32 | D7: ='CALCULATION'!D32 | E7: ='CALCULATION'!E32 | F7: ='CALCULATION'!F32 | G7: ='CALCULATION'!G32
A8: ='CALCULATION'!A33 | B8: ='CALCULATION'!B33 | C8: ='CALCULATION'!C33 | D8: ='CALCULATION'!D33 | E8: ='CALCULATION'!E33 | F8: ='CALCULATION'!F33 | G8: ='CALCULATION'!G33
A9: ='CALCULATION'!A34 | B9: ='CALCULATION'!B34 | C9: ='CALCULATION'!C34 | D9: ='CALCULATION'!D34 | E9: ='CALCULATION'!E34 | F9: ='CALCULATION'!F34 | G9: ='CALCULATION'!G34
A10: ='CALCULATION'!A35 | B10: ='CALCULATION'!B35 | C10: ='CALCULATION'!C35 | D10: ='CALCULATION'!D35 | E10: ='CALCULATION'!E35 | F10: ='CALCULATION'!F35 | G10: ='CALCULATION'!G35
A11: ='CALCULATION'!A36 | B11: ='CALCULATION'!B36 | C11: ='CALCULATION'!C36 | D11: ='CALCULATION'!D36 | E11: ='CALCULATION'!E36 | F11: ='CALCULATION'!F36 | G11: ='CALCULATION'!G36
A12: ='CALCULATION'!A37 | B12: ='CALCULATION'!B37 | C12: ='CALCULATION'!C37 | D12: ='CALCULATION'!D37 | E12: ='CALCULATION'!E37 | F12: ='CALCULATION'!F37 | G12: ='CALCULATION'!G37
A13: ='CALCULATION'!A38 | B13: ='CALCULATION'!B38 | C13: ='CALCULATION'!C38 | D13: ='CALCULATION'!D38 | E13: ='CALCULATION'!E38 | F13: ='CALCULATION'!F38 | G13: ='CALCULATION'!G38
A14: ='CALCULATION'!A39 | B14: ='CALCULATION'!B39 | C14: ='CALCULATION'!C39 | D14: ='CALCULATION'!D39 | E14: ='CALCULATION'!E39 | F14: ='CALCULATION'!F39 | G14: ='CALCULATION'!G39
A17: 계산 결과: test3_wedge_share_positive
A18: ='CALCULATION'!A47 | B18: ='CALCULATION'!B47 | C18: ='CALCULATION'!C47 | D18: ='CALCULATION'!D47 | E18: ='CALCULATION'!E47
A19: ='CALCULATION'!A48 | B19: ='CALCULATION'!B48 | C19: ='CALCULATION'!C48 | D19: ='CALCULATION'!D48 | E19: ='CALCULATION'!E48
