Workbook

Sheet README
A1: T7-1 · 표 7-1. 연구질문·가설·후속 실증확장의 최종 판정
A2: 논문 인쇄값을 계산 입력으로 쓰지 않고, 선택 실행의 실제 산출물에서 값을 계산한 Excel입니다.
A4: 항목 | B4: 내용
A5: 선택 실행 | B5: V11_FINAL_FROZEN_REPLAY_RESUME
A6: 실행 방식 | B6: FrozenReplay
A7: 논문 항목 읽기 | B7: 논문 DOCX에서 번호·제목·위치만 동적으로 읽음
A8: 논문 위치 | B8: 7.2 연구질문·가설 및 후속 실증확장의 판정 · 인쇄면 96
A9: 관측·집계 단위 | B9: cohort_id + budget_label + contrast; contrast + mode + backend_label
A10: 선택 조건 | B10: [[{"column": "oracle_backend", "op": "equals", "value": "alpha"}]]
A11: 계산 방법 | B11: 계산 가능한 결과는 실행 산출물에서 계산하고 정의·설정은 별도로 구분
A12: 생산 코드 | B12: analysis synthesis from registered hypothesis tests
A13: 실제 입력 산출물 | B13: frozen_outputs/analysis/paper_repro/02_llm_hypothesis_tests/holm_h1_h3/holm_H1_score.csv frozen_outputs/analysis/paper_repro/02_llm_hypothesis_tests/holm_h1_h3/holm_H3_reference.csv embedded://selected-run-output/data/analysis/paper_repro/05_extension_e3_e4/e3_c4r_journal/v3_matched/c4r_matched_v3_contrasts.csv

Sheet SOURCE
A1: T7-1 · 실제 입력 산출물
A2: 선택 실행에서 읽은 실제 중간·최종 산출물입니다. 아래 ANALYSIS가 이 셀들을 직접 참조합니다.
A4: 입력 1: frozen_outputs/analysis/paper_repro/02_llm_hypothesis_tests/holm_h1_h3/holm_H1_score.csv
A5: 파일 크기(bytes) | B5: 3433 | C5: 생산 코드 | D5: analysis synthesis from registered hypothesis tests | E5: SHA256 | F5: 8556C662B821B4ACDB6EE66BB02CC093C7C8E86C5B6347D8552F19266C0CB2F3 | G5: 읽기 상태 | H5: OK
A6: hypothesis | B6: contrast | C6: policy_a | D6: policy_b | E6: mode | F6: backend_label | G6: run_dir | H6: n_pairs | I6: n_nonzero_pairs | J6: mean_gap | K6: median_gap | L6: wilcoxon_p_raw | M6: holm_family | N6: wilcoxon_p_holm | O6: sig_holm
A7: H1_score | B7: C5-C4 | C7: C4 | D7: C5 | E7: candidate_selection | F7: ICb_gpt54mini_p50_live_seed1 | G7: embedded://historical-source/data/final_freeze/llm_runs/ICb_gpt54mini_p50_live_seed1/stage9_llm_rl_comparison | H7: 575 | I7: 79 | J7: 0.023674402 | K7: 0 | L7: 0.057257904 | M7: H1_score:candidate_selection | N7: 0.11451581 | O7: n.s.
A8: H1_score | B8: C5-C4 | C8: C4 | D8: C5 | E8: free_form_10d | F8: ICb_gpt54mini_p50_live_seed1 | G8: embedded://historical-source/data/final_freeze/llm_runs/ICb_gpt54mini_p50_live_seed1/stage9_llm_rl_comparison | H8: 575 | I8: 245 | J8: -0.24458485 | K8: 0 | L8: 2.4220305e-17 | M8: H1_score:free_form_10d | N8: 7.2660916e-17 | O8: ***
A9: H1_score | B9: C7-C6 | C9: C6 | D9: C7 | E9: free_form_10d | F9: ICb_gpt54mini_p50_live_seed1 | G9: embedded://historical-source/data/final_freeze/llm_runs/ICb_gpt54mini_p50_live_seed1/stage9_llm_rl_comparison | H9: 575 | I9: 251 | J9: -0.36563269 | K9: 0 | L9: 1.7511543e-26 | M9: H1_score:free_form_10d | N9: 8.7557714e-26 | O9: ***
A10: H1_score | B10: C5-C4 | C10: C4 | D10: C5 | E10: candidate_selection | F10: ICb_gpt41mini_p50_live_seed1_postpatch_20260705_153820 | G10: embedded://historical-source/data/final_freeze/llm_runs/ICb_gpt41mini_p50_live_seed1_postpatch_20260705_153820/stage9_llm_rl_comparison | H10: 575 | I10: 158 | J10: 0.0081689981 | K10: 0 | L10: 0.20812466 | M10: H1_score:candidate_selection | N10: 0.20812466 | O10: n.s.
A11: H1_score | B11: C5-C4 | C11: C4 | D11: C5 | E11: free_form_10d | F11: ICb_gpt41mini_p50_live_seed1_postpatch_20260705_153820 | G11: embedded://historical-source/data/final_freeze/llm_runs/ICb_gpt41mini_p50_live_seed1_postpatch_20260705_153820/stage9_llm_rl_comparison | H11: 575 | I11: 183 | J11: -0.19201133 | K11: 0 | L11: 5.873757e-17 | M11: H1_score:free_form_10d | N11: 1.1747514e-16 | O11: ***
A12: H1_score | B12: C7-C6 | C12: C6 | D12: C7 | E12: free_form_10d | F12: ICb_gpt41mini_p50_live_seed1_postpatch_20260705_153820 | G12: embedded://historical-source/data/final_freeze/llm_runs/ICb_gpt41mini_p50_live_seed1_postpatch_20260705_153820/stage9_llm_rl_comparison | H12: 575 | I12: 279 | J12: -0.48592464 | K12: 0 | L12: 1.258151e-35 | M12: H1_score:free_form_10d | N12: 7.5489063e-35 | O12: ***
A13: H1_score | B13: C5-C4 | C13: C4 | D13: C5 | E13: candidate_selection | F13: ICb_haiku45_p50_live_seed1_postpatch_20260705_190541 | G13: embedded://historical-source/data/final_freeze/llm_runs/ICb_haiku45_p50_live_seed1_postpatch_20260705_190541/stage9_llm_rl_comparison | H13: 575 | I13: 76 | J13: 0.086280353 | K13: 0 | L13: 4.042874e-08 | M13: H1_score:candidate_selection | N13: 1.2128622e-07 | O13: ***
A14: H1_score | B14: C5-C4 | C14: C4 | D14: C5 | E14: free_form_10d | F14: ICb_haiku45_p50_live_seed1_postpatch_20260705_190541 | G14: embedded://historical-source/data/final_freeze/llm_runs/ICb_haiku45_p50_live_seed1_postpatch_20260705_190541/stage9_llm_rl_comparison | H14: 569 | I14: 197 | J14: -0.23781162 | K14: 0 | L14: 8.6887126e-18 | M14: H1_score:free_form_10d | N14: 3.475485e-17 | O14: ***
A15: H1_score | B15: C7-C6 | C15: C6 | D15: C7 | E15: free_form_10d | F15: ICb_haiku45_p50_live_seed1_postpatch_20260705_190541 | G15: embedded://historical-source/data/final_freeze/llm_runs/ICb_haiku45_p50_live_seed1_postpatch_20260705_190541/stage9_llm_rl_comparison | H15: 563 | I15: 204 | J15: -0.2342626 | K15: 0 | L15: 2.3279436e-10 | M15: H1_score:free_form_10d | N15: 2.3279436e-10 | O15: ***
A18: 입력 2: frozen_outputs/analysis/paper_repro/02_llm_hypothesis_tests/holm_h1_h3/holm_H3_reference.csv
A19: 파일 크기(bytes) | B19: 2407 | C19: 생산 코드 | D19: analysis synthesis from registered hypothesis tests | E19: SHA256 | F19: 8E9CF323DD0CC6DB9EB19A3C10067D8C4F6774B2FF42D5E0B7FA58D458D45FB1 | G19: 읽기 상태 | H19: OK
A20: hypothesis | B20: contrast | C20: policy_a | D20: policy_b | E20: mode | F20: backend_label | G20: run_dir | H20: n_pairs | I20: n_nonzero_pairs | J20: mean_gap | K20: median_gap | L20: wilcoxon_p_raw | M20: holm_family | N20: wilcoxon_p_holm | O20: sig_holm
A21: H3_reference | B21: C6-C6X | C21: C6X | D21: C6 | E21: candidate_selection | F21: ICb_gpt54mini_p50_live_seed1 | G21: embedded://historical-source/data/final_freeze/llm_runs/ICb_gpt54mini_p50_live_seed1/stage9_llm_rl_comparison | H21: 575 | I21: 53 | J21: 0.039148217 | K21: 0 | L21: 0.0041766708 | M21: H3_reference:candidate_selection | N21: 0.0083533415 | O21: **
A22: H3_reference | B22: C6-C6X | C22: C6X | D22: C6 | E22: free_form_10d | F22: ICb_gpt54mini_p50_live_seed1 | G22: embedded://historical-source/data/final_freeze/llm_runs/ICb_gpt54mini_p50_live_seed1/stage9_llm_rl_comparison | H22: 575 | I22: 151 | J22: 0.17397525 | K22: 0 | L22: 4.0221885e-11 | M22: H3_reference:free_form_10d | N22: 8.0443769e-11 | O22: ***
A23: H3_reference | B23: C6-C6X | C23: C6X | D23: C6 | E23: candidate_selection | F23: ICb_gpt41mini_p50_live_seed1_postpatch_20260705_153820 | G23: embedded://historical-source/data/final_freeze/llm_runs/ICb_gpt41mini_p50_live_seed1_postpatch_20260705_153820/stage9_llm_rl_comparison | H23: 575 | I23: 111 | J23: 0.079683506 | K23: 0 | L23: 0.00045475479 | M23: H3_reference:candidate_selection | N23: 0.0013642644 | O23: **
A24: H3_reference | B24: C6-C6X | C24: C6X | D24: C6 | E24: free_form_10d | F24: ICb_gpt41mini_p50_live_seed1_postpatch_20260705_153820 | G24: embedded://historical-source/data/final_freeze/llm_runs/ICb_gpt41mini_p50_live_seed1_postpatch_20260705_153820/stage9_llm_rl_comparison | H24: 575 | I24: 195 | J24: 0.30967882 | K24: 0 | L24: 5.1482582e-19 | M24: H3_reference:free_form_10d | N24: 1.5444774e-18 | O24: ***
A25: H3_reference | B25: C6-C6X | C25: C6X | D25: C6 | E25: candidate_selection | F25: ICb_haiku45_p50_live_seed1_postpatch_20260705_190541 | G25: embedded://historical-source/data/final_freeze/llm_runs/ICb_haiku45_p50_live_seed1_postpatch_20260705_190541/stage9_llm_rl_comparison | H25: 575 | I25: 33 | J25: 0.015852154 | K25: 0 | L25: 0.098329826 | M25: H3_reference:candidate_selection | N25: 0.098329826 | O25: n.s.
A26: H3_reference | B26: C6-C6X | C26: C6X | D26: C6 | E26: free_form_10d | F26: ICb_haiku45_p50_live_seed1_postpatch_20260705_190541 | G26: embedded://historical-source/data/final_freeze/llm_runs/ICb_haiku45_p50_live_seed1_postpatch_20260705_190541/stage9_llm_rl_comparison | H26: 575 | I26: 136 | J26: 0.17893674 | K26: 0 | L26: 1.4568967e-10 | M26: H3_reference:free_form_10d | N26: 1.4568967e-10 | O26: ***
A29: 입력 3: embedded://selected-run-output/data/analysis/paper_repro/05_extension_e3_e4/e3_c4r_journal/v3_matched/c4r_matched_v3_contrasts.csv
A30: 파일 크기(bytes) | B30: 21156 | C30: 생산 코드 | D30: analysis synthesis from registered hypothesis tests | E30: SHA256 | F30: F6A52321BC31E9151900CC8FFCF60BB32B2D3D6E3DB021785144463DA45C7483 | G30: 읽기 상태 | H30: OK
A31: cohort_id | B31: backend_id | C31: run_role | D31: budget_label | E31: l1_budget | F31: oracle_backend | G31: contrast | H31: n_pairs | I31: mean_increment | J31: median_increment | K31: win_count | L31: tie_count | M31: loss_count | N31: wilcoxon_p_raw | O31: wilcoxon_p_holm_across_budgets | P31: holm_family_across_budgets | Q31: sig_holm_across_budgets
A32: gemini31flashlite | B32: google_gemini-3.1-flash-lite_generate-content_thinking-low_maxout-4096_json | C32: paper_c4r_journal_ext_gemini31flashlite | D32: 0p75 | E32: 0.75 | F32: alpha | G32: reference_content_conditional | H32: 575 | I32: -0.00098336451 | J32: 0 | K32: 54 | L32: 477 | M32: 44 | N32: 0.67705344 | O32: 0.67705344 | P32: cohort_oracle_contrast_across_budget_arms | Q32: n.s.
A33: gemini31flashlite | B33: google_gemini-3.1-flash-lite_generate-content_thinking-low_maxout-4096_json | C33: paper_c4r_journal_ext_gemini31flashlite | D33: 1p27 | E33: 1.27 | F33: alpha | G33: reference_content_conditional | H33: 575 | I33: 0.045167937 | J33: 0 | K33: 72 | L33: 463 | M33: 40 | N33: 0.017939618 | O33: 0.035879237 | P33: cohort_oracle_contrast_across_budget_arms | Q33: *
A34: gemini31flashlite | B34: google_gemini-3.1-flash-lite_generate-content_thinking-low_maxout-4096_json | C34: paper_c4r_journal_ext_gemini31flashlite | D34: 2p00 | E34: 2 | F34: alpha | G34: reference_content_conditional | H34: 575 | I34: 0.081483834 | J34: 0 | K34: 85 | L34: 449 | M34: 41 | N34: 0.000491999 | O34: 0.001475997 | P34: cohort_oracle_contrast_across_budget_arms | Q34: **
A35: gemini31flashlite | B35: google_gemini-3.1-flash-lite_generate-content_thinking-low_maxout-4096_json | C35: paper_c4r_journal_ext_gemini31flashlite | D35: unbounded | F35: alpha | G35: reference_content_conditional | H35: 575 | I35: 0.40240621 | J35: 0 | K35: 209 | L35: 347 | M35: 19 | N35: 1.5434023e-30 | O35: 6.1736094e-30 | P35: cohort_oracle_contrast_across_budget_arms | Q35: ***
A36: gemini31flashlite | B36: google_gemini-3.1-flash-lite_generate-content_thinking-low_maxout-4096_json | C36: paper_c4r_journal_ext_gemini31flashlite | D36: 0p75 | E36: 0.75 | F36: beta | G36: reference_content_conditional | H36: 575 | I36: -0.0052317656 | J36: 0 | K36: 258 | L36: 87 | M36: 230 | N36: 0.38633721 | O36: 0.38633721 | P36: cohort_oracle_contrast_across_budget_arms | Q36: n.s.
A37: gemini31flashlite | B37: google_gemini-3.1-flash-lite_generate-content_thinking-low_maxout-4096_json | C37: paper_c4r_journal_ext_gemini31flashlite | D37: 1p27 | E37: 1.27 | F37: beta | G37: reference_content_conditional | H37: 575 | I37: 0.0065415303 | J37: 9.1978503e-05 | K37: 295 | L37: 73 | M37: 207 | N37: 0.0011800158 | O37: 0.0035400474 | P37: cohort_oracle_contrast_across_budget_arms | Q37: **
A38: gemini31flashlite | B38: google_gemini-3.1-flash-lite_generate-content_thinking-low_maxout-4096_json | C38: paper_c4r_journal_ext_gemini31flashlite | D38: 2p00 | E38: 2 | F38: beta | G38: reference_content_conditional | H38: 575 | I38: 0.0075570021 | J38: 0.0001845743 | K38: 290 | L38: 53 | M38: 232 | N38: 0.006930842 | O38: 0.013861684 | P38: cohort_oracle_contrast_across_budget_arms | Q38: *
A39: gemini31flashlite | B39: google_gemini-3.1-flash-lite_generate-content_thinking-low_maxout-4096_json | C39: paper_c4r_journal_ext_gemini31flashlite | D39: unbounded | F39: beta | G39: reference_content_conditional | H39: 575 | I39: 0.082272127 | J39: 0.049246315 | K39: 410 | L39: 123 | M39: 42 | N39: 5.7083405e-67 | O39: 2.2833362e-66 | P39: cohort_oracle_contrast_across_budget_arms | Q39: ***
A40: gemini31flashlite | B40: google_gemini-3.1-flash-lite_generate-content_thinking-low_maxout-4096_json | C40: paper_c4r_journal_ext_gemini31flashlite | D40: 0p75 | E40: 0.75 | F40: gamma | G40: reference_content_conditional | H40: 575 | I40: 0.0018276959 | J40: 0 | K40: 85 | L40: 424 | M40: 66 | N40: 0.62580046 | O40: 0.62580046 | P40: cohort_oracle_contrast_across_budget_arms | Q40: n.s.
A41: gemini31flashlite | B41: google_gemini-3.1-flash-lite_generate-content_thinking-low_maxout-4096_json | C41: paper_c4r_journal_ext_gemini31flashlite | D41: 1p27 | E41: 1.27 | F41: gamma | G41: reference_content_conditional | H41: 575 | I41: 0.079484364 | J41: 0 | K41: 114 | L41: 402 | M41: 59 | N41: 3.7984784e-07 | O41: 1.1395435e-06 | P41: cohort_oracle_contrast_across_budget_arms | Q41: ***
A42: gemini31flashlite | B42: google_gemini-3.1-flash-lite_generate-content_thinking-low_maxout-4096_json | C42: paper_c4r_journal_ext_gemini31flashlite | D42: 2p00 | E42: 2 | F42: gamma | G42: reference_content_conditional | H42: 575 | I42: 0.028257244 | J42: 0 | K42: 116 | L42: 357 | M42: 102 | N42: 0.10113196 | O42: 0.20226392 | P42: cohort_oracle_contrast_across_budget_arms | Q42: n.s.
A43: gemini31flashlite | B43: google_gemini-3.1-flash-lite_generate-content_thinking-low_maxout-4096_json | C43: paper_c4r_journal_ext_gemini31flashlite | D43: unbounded | F43: gamma | G43: reference_content_conditional | H43: 575 | I43: 0.29317348 | J43: 0 | K43: 221 | L43: 294 | M43: 60 | N43: 2.9614245e-31 | O43: 1.1845698e-30 | P43: cohort_oracle_contrast_across_budget_arms | Q43: ***
A44: gemini31flashlite | B44: google_gemini-3.1-flash-lite_generate-content_thinking-low_maxout-4096_json | C44: paper_c4r_journal_ext_gemini31flashlite | D44: 0p75 | E44: 0.75 | F44: alpha | G44: reference_plus_revision_package | H44: 575 | I44: 0.069345489 | J44: 0 | K44: 80 | L44: 464 | M44: 31 | N44: 8.8566801e-05 | O44: 8.8566801e-05 | P44: cohort_oracle_contrast_across_budget_arms | Q44: ***
A45: gemini31flashlite | B45: google_gemini-3.1-flash-lite_generate-content_thinking-low_maxout-4096_json | C45: paper_c4r_journal_ext_gemini31flashlite | D45: 1p27 | E45: 1.27 | F45: alpha | G45: reference_plus_revision_package | H45: 575 | I45: 0.11566099 | J45: 0 | K45: 106 | L45: 436 | M45: 33 | N45: 6.8831305e-07 | O45: 1.3766261e-06 | P45: cohort_oracle_contrast_across_budget_arms | Q45: ***
...

Sheet CALCULATION
A1: T7-1 · 분석 과정
A2: 필터·분석단위와 실제 계산 결과입니다. 수치 셀은 SOURCE를 직접 참조합니다.
A4: 항목 | B4: 내용
A5: 계산 방법 | B5: 계산 가능한 결과는 실행 산출물에서 계산하고 정의·설정은 별도로 구분
A6: 생산 코드 | B6: analysis synthesis from registered hypothesis tests
A7: 선택 실행 | B7: V11_FINAL_FROZEN_REPLAY_RESUME
A11: 이 표·그림과 연결된 본문 핵심 수치
A12: 수치 ID | B12: 본문 주장 | C12: 논문 표시값 | D12: 재계산값 | E12: 확인 결과 | F12: 계산식 | G12: 실제 입력 산출물
A13: NC0256-02 | B13: RQ2는 각 정책의 행동이 비교정책과 견주었을 때 어떤 정책가치를 보였는지를 묻는다. Oracle-α에서 11개 표준 후보행동의 상한은 +1.131이었고, Candidate-IQL은 +0.630으로 무행동보다 높은 정책가치를 보였다. GPT-5.4-mini의 IC-b 조건에서는 표준 후보선택 C4가 +0.566, 자유작성 C4가 +0.885, 자유작성 C6이 +1.103이었다. C6는 Candidate-IQL을 참조정책으로 LLM에 제공한 조건이다. | C13: +1.131 | D13: 계산 불가 | E13: 현재 산출물로 계산할 수 없음 | F13: MEAN_i(MAX over ten fixed candidate actions and no-op of [R_score_alpha(action_i) - R_score_alpha(noop_i)]) | G13: embedded://selected-run-output/data/final_freeze/stage6_candidate_selector_eval/multi_oracle_policy_eval.parquet; frozen_outputs/final_freeze/stage6_candidate_selector_eval/derived_comparators_runtime.json; frozen_outputs/final_freeze/stage6_multi_oracle_eval/final_policy_summary.csv; frozen_outputs/final_freeze/stage6_multi_oracle_eval/summary_by_policy_alpha.csv; frozen_outputs/final_freeze/stage6_multi_oracle_eval/summary_by_policy_beta.csv; frozen_outputs/final_freeze/stage6_multi_oracle_eval/summary_by_policy_gamma.csv
A14: NC0256-03 | B14: RQ2는 각 정책의 행동이 비교정책과 견주었을 때 어떤 정책가치를 보였는지를 묻는다. Oracle-α에서 11개 표준 후보행동의 상한은 +1.131이었고, Candidate-IQL은 +0.630으로 무행동보다 높은 정책가치를 보였다. GPT-5.4-mini의 IC-b 조건에서는 표준 후보선택 C4가 +0.566, 자유작성 C4가 +0.885, 자유작성 C6이 +1.103이었다. C6는 Candidate-IQL을 참조정책으로 LLM에 제공한 조건이다. | C14: +0.630 | D14: 0.63 | E14: 논문값과 일치 | F14: MEAN_i(R_score_alpha(action_i) - R_score_alpha(noop_i)) | G14: frozen_outputs/final_freeze/stage6_multi_oracle_eval/final_policy_summary.csv
A17: 계산 데이터: h1_evidence
A18: 입력 파일 | B18: data/analysis/paper_repro/02_llm_hypothesis_tests/holm_h1_h3/holm_H1_score.csv
A19: 선택 조건 | B19: []
A20: 분석 단위 | B20: contrast; mode; backend_label
A21: 집계 | B21: PRODUCER_AGGREGATE_NO_REAGGREGATION
A22: hypothesis | B22: contrast | C22: mode | D22: backend_label | E22: n_pairs | F22: mean_gap | G22: wilcoxon_p_holm | H22: sig_holm
A23: ='SOURCE'!A7 | B23: ='SOURCE'!B7 | C23: ='SOURCE'!E7 | D23: ='SOURCE'!F7 | E23: ='SOURCE'!H7 | F23: ='SOURCE'!J7 | G23: ='SOURCE'!N7 | H23: ='SOURCE'!O7
A24: ='SOURCE'!A8 | B24: ='SOURCE'!B8 | C24: ='SOURCE'!E8 | D24: ='SOURCE'!F8 | E24: ='SOURCE'!H8 | F24: ='SOURCE'!J8 | G24: ='SOURCE'!N8 | H24: ='SOURCE'!O8
A25: ='SOURCE'!A9 | B25: ='SOURCE'!B9 | C25: ='SOURCE'!E9 | D25: ='SOURCE'!F9 | E25: ='SOURCE'!H9 | F25: ='SOURCE'!J9 | G25: ='SOURCE'!N9 | H25: ='SOURCE'!O9
A26: ='SOURCE'!A10 | B26: ='SOURCE'!B10 | C26: ='SOURCE'!E10 | D26: ='SOURCE'!F10 | E26: ='SOURCE'!H10 | F26: ='SOURCE'!J10 | G26: ='SOURCE'!N10 | H26: ='SOURCE'!O10
A27: ='SOURCE'!A11 | B27: ='SOURCE'!B11 | C27: ='SOURCE'!E11 | D27: ='SOURCE'!F11 | E27: ='SOURCE'!H11 | F27: ='SOURCE'!J11 | G27: ='SOURCE'!N11 | H27: ='SOURCE'!O11
A28: ='SOURCE'!A12 | B28: ='SOURCE'!B12 | C28: ='SOURCE'!E12 | D28: ='SOURCE'!F12 | E28: ='SOURCE'!H12 | F28: ='SOURCE'!J12 | G28: ='SOURCE'!N12 | H28: ='SOURCE'!O12
A29: ='SOURCE'!A13 | B29: ='SOURCE'!B13 | C29: ='SOURCE'!E13 | D29: ='SOURCE'!F13 | E29: ='SOURCE'!H13 | F29: ='SOURCE'!J13 | G29: ='SOURCE'!N13 | H29: ='SOURCE'!O13
A30: ='SOURCE'!A14 | B30: ='SOURCE'!B14 | C30: ='SOURCE'!E14 | D30: ='SOURCE'!F14 | E30: ='SOURCE'!H14 | F30: ='SOURCE'!J14 | G30: ='SOURCE'!N14 | H30: ='SOURCE'!O14
A31: ='SOURCE'!A15 | B31: ='SOURCE'!B15 | C31: ='SOURCE'!E15 | D31: ='SOURCE'!F15 | E31: ='SOURCE'!H15 | F31: ='SOURCE'!J15 | G31: ='SOURCE'!N15 | H31: ='SOURCE'!O15
A34: 계산 데이터: h3_evidence
A35: 입력 파일 | B35: data/analysis/paper_repro/02_llm_hypothesis_tests/holm_h1_h3/holm_H3_reference.csv
A36: 선택 조건 | B36: []
A37: 분석 단위 | B37: contrast; mode; backend_label
A38: 집계 | B38: PRODUCER_AGGREGATE_NO_REAGGREGATION
A39: hypothesis | B39: contrast | C39: mode | D39: backend_label | E39: n_pairs | F39: mean_gap | G39: wilcoxon_p_holm | H39: sig_holm
A40: ='SOURCE'!A21 | B40: ='SOURCE'!B21 | C40: ='SOURCE'!E21 | D40: ='SOURCE'!F21 | E40: ='SOURCE'!H21 | F40: ='SOURCE'!J21 | G40: ='SOURCE'!N21 | H40: ='SOURCE'!O21
A41: ='SOURCE'!A22 | B41: ='SOURCE'!B22 | C41: ='SOURCE'!E22 | D41: ='SOURCE'!F22 | E41: ='SOURCE'!H22 | F41: ='SOURCE'!J22 | G41: ='SOURCE'!N22 | H41: ='SOURCE'!O22
A42: ='SOURCE'!A23 | B42: ='SOURCE'!B23 | C42: ='SOURCE'!E23 | D42: ='SOURCE'!F23 | E42: ='SOURCE'!H23 | F42: ='SOURCE'!J23 | G42: ='SOURCE'!N23 | H42: ='SOURCE'!O23
A43: ='SOURCE'!A24 | B43: ='SOURCE'!B24 | C43: ='SOURCE'!E24 | D43: ='SOURCE'!F24 | E43: ='SOURCE'!H24 | F43: ='SOURCE'!J24 | G43: ='SOURCE'!N24 | H43: ='SOURCE'!O24
A44: ='SOURCE'!A25 | B44: ='SOURCE'!B25 | C44: ='SOURCE'!E25 | D44: ='SOURCE'!F25 | E44: ='SOURCE'!H25 | F44: ='SOURCE'!J25 | G44: ='SOURCE'!N25 | H44: ='SOURCE'!O25
A45: ='SOURCE'!A26 | B45: ='SOURCE'!B26 | C45: ='SOURCE'!E26 | D45: ='SOURCE'!F26 | E45: ='SOURCE'!H26 | F45: ='SOURCE'!J26 | G45: ='SOURCE'!N26 | H45: ='SOURCE'!O26
A48: 계산 데이터: extension_evidence
A49: 입력 파일 | B49: data/analysis/paper_repro/05_extension_e3_e4/e3_c4r_journal/v3_matched/c4r_matched_v3_contrasts.csv
A50: 선택 조건 | B50: [{"column": "oracle_backend", "op": "equals", "value": "alpha"}]
...

Sheet PAPER_TABLE
A1: T7-1 · 논문 표 작업용 결과
A2: ANALYSIS에서 계산된 값만 연결한 최종 작업표입니다. Excel에서 정렬·피벗·표시형식만 조정하면 됩니다.
A4: 계산 결과: h1_evidence
A5: ='CALCULATION'!A22 | B5: ='CALCULATION'!B22 | C5: ='CALCULATION'!C22 | D5: ='CALCULATION'!D22 | E5: ='CALCULATION'!E22 | F5: ='CALCULATION'!F22 | G5: ='CALCULATION'!G22 | H5: ='CALCULATION'!H22
A6: ='CALCULATION'!A23 | B6: ='CALCULATION'!B23 | C6: ='CALCULATION'!C23 | D6: ='CALCULATION'!D23 | E6: ='CALCULATION'!E23 | F6: ='CALCULATION'!F23 | G6: ='CALCULATION'!G23 | H6: ='CALCULATION'!H23
A7: ='CALCULATION'!A24 | B7: ='CALCULATION'!B24 | C7: ='CALCULATION'!C24 | D7: ='CALCULATION'!D24 | E7: ='CALCULATION'!E24 | F7: ='CALCULATION'!F24 | G7: ='CALCULATION'!G24 | H7: ='CALCULATION'!H24
A8: ='CALCULATION'!A25 | B8: ='CALCULATION'!B25 | C8: ='CALCULATION'!C25 | D8: ='CALCULATION'!D25 | E8: ='CALCULATION'!E25 | F8: ='CALCULATION'!F25 | G8: ='CALCULATION'!G25 | H8: ='CALCULATION'!H25
A9: ='CALCULATION'!A26 | B9: ='CALCULATION'!B26 | C9: ='CALCULATION'!C26 | D9: ='CALCULATION'!D26 | E9: ='CALCULATION'!E26 | F9: ='CALCULATION'!F26 | G9: ='CALCULATION'!G26 | H9: ='CALCULATION'!H26
A10: ='CALCULATION'!A27 | B10: ='CALCULATION'!B27 | C10: ='CALCULATION'!C27 | D10: ='CALCULATION'!D27 | E10: ='CALCULATION'!E27 | F10: ='CALCULATION'!F27 | G10: ='CALCULATION'!G27 | H10: ='CALCULATION'!H27
A11: ='CALCULATION'!A28 | B11: ='CALCULATION'!B28 | C11: ='CALCULATION'!C28 | D11: ='CALCULATION'!D28 | E11: ='CALCULATION'!E28 | F11: ='CALCULATION'!F28 | G11: ='CALCULATION'!G28 | H11: ='CALCULATION'!H28
A12: ='CALCULATION'!A29 | B12: ='CALCULATION'!B29 | C12: ='CALCULATION'!C29 | D12: ='CALCULATION'!D29 | E12: ='CALCULATION'!E29 | F12: ='CALCULATION'!F29 | G12: ='CALCULATION'!G29 | H12: ='CALCULATION'!H29
A13: ='CALCULATION'!A30 | B13: ='CALCULATION'!B30 | C13: ='CALCULATION'!C30 | D13: ='CALCULATION'!D30 | E13: ='CALCULATION'!E30 | F13: ='CALCULATION'!F30 | G13: ='CALCULATION'!G30 | H13: ='CALCULATION'!H30
A14: ='CALCULATION'!A31 | B14: ='CALCULATION'!B31 | C14: ='CALCULATION'!C31 | D14: ='CALCULATION'!D31 | E14: ='CALCULATION'!E31 | F14: ='CALCULATION'!F31 | G14: ='CALCULATION'!G31 | H14: ='CALCULATION'!H31
A17: 계산 결과: extension_evidence
A18: ='CALCULATION'!A53 | B18: ='CALCULATION'!B53 | C18: ='CALCULATION'!C53 | D18: ='CALCULATION'!D53 | E18: ='CALCULATION'!E53 | F18: ='CALCULATION'!F53 | G18: ='CALCULATION'!G53
A19: ='CALCULATION'!A54 | B19: ='CALCULATION'!B54 | C19: ='CALCULATION'!C54 | D19: ='CALCULATION'!D54 | E19: ='CALCULATION'!E54 | F19: ='CALCULATION'!F54 | G19: ='CALCULATION'!G54
A20: ='CALCULATION'!A55 | B20: ='CALCULATION'!B55 | C20: ='CALCULATION'!C55 | D20: ='CALCULATION'!D55 | E20: ='CALCULATION'!E55 | F20: ='CALCULATION'!F55 | G20: ='CALCULATION'!G55
A21: ='CALCULATION'!A56 | B21: ='CALCULATION'!B56 | C21: ='CALCULATION'!C56 | D21: ='CALCULATION'!D56 | E21: ='CALCULATION'!E56 | F21: ='CALCULATION'!F56 | G21: ='CALCULATION'!G56
A22: ='CALCULATION'!A57 | B22: ='CALCULATION'!B57 | C22: ='CALCULATION'!C57 | D22: ='CALCULATION'!D57 | E22: ='CALCULATION'!E57 | F22: ='CALCULATION'!F57 | G22: ='CALCULATION'!G57
A23: ='CALCULATION'!A58 | B23: ='CALCULATION'!B58 | C23: ='CALCULATION'!C58 | D23: ='CALCULATION'!D58 | E23: ='CALCULATION'!E58 | F23: ='CALCULATION'!F58 | G23: ='CALCULATION'!G58
A24: ='CALCULATION'!A59 | B24: ='CALCULATION'!B59 | C24: ='CALCULATION'!C59 | D24: ='CALCULATION'!D59 | E24: ='CALCULATION'!E59 | F24: ='CALCULATION'!F59 | G24: ='CALCULATION'!G59
A25: ='CALCULATION'!A60 | B25: ='CALCULATION'!B60 | C25: ='CALCULATION'!C60 | D25: ='CALCULATION'!D60 | E25: ='CALCULATION'!E60 | F25: ='CALCULATION'!F60 | G25: ='CALCULATION'!G60
A26: ='CALCULATION'!A61 | B26: ='CALCULATION'!B61 | C26: ='CALCULATION'!C61 | D26: ='CALCULATION'!D61 | E26: ='CALCULATION'!E61 | F26: ='CALCULATION'!F61 | G26: ='CALCULATION'!G61
A27: ='CALCULATION'!A62 | B27: ='CALCULATION'!B62 | C27: ='CALCULATION'!C62 | D27: ='CALCULATION'!D62 | E27: ='CALCULATION'!E62 | F27: ='CALCULATION'!F62 | G27: ='CALCULATION'!G62
A28: ='CALCULATION'!A63 | B28: ='CALCULATION'!B63 | C28: ='CALCULATION'!C63 | D28: ='CALCULATION'!D63 | E28: ='CALCULATION'!E63 | F28: ='CALCULATION'!F63 | G28: ='CALCULATION'!G63
A29: ='CALCULATION'!A64 | B29: ='CALCULATION'!B64 | C29: ='CALCULATION'!C64 | D29: ='CALCULATION'!D64 | E29: ='CALCULATION'!E64 | F29: ='CALCULATION'!F64 | G29: ='CALCULATION'!G64
... A42: ='CALCULATION'!A77 | B42: ='CALCULATION'!B77 | C42: ='CALCULATION'!C77 | D42: ='CALCULATION'!D77 | E42: ='CALCULATION'!E77 | F42: ='CALCULATION'!F77 | G42: ='CALCULATION'!G77
A45: 계산 결과: h3_evidence
A46: ='CALCULATION'!A39 | B46: ='CALCULATION'!B39 | C46: ='CALCULATION'!C39 | D46: ='CALCULATION'!D39 | E46: ='CALCULATION'!E39 | F46: ='CALCULATION'!F39 | G46: ='CALCULATION'!G39 | H46: ='CALCULATION'!H39
A47: ='CALCULATION'!A40 | B47: ='CALCULATION'!B40 | C47: ='CALCULATION'!C40 | D47: ='CALCULATION'!D40 | E47: ='CALCULATION'!E40 | F47: ='CALCULATION'!F40 | G47: ='CALCULATION'!G40 | H47: ='CALCULATION'!H40
A48: ='CALCULATION'!A41 | B48: ='CALCULATION'!B41 | C48: ='CALCULATION'!C41 | D48: ='CALCULATION'!D41 | E48: ='CALCULATION'!E41 | F48: ='CALCULATION'!F41 | G48: ='CALCULATION'!G41 | H48: ='CALCULATION'!H41
A49: ='CALCULATION'!A42 | B49: ='CALCULATION'!B42 | C49: ='CALCULATION'!C42 | D49: ='CALCULATION'!D42 | E49: ='CALCULATION'!E42 | F49: ='CALCULATION'!F42 | G49: ='CALCULATION'!G42 | H49: ='CALCULATION'!H42
A50: ='CALCULATION'!A43 | B50: ='CALCULATION'!B43 | C50: ='CALCULATION'!C43 | D50: ='CALCULATION'!D43 | E50: ='CALCULATION'!E43 | F50: ='CALCULATION'!F43 | G50: ='CALCULATION'!G43 | H50: ='CALCULATION'!H43
A51: ='CALCULATION'!A44 | B51: ='CALCULATION'!B44 | C51: ='CALCULATION'!C44 | D51: ='CALCULATION'!D44 | E51: ='CALCULATION'!E44 | F51: ='CALCULATION'!F44 | G51: ='CALCULATION'!G44 | H51: ='CALCULATION'!H44
A52: ='CALCULATION'!A45 | B52: ='CALCULATION'!B45 | C52: ='CALCULATION'!C45 | D52: ='CALCULATION'!D45 | E52: ='CALCULATION'!E45 | F52: ='CALCULATION'!F45 | G52: ='CALCULATION'!G45 | H52: ='CALCULATION'!H45
