Workbook

Sheet README
A1: T5-5 · 표 5-5. 행동작성 방식과 외부 정책 참조 제시시점별 Oracle-α 정책가치
A2: 논문 인쇄값을 계산 입력으로 쓰지 않고, 선택 실행의 실제 산출물에서 값을 계산한 Excel입니다.
A4: 항목 | B4: 내용
A5: 선택 실행 | B5: V11_FINAL_FROZEN_REPLAY_RESUME
A6: 실행 방식 | B6: FrozenReplay
A7: 논문 항목 읽기 | B7: 논문 DOCX에서 번호·제목·위치만 동적으로 읽음
A8: 논문 위치 | B8: 5.3 외부 정책 참조의 출처와 제시시점 · 인쇄면 59
A9: 관측·집계 단위 | B9: backend_label + harness_cell
A10: 선택 조건 | B10: [[{"column": "oracle_backend", "op": "equals", "value": "alpha"}, {"column": "harness_cell", "op": "in", "values": ["C4__candidate_selection", "C5__candidate_selection", "C6__candidate_selection", "C6X__candidate_selection", "C7__candidate_selection", "C8__candidate_selection", "C6__free_form_10d", "C8__free_form_10d"]}]]
A11: 계산 방법 | B11: 같은 기업의 행동 후 Oracle 점수에서 그 기업의 무행동 Oracle 점수를 뺀 뒤 기업 단위로 집계
A12: 생산 코드 | B12: src/credit_recourse/analysis/main_harness_backend_decomposition.py
A13: 실제 입력 산출물 | B13: frozen_outputs/analysis/paper_repro/03_output_contract_diagnostics/main_harness_backend_decomposition/main_harness_backend_cell_means.csv

Sheet SOURCE
A1: T5-5 · 실제 입력 산출물
A2: 선택 실행에서 읽은 실제 중간·최종 산출물입니다. 아래 ANALYSIS가 이 셀들을 직접 참조합니다.
A4: 입력 1: frozen_outputs/analysis/paper_repro/03_output_contract_diagnostics/main_harness_backend_decomposition/main_harness_backend_cell_means.csv
A5: 파일 크기(bytes) | B5: 8883 | C5: 생산 코드 | D5: src/credit_recourse/analysis/main_harness_backend_decomposition.py | E5: SHA256 | F5: 2F7A7BF684B686F2CD9901FF6BB960F499AD3F5CFBD5A4A7B9A467FC91640769 | G5: 읽기 상태 | H5: OK
A6: oracle_backend | B6: backend_label | C6: harness_cell | D6: n_firms | E6: mean_score | F6: median_score
A7: alpha | B7: GPT-4.1-mini | C7: C4__candidate_selection | D7: 575 | E7: 0.44872513 | F7: 0
A8: alpha | B8: GPT-4.1-mini | C8: C4__free_form_10d | D8: 575 | E8: 0.78595747 | F8: 0.85904676
A9: alpha | B9: GPT-4.1-mini | C9: C5__candidate_selection | D9: 575 | E9: 0.45689413 | F9: 0
A10: alpha | B10: GPT-4.1-mini | C10: C5__free_form_10d | D10: 575 | E10: 0.59394614 | F10: 0.52620402
A11: alpha | B11: GPT-4.1-mini | C11: C6X__candidate_selection | D11: 575 | E11: 0.48234225 | F11: 0
A12: alpha | B12: GPT-4.1-mini | C12: C6X__free_form_10d | D12: 575 | E12: 0.85965626 | F12: 0.85904676
A13: alpha | B13: GPT-4.1-mini | C13: C6__candidate_selection | D13: 575 | E13: 0.56202576 | F13: 0.19649361
A14: alpha | B14: GPT-4.1-mini | C14: C6__free_form_10d | D14: 575 | E14: 1.1693351 | F14: 0.89187138
A15: alpha | B15: GPT-4.1-mini | C15: C7__candidate_selection | D15: 575 | E15: 0.4940117 | F15: 0.14214537
A16: alpha | B16: GPT-4.1-mini | C16: C7__free_form_10d | D16: 575 | E16: 0.68341043 | F16: 0.6696426
A17: alpha | B17: GPT-4.1-mini | C17: C8__candidate_selection | D17: 575 | E17: 0.63722325 | F17: 0.14214537
A18: alpha | B18: GPT-4.1-mini | C18: C8__free_form_10d | D18: 575 | E18: 1.050058 | F18: 0.85904676
... A114: gamma | B114: Haiku-4.5 | C114: C8__free_form_10d | D114: 575 | E114: 0.91617971 | F114: 0.5573419

Sheet CALCULATION
A1: T5-5 · 분석 과정
A2: 필터·분석단위와 실제 계산 결과입니다. 수치 셀은 SOURCE를 직접 참조합니다.
A4: 항목 | B4: 내용
A5: 계산 방법 | B5: 같은 기업의 행동 후 Oracle 점수에서 그 기업의 무행동 Oracle 점수를 뺀 뒤 기업 단위로 집계
A6: 생산 코드 | B6: src/credit_recourse/analysis/main_harness_backend_decomposition.py
A7: 선택 실행 | B7: V11_FINAL_FROZEN_REPLAY_RESUME
A11: 이 표·그림과 연결된 본문 핵심 수치
A12: 수치 ID | B12: 본문 주장 | C12: 논문 표시값 | D12: 재계산값 | E12: 확인 결과 | F12: 계산식 | G12: 실제 입력 산출물
A13: NC0152-04 | B13: GPT-4.1-mini는 두 조건 모두에서 행동을 수정했지만, Candidate-IQL의 행동을 보여주었을 때 그 방향을 더 많이 받아들였다. 채택률은 C6 0.504, C6X 0.347이었고 정책가치는 Candidate-IQL 참조에서 +0.310 높았다. 따라서 행동을 수정했는지만으로는 두 조건의 차이를 설명할 수 없으며, 어떤 방향으로 수정했는지가 중요했다. | C13: +0.310 | D13: 0.31 | E13: 논문값과 일치 | F13: MEAN_i(delta_alpha(C6_i) - delta_alpha(C6X_i)) | G13: frozen_outputs/analysis/paper_repro/02_llm_hypothesis_tests/holm_h1_h3/holm_H3_reference.csv
A14: NC0153-03 | B14: Claude Haiku 4.5와 GPT-5.4-mini에서도 Candidate-IQL 참조의 수정률과 채택률이 무작위 참조보다 높았다. 정책가치 역시 각각 +0.179와 +0.174 높았다. 세 파운데이션 모델에서 같은 방향의 결과가 나타났으므로, LLM은 외부 정책 참조가 있다는 사실에만 반응한 것이 아니라 제시된 행동의 내용에 따라 다르게 반응하였다. H3은 지지되었다. | C14: +0.179 | D14: 0.179 | E14: 논문값과 일치 | F14: MEAN_i(delta_alpha(C6_i) - delta_alpha(C6X_i)) | G14: frozen_outputs/analysis/paper_repro/02_llm_hypothesis_tests/holm_h1_h3/holm_H3_reference.csv
A15: NC0153-04 | B15: Claude Haiku 4.5와 GPT-5.4-mini에서도 Candidate-IQL 참조의 수정률과 채택률이 무작위 참조보다 높았다. 정책가치 역시 각각 +0.179와 +0.174 높았다. 세 파운데이션 모델에서 같은 방향의 결과가 나타났으므로, LLM은 외부 정책 참조가 있다는 사실에만 반응한 것이 아니라 제시된 행동의 내용에 따라 다르게 반응하였다. H3은 지지되었다. | C15: +0.174 | D15: 0.174 | E15: 논문값과 일치 | F15: MEAN_i(delta_alpha(C6_i) - delta_alpha(C6X_i)) | G15: frozen_outputs/analysis/paper_repro/02_llm_hypothesis_tests/holm_h1_h3/holm_H3_reference.csv
A16: NC0155-02 | B16: 후보행동 선택에서는 Candidate-IQL의 행동을 처음부터 보여준 C8이 초안 작성 후 수정한 C6보다 높거나 거의 같은 정책가치를 보였다. GPT-4.1-mini는 C6 +0.562에서 C8 +0.637로 높아졌고, Claude Haiku 4.5는 +0.457에서 +0.501로 높아졌다. GPT-5.4-mini는 +0.591과 +0.592로 거의 같았다. | C16: +0.562 | D16: 0.562 | E16: 논문값과 일치 | F16: MEAN_i(R_score_alpha(policy_i) - R_score_alpha(noop_i)) | G16: frozen_outputs/analysis/paper_repro/03_output_contract_diagnostics/main_harness_backend_decomposition/main_harness_backend_cell_means.csv
A17: NC0155-03 | B17: 후보행동 선택에서는 Candidate-IQL의 행동을 처음부터 보여준 C8이 초안 작성 후 수정한 C6보다 높거나 거의 같은 정책가치를 보였다. GPT-4.1-mini는 C6 +0.562에서 C8 +0.637로 높아졌고, Claude Haiku 4.5는 +0.457에서 +0.501로 높아졌다. GPT-5.4-mini는 +0.591과 +0.592로 거의 같았다. | C17: +0.637 | D17: 0.637 | E17: 논문값과 일치 | F17: MEAN_i(R_score_alpha(policy_i) - R_score_alpha(noop_i)) | G17: frozen_outputs/analysis/paper_repro/03_output_contract_diagnostics/main_harness_backend_decomposition/main_harness_backend_cell_means.csv
A18: NC0155-05 | B18: 후보행동 선택에서는 Candidate-IQL의 행동을 처음부터 보여준 C8이 초안 작성 후 수정한 C6보다 높거나 거의 같은 정책가치를 보였다. GPT-4.1-mini는 C6 +0.562에서 C8 +0.637로 높아졌고, Claude Haiku 4.5는 +0.457에서 +0.501로 높아졌다. GPT-5.4-mini는 +0.591과 +0.592로 거의 같았다. | C18: +0.457 | D18: 0.457 | E18: 논문값과 일치 | F18: MEAN_i(R_score_alpha(policy_i) - R_score_alpha(noop_i)) | G18: frozen_outputs/analysis/paper_repro/03_output_contract_diagnostics/main_harness_backend_decomposition/main_harness_backend_cell_means.csv
A19: NC0155-06 | B19: 후보행동 선택에서는 Candidate-IQL의 행동을 처음부터 보여준 C8이 초안 작성 후 수정한 C6보다 높거나 거의 같은 정책가치를 보였다. GPT-4.1-mini는 C6 +0.562에서 C8 +0.637로 높아졌고, Claude Haiku 4.5는 +0.457에서 +0.501로 높아졌다. GPT-5.4-mini는 +0.591과 +0.592로 거의 같았다. | C19: +0.501 | D19: 0.501 | E19: 논문값과 일치 | F19: MEAN_i(R_score_alpha(policy_i) - R_score_alpha(noop_i)) | G19: frozen_outputs/analysis/paper_repro/03_output_contract_diagnostics/main_harness_backend_decomposition/main_harness_backend_cell_means.csv
A20: NC0155-08 | B20: 후보행동 선택에서는 Candidate-IQL의 행동을 처음부터 보여준 C8이 초안 작성 후 수정한 C6보다 높거나 거의 같은 정책가치를 보였다. GPT-4.1-mini는 C6 +0.562에서 C8 +0.637로 높아졌고, Claude Haiku 4.5는 +0.457에서 +0.501로 높아졌다. GPT-5.4-mini는 +0.591과 +0.592로 거의 같았다. | C20: +0.591 | D20: 0.591 | E20: 논문값과 일치 | F20: MEAN_i(R_score_alpha(C6 candidate_i) - R_score_alpha(noop_i)) | G20: frozen_outputs/analysis/paper_repro/03_output_contract_diagnostics/main_harness_backend_decomposition/main_harness_backend_cell_means.csv
A21: NC0155-09 | B21: 후보행동 선택에서는 Candidate-IQL의 행동을 처음부터 보여준 C8이 초안 작성 후 수정한 C6보다 높거나 거의 같은 정책가치를 보였다. GPT-4.1-mini는 C6 +0.562에서 C8 +0.637로 높아졌고, Claude Haiku 4.5는 +0.457에서 +0.501로 높아졌다. GPT-5.4-mini는 +0.591과 +0.592로 거의 같았다. | C21: +0.592 | D21: 0.592 | E21: 논문값과 일치 | F21: MEAN_i(R_score_alpha(policy_i) - R_score_alpha(noop_i)) | G21: frozen_outputs/analysis/paper_repro/03_output_contract_diagnostics/main_harness_backend_decomposition/main_harness_backend_cell_means.csv
A22: NC0156-02 | B22: 자유작성에서는 반대 결과가 나타났다. 세 파운데이션 모델 모두 처음부터 Candidate-IQL의 행동을 보여준 C8보다 먼저 행동을 작성한 뒤 다시 검토한 C6의 정책가치가 높았다. GPT-4.1-mini는 C6 +1.169와 C8 +1.050, Claude Haiku 4.5는 +1.231과 +1.013, GPT-5.4-mini는 +1.103과 +0.966이었다. | C22: +1.169 | D22: 1.169 | E22: 논문값과 일치 | F22: MEAN_i(R_score_alpha(policy_i) - R_score_alpha(noop_i)) | G22: frozen_outputs/analysis/paper_repro/03_output_contract_diagnostics/main_harness_backend_decomposition/main_harness_backend_cell_means.csv
A23: NC0156-03 | B23: 자유작성에서는 반대 결과가 나타났다. 세 파운데이션 모델 모두 처음부터 Candidate-IQL의 행동을 보여준 C8보다 먼저 행동을 작성한 뒤 다시 검토한 C6의 정책가치가 높았다. GPT-4.1-mini는 C6 +1.169와 C8 +1.050, Claude Haiku 4.5는 +1.231과 +1.013, GPT-5.4-mini는 +1.103과 +0.966이었다. | C23: +1.050 | D23: 1.05 | E23: 논문값과 일치 | F23: MEAN_i(R_score_alpha(policy_i) - R_score_alpha(noop_i)) | G23: frozen_outputs/analysis/paper_repro/03_output_contract_diagnostics/main_harness_backend_decomposition/main_harness_backend_cell_means.csv
A24: NC0156-05 | B24: 자유작성에서는 반대 결과가 나타났다. 세 파운데이션 모델 모두 처음부터 Candidate-IQL의 행동을 보여준 C8보다 먼저 행동을 작성한 뒤 다시 검토한 C6의 정책가치가 높았다. GPT-4.1-mini는 C6 +1.169와 C8 +1.050, Claude Haiku 4.5는 +1.231과 +1.013, GPT-5.4-mini는 +1.103과 +0.966이었다. | C24: +1.231 | D24: 1.231 | E24: 논문값과 일치 | F24: MEAN_i(R_score_alpha(policy_i) - R_score_alpha(noop_i)) | G24: frozen_outputs/analysis/paper_repro/03_output_contract_diagnostics/main_harness_backend_decomposition/main_harness_backend_cell_means.csv
... A27: NC0156-09 | B27: 자유작성에서는 반대 결과가 나타났다. 세 파운데이션 모델 모두 처음부터 Candidate-IQL의 행동을 보여준 C8보다 먼저 행동을 작성한 뒤 다시 검토한 C6의 정책가치가 높았다. GPT-4.1-mini는 C6 +1.169와 C8 +1.050, Claude Haiku 4.5는 +1.231과 +1.013, GPT-5.4-mini는 +1.103과 +0.966이었다. | C27: +0.966 | D27: 0.966 | E27: 논문값과 일치 | F27: MEAN_i(R_score_alpha(policy_i) - R_score_alpha(noop_i)) | G27: frozen_outputs/analysis/paper_repro/03_output_contract_diagnostics/main_harness_backend_decomposition/main_harness_backend_cell_means.csv
A30: 계산 데이터: alpha_harness_cells
A31: 입력 파일 | B31: data/analysis/paper_repro/03_output_contract_diagnostics/main_harness_backend_decomposition/main_harness_backend_cell_means.csv
A32: 선택 조건 | B32: [{"column": "oracle_backend", "op": "equals", "value": "alpha"}, {"column": "harness_cell", "op": "in", "values": ["C4__candidate_selection", "C5__candidate_selection", "C6__candidate_selection", "C6X__candidate_selection", "C7__candidate_selection", "C8__candidate_selection", "C6__free_form_10d", "C8__free_form_10d"]}]
A33: 분석 단위 | B33: backend_label; harness_cell
A34: 집계 | B34: PRODUCER_MEAN_AFTER_SAME_FIRM_PAIRING_VERIFIED
A35: backend_label | B35: harness_cell | C35: n_firms | D35: mean_score | E35: median_score
A36: ='SOURCE'!B7 | B36: ='SOURCE'!C7 | C36: ='SOURCE'!D7 | D36: ='SOURCE'!E7 | E36: ='SOURCE'!F7
A37: ='SOURCE'!B9 | B37: ='SOURCE'!C9 | C37: ='SOURCE'!D9 | D37: ='SOURCE'!E9 | E37: ='SOURCE'!F9
A38: ='SOURCE'!B11 | B38: ='SOURCE'!C11 | C38: ='SOURCE'!D11 | D38: ='SOURCE'!E11 | E38: ='SOURCE'!F11
A39: ='SOURCE'!B13 | B39: ='SOURCE'!C13 | C39: ='SOURCE'!D13 | D39: ='SOURCE'!E13 | E39: ='SOURCE'!F13
A40: ='SOURCE'!B14 | B40: ='SOURCE'!C14 | C40: ='SOURCE'!D14 | D40: ='SOURCE'!E14 | E40: ='SOURCE'!F14
A41: ='SOURCE'!B15 | B41: ='SOURCE'!C15 | C41: ='SOURCE'!D15 | D41: ='SOURCE'!E15 | E41: ='SOURCE'!F15
A42: ='SOURCE'!B17 | B42: ='SOURCE'!C17 | C42: ='SOURCE'!D17 | D42: ='SOURCE'!E17 | E42: ='SOURCE'!F17
A43: ='SOURCE'!B18 | B43: ='SOURCE'!C18 | C43: ='SOURCE'!D18 | D43: ='SOURCE'!E18 | E43: ='SOURCE'!F18
A44: ='SOURCE'!B19 | B44: ='SOURCE'!C19 | C44: ='SOURCE'!D19 | D44: ='SOURCE'!E19 | E44: ='SOURCE'!F19
A45: ='SOURCE'!B21 | B45: ='SOURCE'!C21 | C45: ='SOURCE'!D21 | D45: ='SOURCE'!E21 | E45: ='SOURCE'!F21
A46: ='SOURCE'!B23 | B46: ='SOURCE'!C23 | C46: ='SOURCE'!D23 | D46: ='SOURCE'!E23 | E46: ='SOURCE'!F23
A47: ='SOURCE'!B25 | B47: ='SOURCE'!C25 | C47: ='SOURCE'!D25 | D47: ='SOURCE'!E25 | E47: ='SOURCE'!F25
A48: ='SOURCE'!B26 | B48: ='SOURCE'!C26 | C48: ='SOURCE'!D26 | D48: ='SOURCE'!E26 | E48: ='SOURCE'!F26
...

Sheet PAPER_TABLE
A1: T5-5 · 논문 표 작업용 결과
A2: ANALYSIS에서 계산된 값만 연결한 최종 작업표입니다. Excel에서 정렬·피벗·표시형식만 조정하면 됩니다.
A4: 계산 결과: alpha_harness_cells
A5: ='CALCULATION'!A35 | B5: ='CALCULATION'!B35 | C5: ='CALCULATION'!C35 | D5: ='CALCULATION'!D35 | E5: ='CALCULATION'!E35
A6: ='CALCULATION'!A36 | B6: ='CALCULATION'!B36 | C6: ='CALCULATION'!C36 | D6: ='CALCULATION'!D36 | E6: ='CALCULATION'!E36
A7: ='CALCULATION'!A37 | B7: ='CALCULATION'!B37 | C7: ='CALCULATION'!C37 | D7: ='CALCULATION'!D37 | E7: ='CALCULATION'!E37
A8: ='CALCULATION'!A38 | B8: ='CALCULATION'!B38 | C8: ='CALCULATION'!C38 | D8: ='CALCULATION'!D38 | E8: ='CALCULATION'!E38
A9: ='CALCULATION'!A39 | B9: ='CALCULATION'!B39 | C9: ='CALCULATION'!C39 | D9: ='CALCULATION'!D39 | E9: ='CALCULATION'!E39
A10: ='CALCULATION'!A40 | B10: ='CALCULATION'!B40 | C10: ='CALCULATION'!C40 | D10: ='CALCULATION'!D40 | E10: ='CALCULATION'!E40
A11: ='CALCULATION'!A41 | B11: ='CALCULATION'!B41 | C11: ='CALCULATION'!C41 | D11: ='CALCULATION'!D41 | E11: ='CALCULATION'!E41
A12: ='CALCULATION'!A42 | B12: ='CALCULATION'!B42 | C12: ='CALCULATION'!C42 | D12: ='CALCULATION'!D42 | E12: ='CALCULATION'!E42
A13: ='CALCULATION'!A43 | B13: ='CALCULATION'!B43 | C13: ='CALCULATION'!C43 | D13: ='CALCULATION'!D43 | E13: ='CALCULATION'!E43
A14: ='CALCULATION'!A44 | B14: ='CALCULATION'!B44 | C14: ='CALCULATION'!C44 | D14: ='CALCULATION'!D44 | E14: ='CALCULATION'!E44
A15: ='CALCULATION'!A45 | B15: ='CALCULATION'!B45 | C15: ='CALCULATION'!C45 | D15: ='CALCULATION'!D45 | E15: ='CALCULATION'!E45
A16: ='CALCULATION'!A46 | B16: ='CALCULATION'!B46 | C16: ='CALCULATION'!C46 | D16: ='CALCULATION'!D46 | E16: ='CALCULATION'!E46
... A29: ='CALCULATION'!A59 | B29: ='CALCULATION'!B59 | C29: ='CALCULATION'!C59 | D29: ='CALCULATION'!D59 | E29: ='CALCULATION'!E59
