Workbook

Sheet README
A1: TG-2 · 표 G-2. E2와 E3의 독립 반복 비교(Oracle-α)
A2: 논문 인쇄값을 계산 입력으로 쓰지 않고, 선택 실행의 실제 산출물에서 값을 계산한 Excel입니다.
A4: 항목 | B4: 내용
A5: 선택 실행 | B5: V11_FINAL_FROZEN_REPLAY_RESUME
A6: 실행 방식 | B6: FrozenReplay
A7: 논문 항목 읽기 | B7: 논문 DOCX에서 번호·제목·위치만 동적으로 읽음
A8: 논문 위치 | B8: G 추가 실험의 실행 이력과 반복 비교 · 인쇄면 127
A9: 관측·집계 단위 | B9: cohort_id + budget_label + contrast
A10: 선택 조건 | B10: [[{"column": "oracle_backend", "op": "equals", "value": "alpha"}, {"column": "budget_label", "op": "in", "values": ["0p75", "unbounded"]}, {"column": "contrast", "op": "in", "values": ["self_revision", "reference_content_conditional", "reference_plus_revision_package"]}]]
A11: 계산 방법 | B11: 선택 실행 산출물에 명시된 조건을 적용하고 논문 분석단위로 행·열을 정리
A12: 생산 코드 | B12: src/credit_recourse/analysis/c4r_matched_inference_v3.py
A13: 실제 입력 산출물 | B13: embedded://selected-run-output/data/analysis/paper_repro/05_extension_e3_e4/e3_c4r_journal/v3_matched/c4r_matched_v3_contrasts.csv

Sheet SOURCE
A1: TG-2 · 실제 입력 산출물
A2: 선택 실행에서 읽은 실제 중간·최종 산출물입니다. 아래 ANALYSIS가 이 셀들을 직접 참조합니다.
A4: 입력 1: embedded://selected-run-output/data/analysis/paper_repro/05_extension_e3_e4/e3_c4r_journal/v3_matched/c4r_matched_v3_contrasts.csv
A5: 파일 크기(bytes) | B5: 21156 | C5: 생산 코드 | D5: src/credit_recourse/analysis/c4r_matched_inference_v3.py | E5: SHA256 | F5: F6A52321BC31E9151900CC8FFCF60BB32B2D3D6E3DB021785144463DA45C7483 | G5: 읽기 상태 | H5: OK
A6: cohort_id | B6: backend_id | C6: run_role | D6: budget_label | E6: l1_budget | F6: oracle_backend | G6: contrast | H6: n_pairs | I6: mean_increment | J6: median_increment | K6: win_count | L6: tie_count | M6: loss_count | N6: wilcoxon_p_raw | O6: wilcoxon_p_holm_across_budgets | P6: holm_family_across_budgets | Q6: sig_holm_across_budgets
A7: gemini31flashlite | B7: google_gemini-3.1-flash-lite_generate-content_thinking-low_maxout-4096_json | C7: paper_c4r_journal_ext_gemini31flashlite | D7: 0p75 | E7: 0.75 | F7: alpha | G7: reference_content_conditional | H7: 575 | I7: -0.00098336451 | J7: 0 | K7: 54 | L7: 477 | M7: 44 | N7: 0.67705344 | O7: 0.67705344 | P7: cohort_oracle_contrast_across_budget_arms | Q7: n.s.
A8: gemini31flashlite | B8: google_gemini-3.1-flash-lite_generate-content_thinking-low_maxout-4096_json | C8: paper_c4r_journal_ext_gemini31flashlite | D8: 1p27 | E8: 1.27 | F8: alpha | G8: reference_content_conditional | H8: 575 | I8: 0.045167937 | J8: 0 | K8: 72 | L8: 463 | M8: 40 | N8: 0.017939618 | O8: 0.035879237 | P8: cohort_oracle_contrast_across_budget_arms | Q8: *
A9: gemini31flashlite | B9: google_gemini-3.1-flash-lite_generate-content_thinking-low_maxout-4096_json | C9: paper_c4r_journal_ext_gemini31flashlite | D9: 2p00 | E9: 2 | F9: alpha | G9: reference_content_conditional | H9: 575 | I9: 0.081483834 | J9: 0 | K9: 85 | L9: 449 | M9: 41 | N9: 0.000491999 | O9: 0.001475997 | P9: cohort_oracle_contrast_across_budget_arms | Q9: **
A10: gemini31flashlite | B10: google_gemini-3.1-flash-lite_generate-content_thinking-low_maxout-4096_json | C10: paper_c4r_journal_ext_gemini31flashlite | D10: unbounded | F10: alpha | G10: reference_content_conditional | H10: 575 | I10: 0.40240621 | J10: 0 | K10: 209 | L10: 347 | M10: 19 | N10: 1.5434023e-30 | O10: 6.1736094e-30 | P10: cohort_oracle_contrast_across_budget_arms | Q10: ***
A11: gemini31flashlite | B11: google_gemini-3.1-flash-lite_generate-content_thinking-low_maxout-4096_json | C11: paper_c4r_journal_ext_gemini31flashlite | D11: 0p75 | E11: 0.75 | F11: beta | G11: reference_content_conditional | H11: 575 | I11: -0.0052317656 | J11: 0 | K11: 258 | L11: 87 | M11: 230 | N11: 0.38633721 | O11: 0.38633721 | P11: cohort_oracle_contrast_across_budget_arms | Q11: n.s.
A12: gemini31flashlite | B12: google_gemini-3.1-flash-lite_generate-content_thinking-low_maxout-4096_json | C12: paper_c4r_journal_ext_gemini31flashlite | D12: 1p27 | E12: 1.27 | F12: beta | G12: reference_content_conditional | H12: 575 | I12: 0.0065415303 | J12: 9.1978503e-05 | K12: 295 | L12: 73 | M12: 207 | N12: 0.0011800158 | O12: 0.0035400474 | P12: cohort_oracle_contrast_across_budget_arms | Q12: **
A13: gemini31flashlite | B13: google_gemini-3.1-flash-lite_generate-content_thinking-low_maxout-4096_json | C13: paper_c4r_journal_ext_gemini31flashlite | D13: 2p00 | E13: 2 | F13: beta | G13: reference_content_conditional | H13: 575 | I13: 0.0075570021 | J13: 0.0001845743 | K13: 290 | L13: 53 | M13: 232 | N13: 0.006930842 | O13: 0.013861684 | P13: cohort_oracle_contrast_across_budget_arms | Q13: *
A14: gemini31flashlite | B14: google_gemini-3.1-flash-lite_generate-content_thinking-low_maxout-4096_json | C14: paper_c4r_journal_ext_gemini31flashlite | D14: unbounded | F14: beta | G14: reference_content_conditional | H14: 575 | I14: 0.082272127 | J14: 0.049246315 | K14: 410 | L14: 123 | M14: 42 | N14: 5.7083405e-67 | O14: 2.2833362e-66 | P14: cohort_oracle_contrast_across_budget_arms | Q14: ***
A15: gemini31flashlite | B15: google_gemini-3.1-flash-lite_generate-content_thinking-low_maxout-4096_json | C15: paper_c4r_journal_ext_gemini31flashlite | D15: 0p75 | E15: 0.75 | F15: gamma | G15: reference_content_conditional | H15: 575 | I15: 0.0018276959 | J15: 0 | K15: 85 | L15: 424 | M15: 66 | N15: 0.62580046 | O15: 0.62580046 | P15: cohort_oracle_contrast_across_budget_arms | Q15: n.s.
A16: gemini31flashlite | B16: google_gemini-3.1-flash-lite_generate-content_thinking-low_maxout-4096_json | C16: paper_c4r_journal_ext_gemini31flashlite | D16: 1p27 | E16: 1.27 | F16: gamma | G16: reference_content_conditional | H16: 575 | I16: 0.079484364 | J16: 0 | K16: 114 | L16: 402 | M16: 59 | N16: 3.7984784e-07 | O16: 1.1395435e-06 | P16: cohort_oracle_contrast_across_budget_arms | Q16: ***
A17: gemini31flashlite | B17: google_gemini-3.1-flash-lite_generate-content_thinking-low_maxout-4096_json | C17: paper_c4r_journal_ext_gemini31flashlite | D17: 2p00 | E17: 2 | F17: gamma | G17: reference_content_conditional | H17: 575 | I17: 0.028257244 | J17: 0 | K17: 116 | L17: 357 | M17: 102 | N17: 0.10113196 | O17: 0.20226392 | P17: cohort_oracle_contrast_across_budget_arms | Q17: n.s.
A18: gemini31flashlite | B18: google_gemini-3.1-flash-lite_generate-content_thinking-low_maxout-4096_json | C18: paper_c4r_journal_ext_gemini31flashlite | D18: unbounded | F18: gamma | G18: reference_content_conditional | H18: 575 | I18: 0.29317348 | J18: 0 | K18: 221 | L18: 294 | M18: 60 | N18: 2.9614245e-31 | O18: 1.1845698e-30 | P18: cohort_oracle_contrast_across_budget_arms | Q18: ***
A19: gemini31flashlite | B19: google_gemini-3.1-flash-lite_generate-content_thinking-low_maxout-4096_json | C19: paper_c4r_journal_ext_gemini31flashlite | D19: 0p75 | E19: 0.75 | F19: alpha | G19: reference_plus_revision_package | H19: 575 | I19: 0.069345489 | J19: 0 | K19: 80 | L19: 464 | M19: 31 | N19: 8.8566801e-05 | O19: 8.8566801e-05 | P19: cohort_oracle_contrast_across_budget_arms | Q19: ***
A20: gemini31flashlite | B20: google_gemini-3.1-flash-lite_generate-content_thinking-low_maxout-4096_json | C20: paper_c4r_journal_ext_gemini31flashlite | D20: 1p27 | E20: 1.27 | F20: alpha | G20: reference_plus_revision_package | H20: 575 | I20: 0.11566099 | J20: 0 | K20: 106 | L20: 436 | M20: 33 | N20: 6.8831305e-07 | O20: 1.3766261e-06 | P20: cohort_oracle_contrast_across_budget_arms | Q20: ***
A21: gemini31flashlite | B21: google_gemini-3.1-flash-lite_generate-content_thinking-low_maxout-4096_json | C21: paper_c4r_journal_ext_gemini31flashlite | D21: 2p00 | E21: 2 | F21: alpha | G21: reference_plus_revision_package | H21: 575 | I21: 0.14369843 | J21: 0 | K21: 123 | L21: 414 | M21: 38 | N21: 1.6687549e-08 | O21: 5.0062648e-08 | P21: cohort_oracle_contrast_across_budget_arms | Q21: ***
A22: gemini31flashlite | B22: google_gemini-3.1-flash-lite_generate-content_thinking-low_maxout-4096_json | C22: paper_c4r_journal_ext_gemini31flashlite | D22: unbounded | F22: alpha | G22: reference_plus_revision_package | H22: 575 | I22: 0.42133426 | J22: 0 | K22: 218 | L22: 344 | M22: 13 | N22: 2.8375875e-33 | O22: 1.135035e-32 | P22: cohort_oracle_contrast_across_budget_arms | Q22: ***
A23: gemini31flashlite | B23: google_gemini-3.1-flash-lite_generate-content_thinking-low_maxout-4096_json | C23: paper_c4r_journal_ext_gemini31flashlite | D23: 0p75 | E23: 0.75 | F23: beta | G23: reference_plus_revision_package | H23: 575 | I23: 0.0082999737 | J23: 0.00030034179 | K23: 297 | L23: 105 | M23: 173 | N23: 8.1923961e-08 | O23: 8.1923961e-08 | P23: cohort_oracle_contrast_across_budget_arms | Q23: ***
A24: gemini31flashlite | B24: google_gemini-3.1-flash-lite_generate-content_thinking-low_maxout-4096_json | C24: paper_c4r_journal_ext_gemini31flashlite | D24: 1p27 | E24: 1.27 | F24: beta | G24: reference_plus_revision_package | H24: 575 | I24: 0.019420248 | J24: 0.002336768 | K24: 322 | L24: 91 | M24: 162 | N24: 1.4852065e-17 | O24: 4.4556195e-17 | P24: cohort_oracle_contrast_across_budget_arms | Q24: ***
A25: gemini31flashlite | B25: google_gemini-3.1-flash-lite_generate-content_thinking-low_maxout-4096_json | C25: paper_c4r_journal_ext_gemini31flashlite | D25: 2p00 | E25: 2 | F25: beta | G25: reference_plus_revision_package | H25: 575 | I25: 0.016208471 | J25: 0.003535389 | K25: 330 | L25: 66 | M25: 179 | N25: 1.3460406e-11 | O25: 2.6920811e-11 | P25: cohort_oracle_contrast_across_budget_arms | Q25: ***
A26: gemini31flashlite | B26: google_gemini-3.1-flash-lite_generate-content_thinking-low_maxout-4096_json | C26: paper_c4r_journal_ext_gemini31flashlite | D26: unbounded | F26: beta | G26: reference_plus_revision_package | H26: 575 | I26: 0.08517421 | J26: 0.054921898 | K26: 423 | L26: 124 | M26: 28 | N26: 4.4568022e-70 | O26: 1.7827209e-69 | P26: cohort_oracle_contrast_across_budget_arms | Q26: ***
A27: gemini31flashlite | B27: google_gemini-3.1-flash-lite_generate-content_thinking-low_maxout-4096_json | C27: paper_c4r_journal_ext_gemini31flashlite | D27: 0p75 | E27: 0.75 | F27: gamma | G27: reference_plus_revision_package | H27: 575 | I27: 0.031550579 | J27: 0 | K27: 99 | L27: 408 | M27: 68 | N27: 0.010205537 | O27: 0.010205537 | P27: cohort_oracle_contrast_across_budget_arms | Q27: *
A28: gemini31flashlite | B28: google_gemini-3.1-flash-lite_generate-content_thinking-low_maxout-4096_json | C28: paper_c4r_journal_ext_gemini31flashlite | D28: 1p27 | E28: 1.27 | F28: gamma | G28: reference_plus_revision_package | H28: 575 | I28: 0.10978819 | J28: 0 | K28: 129 | L28: 391 | M28: 55 | N28: 6.7747176e-10 | O28: 1.3549435e-09 | P28: cohort_oracle_contrast_across_budget_arms | Q28: ***
A29: gemini31flashlite | B29: google_gemini-3.1-flash-lite_generate-content_thinking-low_maxout-4096_json | C29: paper_c4r_journal_ext_gemini31flashlite | D29: 2p00 | E29: 2 | F29: gamma | G29: reference_plus_revision_package | H29: 575 | I29: 0.11931369 | J29: 0 | K29: 147 | L29: 358 | M29: 70 | N29: 1.2223304e-10 | O29: 3.6669913e-10 | P29: cohort_oracle_contrast_across_budget_arms | Q29: ***
A30: gemini31flashlite | B30: google_gemini-3.1-flash-lite_generate-content_thinking-low_maxout-4096_json | C30: paper_c4r_journal_ext_gemini31flashlite | D30: unbounded | F30: gamma | G30: reference_plus_revision_package | H30: 575 | I30: 0.32782122 | J30: 0 | K30: 231 | L30: 295 | M30: 49 | N30: 2.1094053e-35 | O30: 8.4376211e-35 | P30: cohort_oracle_contrast_across_budget_arms | Q30: ***
A31: gemini31flashlite | B31: google_gemini-3.1-flash-lite_generate-content_thinking-low_maxout-4096_json | C31: paper_c4r_journal_ext_gemini31flashlite | D31: 0p75 | E31: 0.75 | F31: alpha | G31: self_revision | H31: 575 | I31: 0.070328854 | J31: 0 | K31: 66 | L31: 484 | M31: 25 | N31: 7.7132895e-05 | O31: 0.00030853158 | P31: cohort_oracle_contrast_across_budget_arms | Q31: ***
A32: gemini31flashlite | B32: google_gemini-3.1-flash-lite_generate-content_thinking-low_maxout-4096_json | C32: paper_c4r_journal_ext_gemini31flashlite | D32: 1p27 | E32: 1.27 | F32: alpha | G32: self_revision | H32: 575 | I32: 0.07049305 | J32: 0 | K32: 77 | L32: 464 | M32: 34 | N32: 0.0026702809 | O32: 0.0065746427 | P32: cohort_oracle_contrast_across_budget_arms | Q32: **
A33: gemini31flashlite | B33: google_gemini-3.1-flash-lite_generate-content_thinking-low_maxout-4096_json | C33: paper_c4r_journal_ext_gemini31flashlite | D33: 2p00 | E33: 2 | F33: alpha | G33: self_revision | H33: 575 | I33: 0.062214598 | J33: 0 | K33: 78 | L33: 458 | M33: 39 | N33: 0.0021915476 | O33: 0.0065746427 | P33: cohort_oracle_contrast_across_budget_arms | Q33: **
A34: gemini31flashlite | B34: google_gemini-3.1-flash-lite_generate-content_thinking-low_maxout-4096_json | C34: paper_c4r_journal_ext_gemini31flashlite | D34: unbounded | F34: alpha | G34: self_revision | H34: 575 | I34: 0.018928051 | J34: 0 | K34: 24 | L34: 547 | M34: 4 | N34: 0.004733027 | O34: 0.0065746427 | P34: cohort_oracle_contrast_across_budget_arms | Q34: **
A35: gemini31flashlite | B35: google_gemini-3.1-flash-lite_generate-content_thinking-low_maxout-4096_json | C35: paper_c4r_journal_ext_gemini31flashlite | D35: 0p75 | E35: 0.75 | F35: beta | G35: self_revision | H35: 575 | I35: 0.013531739 | J35: 0 | K35: 261 | L35: 155 | M35: 159 | N35: 1.1896368e-10 | O35: 4.7585471e-10 | P35: cohort_oracle_contrast_across_budget_arms | Q35: ***
A36: gemini31flashlite | B36: google_gemini-3.1-flash-lite_generate-content_thinking-low_maxout-4096_json | C36: paper_c4r_journal_ext_gemini31flashlite | D36: 1p27 | E36: 1.27 | F36: beta | G36: self_revision | H36: 575 | I36: 0.012878717 | J36: 0 | K36: 265 | L36: 139 | M36: 171 | N36: 9.5954095e-10 | O36: 2.8786228e-09 | P36: cohort_oracle_contrast_across_budget_arms | Q36: ***
A37: gemini31flashlite | B37: google_gemini-3.1-flash-lite_generate-content_thinking-low_maxout-4096_json | C37: paper_c4r_journal_ext_gemini31flashlite | D37: 2p00 | E37: 2 | F37: beta | G37: self_revision | H37: 575 | I37: 0.0086514691 | J37: 0 | K37: 280 | L37: 106 | M37: 189 | N37: 7.8548765e-06 | O37: 1.5709753e-05 | P37: cohort_oracle_contrast_across_budget_arms | Q37: ***
A38: gemini31flashlite | B38: google_gemini-3.1-flash-lite_generate-content_thinking-low_maxout-4096_json | C38: paper_c4r_journal_ext_gemini31flashlite | D38: unbounded | F38: beta | G38: self_revision | H38: 575 | I38: 0.002902083 | J38: 0 | K38: 76 | L38: 463 | M38: 36 | N38: 0.00016248863 | O38: 0.00016248863 | P38: cohort_oracle_contrast_across_budget_arms | Q38: ***
A39: gemini31flashlite | B39: google_gemini-3.1-flash-lite_generate-content_thinking-low_maxout-4096_json | C39: paper_c4r_journal_ext_gemini31flashlite | D39: 0p75 | E39: 0.75 | F39: gamma | G39: self_revision | H39: 575 | I39: 0.029722883 | J39: 0 | K39: 80 | L39: 427 | M39: 68 | N39: 0.059868814 | O39: 0.059868814 | P39: cohort_oracle_contrast_across_budget_arms | Q39: n.s.
A40: gemini31flashlite | B40: google_gemini-3.1-flash-lite_generate-content_thinking-low_maxout-4096_json | C40: paper_c4r_journal_ext_gemini31flashlite | D40: 1p27 | E40: 1.27 | F40: gamma | G40: self_revision | H40: 575 | I40: 0.030303829 | J40: 0 | K40: 88 | L40: 427 | M40: 60 | N40: 0.025419139 | O40: 0.050838277 | P40: cohort_oracle_contrast_across_budget_arms | Q40: n.s.
A41: gemini31flashlite | B41: google_gemini-3.1-flash-lite_generate-content_thinking-low_maxout-4096_json | C41: paper_c4r_journal_ext_gemini31flashlite | D41: 2p00 | E41: 2 | F41: gamma | G41: self_revision | H41: 575 | I41: 0.091056441 | J41: 0 | K41: 125 | L41: 393 | M41: 57 | N41: 9.2701939e-07 | O41: 3.7080775e-06 | P41: cohort_oracle_contrast_across_budget_arms | Q41: ***
...

Sheet CALCULATION
A1: TG-2 · 분석 과정
A2: 필터·분석단위와 실제 계산 결과입니다. 수치 셀은 SOURCE를 직접 참조합니다.
A4: 항목 | B4: 내용
A5: 계산 방법 | B5: 선택 실행 산출물에 명시된 조건을 적용하고 논문 분석단위로 행·열을 정리
A6: 생산 코드 | B6: src/credit_recourse/analysis/c4r_matched_inference_v3.py
A7: 선택 실행 | B7: V11_FINAL_FROZEN_REPLAY_RESUME
A11: 계산 데이터: independent_repeat_contrasts
A12: 입력 파일 | B12: data/analysis/paper_repro/05_extension_e3_e4/e3_c4r_journal/v3_matched/c4r_matched_v3_contrasts.csv
A13: 선택 조건 | B13: [{"column": "oracle_backend", "op": "equals", "value": "alpha"}, {"column": "budget_label", "op": "in", "values": ["0p75", "unbounded"]}, {"column": "contrast", "op": "in", "values": ["self_revision", "reference_content_conditional", "reference_plus_revision_package"]}]
A14: 분석 단위 | B14: cohort_id; budget_label; contrast
A15: 집계 | B15: PRODUCER_AGGREGATE_NO_REAGGREGATION
A16: cohort_id | B16: budget_label | C16: contrast | D16: n_pairs | E16: mean_increment | F16: median_increment | G16: wilcoxon_p_holm_across_budgets | H16: sig_holm_across_budgets
A17: ='SOURCE'!A7 | B17: ='SOURCE'!D7 | C17: ='SOURCE'!G7 | D17: ='SOURCE'!H7 | E17: ='SOURCE'!I7 | F17: ='SOURCE'!J7 | G17: ='SOURCE'!O7 | H17: ='SOURCE'!Q7
A18: ='SOURCE'!A10 | B18: ='SOURCE'!D10 | C18: ='SOURCE'!G10 | D18: ='SOURCE'!H10 | E18: ='SOURCE'!I10 | F18: ='SOURCE'!J10 | G18: ='SOURCE'!O10 | H18: ='SOURCE'!Q10
A19: ='SOURCE'!A19 | B19: ='SOURCE'!D19 | C19: ='SOURCE'!G19 | D19: ='SOURCE'!H19 | E19: ='SOURCE'!I19 | F19: ='SOURCE'!J19 | G19: ='SOURCE'!O19 | H19: ='SOURCE'!Q19
A20: ='SOURCE'!A22 | B20: ='SOURCE'!D22 | C20: ='SOURCE'!G22 | D20: ='SOURCE'!H22 | E20: ='SOURCE'!I22 | F20: ='SOURCE'!J22 | G20: ='SOURCE'!O22 | H20: ='SOURCE'!Q22
A21: ='SOURCE'!A31 | B21: ='SOURCE'!D31 | C21: ='SOURCE'!G31 | D21: ='SOURCE'!H31 | E21: ='SOURCE'!I31 | F21: ='SOURCE'!J31 | G21: ='SOURCE'!O31 | H21: ='SOURCE'!Q31
A22: ='SOURCE'!A34 | B22: ='SOURCE'!D34 | C22: ='SOURCE'!G34 | D22: ='SOURCE'!H34 | E22: ='SOURCE'!I34 | F22: ='SOURCE'!J34 | G22: ='SOURCE'!O34 | H22: ='SOURCE'!Q34
A23: ='SOURCE'!A43 | B23: ='SOURCE'!D43 | C23: ='SOURCE'!G43 | D23: ='SOURCE'!H43 | E23: ='SOURCE'!I43 | F23: ='SOURCE'!J43 | G23: ='SOURCE'!O43 | H23: ='SOURCE'!Q43
A24: ='SOURCE'!A46 | B24: ='SOURCE'!D46 | C24: ='SOURCE'!G46 | D24: ='SOURCE'!H46 | E24: ='SOURCE'!I46 | F24: ='SOURCE'!J46 | G24: ='SOURCE'!O46 | H24: ='SOURCE'!Q46
A25: ='SOURCE'!A55 | B25: ='SOURCE'!D55 | C25: ='SOURCE'!G55 | D25: ='SOURCE'!H55 | E25: ='SOURCE'!I55 | F25: ='SOURCE'!J55 | G25: ='SOURCE'!O55 | H25: ='SOURCE'!Q55
A26: ='SOURCE'!A58 | B26: ='SOURCE'!D58 | C26: ='SOURCE'!G58 | D26: ='SOURCE'!H58 | E26: ='SOURCE'!I58 | F26: ='SOURCE'!J58 | G26: ='SOURCE'!O58 | H26: ='SOURCE'!Q58
A27: ='SOURCE'!A67 | B27: ='SOURCE'!D67 | C27: ='SOURCE'!G67 | D27: ='SOURCE'!H67 | E27: ='SOURCE'!I67 | F27: ='SOURCE'!J67 | G27: ='SOURCE'!O67 | H27: ='SOURCE'!Q67
A28: ='SOURCE'!A70 | B28: ='SOURCE'!D70 | C28: ='SOURCE'!G70 | D28: ='SOURCE'!H70 | E28: ='SOURCE'!I70 | F28: ='SOURCE'!J70 | G28: ='SOURCE'!O70 | H28: ='SOURCE'!Q70

Sheet PAPER_TABLE
A1: TG-2 · 논문 표 작업용 결과
A2: ANALYSIS에서 계산된 값만 연결한 최종 작업표입니다. Excel에서 정렬·피벗·표시형식만 조정하면 됩니다.
A4: 계산 결과: independent_repeat_contrasts
A5: ='CALCULATION'!A16 | B5: ='CALCULATION'!B16 | C5: ='CALCULATION'!C16 | D5: ='CALCULATION'!D16 | E5: ='CALCULATION'!E16 | F5: ='CALCULATION'!F16 | G5: ='CALCULATION'!G16 | H5: ='CALCULATION'!H16
A6: ='CALCULATION'!A17 | B6: ='CALCULATION'!B17 | C6: ='CALCULATION'!C17 | D6: ='CALCULATION'!D17 | E6: ='CALCULATION'!E17 | F6: ='CALCULATION'!F17 | G6: ='CALCULATION'!G17 | H6: ='CALCULATION'!H17
A7: ='CALCULATION'!A18 | B7: ='CALCULATION'!B18 | C7: ='CALCULATION'!C18 | D7: ='CALCULATION'!D18 | E7: ='CALCULATION'!E18 | F7: ='CALCULATION'!F18 | G7: ='CALCULATION'!G18 | H7: ='CALCULATION'!H18
A8: ='CALCULATION'!A19 | B8: ='CALCULATION'!B19 | C8: ='CALCULATION'!C19 | D8: ='CALCULATION'!D19 | E8: ='CALCULATION'!E19 | F8: ='CALCULATION'!F19 | G8: ='CALCULATION'!G19 | H8: ='CALCULATION'!H19
A9: ='CALCULATION'!A20 | B9: ='CALCULATION'!B20 | C9: ='CALCULATION'!C20 | D9: ='CALCULATION'!D20 | E9: ='CALCULATION'!E20 | F9: ='CALCULATION'!F20 | G9: ='CALCULATION'!G20 | H9: ='CALCULATION'!H20
A10: ='CALCULATION'!A21 | B10: ='CALCULATION'!B21 | C10: ='CALCULATION'!C21 | D10: ='CALCULATION'!D21 | E10: ='CALCULATION'!E21 | F10: ='CALCULATION'!F21 | G10: ='CALCULATION'!G21 | H10: ='CALCULATION'!H21
A11: ='CALCULATION'!A22 | B11: ='CALCULATION'!B22 | C11: ='CALCULATION'!C22 | D11: ='CALCULATION'!D22 | E11: ='CALCULATION'!E22 | F11: ='CALCULATION'!F22 | G11: ='CALCULATION'!G22 | H11: ='CALCULATION'!H22
A12: ='CALCULATION'!A23 | B12: ='CALCULATION'!B23 | C12: ='CALCULATION'!C23 | D12: ='CALCULATION'!D23 | E12: ='CALCULATION'!E23 | F12: ='CALCULATION'!F23 | G12: ='CALCULATION'!G23 | H12: ='CALCULATION'!H23
A13: ='CALCULATION'!A24 | B13: ='CALCULATION'!B24 | C13: ='CALCULATION'!C24 | D13: ='CALCULATION'!D24 | E13: ='CALCULATION'!E24 | F13: ='CALCULATION'!F24 | G13: ='CALCULATION'!G24 | H13: ='CALCULATION'!H24
A14: ='CALCULATION'!A25 | B14: ='CALCULATION'!B25 | C14: ='CALCULATION'!C25 | D14: ='CALCULATION'!D25 | E14: ='CALCULATION'!E25 | F14: ='CALCULATION'!F25 | G14: ='CALCULATION'!G25 | H14: ='CALCULATION'!H25
A15: ='CALCULATION'!A26 | B15: ='CALCULATION'!B26 | C15: ='CALCULATION'!C26 | D15: ='CALCULATION'!D26 | E15: ='CALCULATION'!E26 | F15: ='CALCULATION'!F26 | G15: ='CALCULATION'!G26 | H15: ='CALCULATION'!H26
A16: ='CALCULATION'!A27 | B16: ='CALCULATION'!B27 | C16: ='CALCULATION'!C27 | D16: ='CALCULATION'!D27 | E16: ='CALCULATION'!E27 | F16: ='CALCULATION'!F27 | G16: ='CALCULATION'!G27 | H16: ='CALCULATION'!H27
A17: ='CALCULATION'!A28 | B17: ='CALCULATION'!B28 | C17: ='CALCULATION'!C28 | D17: ='CALCULATION'!D28 | E17: ='CALCULATION'!E28 | F17: ='CALCULATION'!F28 | G17: ='CALCULATION'!G28 | H17: ='CALCULATION'!H28
