Workbook

Sheet README
A1: T4-1 · 표 4-1. Oracle 신용평점과 실제 신용등급의 비교
A2: 논문 인쇄값을 계산 입력으로 쓰지 않고, 선택 실행의 실제 산출물에서 값을 계산한 Excel입니다.
A4: 항목 | B4: 내용
A5: 선택 실행 | B5: V11_FINAL_FROZEN_REPLAY_RESUME
A6: 실행 방식 | B6: FrozenReplay
A7: 논문 항목 읽기 | B7: 논문 DOCX에서 번호·제목·위치만 동적으로 읽음
A8: 논문 위치 | B8: 4.1 Oracle과 실제 신용등급의 일치도 검증 · 인쇄면 45
A9: 관측·집계 단위 | B9: json_path
A10: 선택 조건 | B10: [[{"column": "json_path", "op": "in", "values": ["per_backend.alpha.all.level_validity_spearman_oriented", "per_backend.alpha.oot.n_movers", "per_backend.alpha.oot.lead_direction_agreement", "per_backend.alpha.oot.lead_direction_agreement_ci95[0]", "per_backend.alpha.oot.lead_direction_agreement_ci95[1]", "per_backend.alpha.oot.lead_spearman", "per_backend.alpha.oot.upgrade_vs_downgrade_auc", "per_backend.beta.all.level_validity_spearman_oriented", "per_backend.beta.oot.lead_direction_agreement", "per_backend.beta.oot.lead_direction_agreement_ci95[0]", "per_backend.beta.oot.lead_direction_agreement_ci95[1]", "per_backend.beta.oot.lead_spearman", "per_backend.beta.oot.upgrade_vs_downgrade_auc", "per_backend.gamma.all.level_validity_spearman_oriented", "per_backend.gamma.oot.lead_direction_agreement", "per_backend.gamma.oot.lead_direction_agreement_ci95[0]", "per_backend.gamma.oot.lead_direction_agreement_ci95[1]", "per_backend.gamma.oot.lead_spearman", "per_backend.gamma.oot.upgrade_vs_downgrade_auc"]}]]
A11: 계산 방법 | B11: 선택 실행 산출물에 명시된 조건을 적용하고 논문 분석단위로 행·열을 정리
A12: 생산 코드 | B12: src/credit_recourse/analysis/paper_repro_analysis.py
A13: 실제 입력 산출물 | B13: frozen_outputs/final_freeze/ledgers/stage1_substrate_validation_loopB1.json frozen_outputs/final_freeze/stage1_oracle_backends/alpha/preliminary_dev_oot_metrics_alpha.csv frozen_outputs/final_freeze/stage1_oracle_backends/beta/preliminary_dev_oot_metrics_beta.csv frozen_outputs/final_freeze/stage1_oracle_backends/gamma/preliminary_dev_oot_metrics_gamma.csv

Sheet SOURCE
A1: T4-1 · 실제 입력 산출물
A2: 선택 실행에서 읽은 실제 중간·최종 산출물입니다. 아래 ANALYSIS가 이 셀들을 직접 참조합니다.
A4: 입력 1: frozen_outputs/final_freeze/ledgers/stage1_substrate_validation_loopB1.json
A5: 파일 크기(bytes) | B5: 10092 | C5: 생산 코드 | D5: src/credit_recourse/analysis/paper_repro_analysis.py | E5: SHA256 | F5: 6074570E79BA6955E7692C696399F5DC8BF04AA496D46EF06F5869E8293265BC | G5: 읽기 상태 | H5: OK
A6: json_path | B6: value
A7: stage | B7: verify_stage1_substrate_validation
A8: loop | B8: B1
A9: specification | B9: lead (Oracle score change t-1->t vs real 10-grade rating change t->t+1)
A10: scale | B10: rating_num_10
A11: thresholds.level_validity_spearman_oriented_min | B11: 0.55
A12: thresholds.level_validity_orientation_rule | B12: oriented = -spearman(R_score, rating_num_10), because R_score is higher-is-better and rating_num_10 is lower-is-better
A13: thresholds.loopB1_lead_direction_agreement_target | B13: 0.65
A14: thresholds.loopB1_lead_direction_agreement_min_rule | B14: 95pct_CI_lower_bound_gt_0.50
A15: thresholds.loopB1_direction_agreement_ci_method | B15: wilson
A16: thresholds.loopB1_delta_zero_rule | B16: rating_delta_zero_excluded; score_delta_zero_among_movers_counts_as_nonmatch
A17: thresholds.loopB1_lead_spearman_target | B17: 0.35
A18: per_backend.alpha.backend | B18: alpha
A19: per_backend.alpha.score_column | B19: R_score_alpha
A20: per_backend.alpha.all.n_pairs | B20: 1951
A21: per_backend.alpha.all.n_movers | B21: 350
A22: per_backend.alpha.all.level_validity_spearman_raw | B22: -0.6781862
A23: per_backend.alpha.all.level_validity_spearman_oriented | B23: 0.6781862
A24: per_backend.alpha.all.level_validity_spearman | B24: -0.6781862
A25: per_backend.alpha.all.rating_num_10_orientation | B25: lower_is_better
A26: per_backend.alpha.all.score_orientation | B26: higher_is_better
A27: per_backend.alpha.all.direction_agreement_ci_method | B27: wilson
A28: per_backend.alpha.all.delta_zero_rule | B28: rating_delta_zero_excluded; score_delta_zero_among_movers_counts_as_nonmatch
A29: per_backend.alpha.all.n_score_delta_zero_movers | B29: 0
A30: per_backend.alpha.all.lead_direction_agreement | B30: 0.7
A31: per_backend.alpha.all.lead_direction_agreement_ci95[0] | B31: 0.65003157
A32: per_backend.alpha.all.lead_direction_agreement_ci95[1] | B32: 0.74562586
A33: per_backend.alpha.all.lead_direction_agreement_matches | B33: 245
A34: per_backend.alpha.all.lead_spearman | B34: 0.41160076
A35: per_backend.alpha.all.lead_spearman_p | B35: 9.622559e-16
A36: per_backend.alpha.all.upgrade_vs_downgrade_auc | B36: 0.75563627
A37: per_backend.alpha.oot.n_pairs | B37: 933
A38: per_backend.alpha.oot.n_movers | B38: 161
A39: per_backend.alpha.oot.level_validity_spearman_raw | B39: -0.6781862
A40: per_backend.alpha.oot.level_validity_spearman_oriented | B40: 0.6781862
A41: per_backend.alpha.oot.level_validity_spearman | B41: -0.6781862
...

Sheet CALCULATION
A1: T4-1 · 분석 과정
A2: 필터·분석단위와 실제 계산 결과입니다. 수치 셀은 SOURCE를 직접 참조합니다.
A4: 항목 | B4: 내용
A5: 계산 방법 | B5: 선택 실행 산출물에 명시된 조건을 적용하고 논문 분석단위로 행·열을 정리
A6: 생산 코드 | B6: src/credit_recourse/analysis/paper_repro_analysis.py
A7: 선택 실행 | B7: V11_FINAL_FROZEN_REPLAY_RESUME
A11: 이 표·그림과 연결된 본문 핵심 수치
A12: 수치 ID | B12: 본문 주장 | C12: 논문 표시값 | D12: 재계산값 | E12: 확인 결과 | F12: 계산식 | G12: 실제 입력 산출물
A13: NC0106-01 | B13: 세 Oracle 모두 실제 신용등급의 순서와 양의 관계를 보였다. Oracle-α의 같은 시점 순위상관은 0.678이었고, 1년 선행 순위상관은 0.500이었다. 실제 신용등급이 이동한 161개 기업에서는 Oracle 신용평점의 변화방향과 다음 해 등급이동 방향이 72.0% 일치했으며, AUC는 0.803이었다. Oracle-β와 Oracle-γ에서도 같은 시점의 순위상관과 다음 해 등급이동 방향에 대한 양의 관계가 나타났다. 이후 분석에서는 Oracle-α를 주요 평가모형으로 사용하고, Oracle-β와 Oracle-γ를 이용해 결과의 방향이 유지되는지를 함께 확인한다. | C13: 0.678 | D13: 0.678 | E13: 논문값과 일치 | F13: per_backend.alpha.all.level_validity_spearman_oriented | G13: frozen_outputs/final_freeze/ledgers/stage1_substrate_validation_loopB1.json
A14: NC0106-03 | B14: 세 Oracle 모두 실제 신용등급의 순서와 양의 관계를 보였다. Oracle-α의 같은 시점 순위상관은 0.678이었고, 1년 선행 순위상관은 0.500이었다. 실제 신용등급이 이동한 161개 기업에서는 Oracle 신용평점의 변화방향과 다음 해 등급이동 방향이 72.0% 일치했으며, AUC는 0.803이었다. Oracle-β와 Oracle-γ에서도 같은 시점의 순위상관과 다음 해 등급이동 방향에 대한 양의 관계가 나타났다. 이후 분석에서는 Oracle-α를 주요 평가모형으로 사용하고, Oracle-β와 Oracle-γ를 이용해 결과의 방향이 유지되는지를 함께 확인한다. | C14: 0.500 | D14: 0.5 | E14: 논문값과 일치 | F14: per_backend.alpha.oot.lead_spearman | G14: frozen_outputs/final_freeze/ledgers/stage1_substrate_validation_loopB1.json
A15: NC0106-04 | B15: 세 Oracle 모두 실제 신용등급의 순서와 양의 관계를 보였다. Oracle-α의 같은 시점 순위상관은 0.678이었고, 1년 선행 순위상관은 0.500이었다. 실제 신용등급이 이동한 161개 기업에서는 Oracle 신용평점의 변화방향과 다음 해 등급이동 방향이 72.0% 일치했으며, AUC는 0.803이었다. Oracle-β와 Oracle-γ에서도 같은 시점의 순위상관과 다음 해 등급이동 방향에 대한 양의 관계가 나타났다. 이후 분석에서는 Oracle-α를 주요 평가모형으로 사용하고, Oracle-β와 Oracle-γ를 이용해 결과의 방향이 유지되는지를 함께 확인한다. | C15: 161개 | D15: 161 | E15: 논문값과 일치 | F15: COUNT(per_backend.alpha.oot rating movers) | G15: frozen_outputs/final_freeze/ledgers/stage1_substrate_validation_loopB1.json
A16: NC0106-05 | B16: 세 Oracle 모두 실제 신용등급의 순서와 양의 관계를 보였다. Oracle-α의 같은 시점 순위상관은 0.678이었고, 1년 선행 순위상관은 0.500이었다. 실제 신용등급이 이동한 161개 기업에서는 Oracle 신용평점의 변화방향과 다음 해 등급이동 방향이 72.0% 일치했으며, AUC는 0.803이었다. Oracle-β와 Oracle-γ에서도 같은 시점의 순위상관과 다음 해 등급이동 방향에 대한 양의 관계가 나타났다. 이후 분석에서는 Oracle-α를 주요 평가모형으로 사용하고, Oracle-β와 Oracle-γ를 이용해 결과의 방향이 유지되는지를 함께 확인한다. | C16: 72.0% | D16: 72 | E16: 논문값과 일치 | F16: 100 * per_backend.alpha.oot.lead_direction_agreement | G16: frozen_outputs/final_freeze/ledgers/stage1_substrate_validation_loopB1.json
A17: NC0106-06 | B17: 세 Oracle 모두 실제 신용등급의 순서와 양의 관계를 보였다. Oracle-α의 같은 시점 순위상관은 0.678이었고, 1년 선행 순위상관은 0.500이었다. 실제 신용등급이 이동한 161개 기업에서는 Oracle 신용평점의 변화방향과 다음 해 등급이동 방향이 72.0% 일치했으며, AUC는 0.803이었다. Oracle-β와 Oracle-γ에서도 같은 시점의 순위상관과 다음 해 등급이동 방향에 대한 양의 관계가 나타났다. 이후 분석에서는 Oracle-α를 주요 평가모형으로 사용하고, Oracle-β와 Oracle-γ를 이용해 결과의 방향이 유지되는지를 함께 확인한다. | C17: 0.803 | D17: 0.803 | E17: 논문값과 일치 | F17: per_backend.alpha.oot.upgrade_vs_downgrade_auc | G17: frozen_outputs/final_freeze/ledgers/stage1_substrate_validation_loopB1.json
A20: 계산 데이터: oracle_oot_validation
A21: 입력 파일 | B21: data/final_freeze/ledgers/stage1_substrate_validation_loopB1.json
A22: 선택 조건 | B22: [{"column": "json_path", "op": "in", "values": ["per_backend.alpha.all.level_validity_spearman_oriented", "per_backend.alpha.oot.n_movers", "per_backend.alpha.oot.lead_direction_agreement", "per_backend.alpha.oot.lead_direction_agreement_ci95[0]", "per_backend.alpha.oot.lead_direction_agreement_ci95[1]", "per_backend.alpha.oot.lead_spearman", "per_backend.alpha.oot.upgrade_vs_downgrade_auc", "per_backend.beta.all.level_validity_spearman_oriented", "per_backend.beta.oot.lead_direction_agreement", "per_backend.beta.oot.lead_direction_agreement_ci95[0]", "per_backend.beta.oot.lead_direction_agreement_ci95[1]", "per_backend.beta.oot.lead_spearman", "per_backend.beta.oot.upgrade_vs_downgrade_auc", "per_backend.gamma.all.level_validity_spearman_oriented", "per_backend.gamma.oot.lead_direction_agreement", "per_backend.gamma.oot.lead_direction_agreement_ci95[0]", "per_backend.gamma.oot.lead_direction_agreement_ci95[1]", "per_backend.gamma.oot.lead_spearman", "per_backend.gamma.oot.upgrade_vs_downgrade_auc"]}]
A23: 분석 단위 | B23: json_path
A24: 집계 | B24: PRODUCER_AGGREGATE_NO_REAGGREGATION
A25: json_path | B25: value
A26: ='SOURCE'!A23 | B26: ='SOURCE'!B23
A27: ='SOURCE'!A38 | B27: ='SOURCE'!B38
A28: ='SOURCE'!A47 | B28: ='SOURCE'!B47
A29: ='SOURCE'!A48 | B29: ='SOURCE'!B48
A30: ='SOURCE'!A49 | B30: ='SOURCE'!B49
A31: ='SOURCE'!A51 | B31: ='SOURCE'!B51
A32: ='SOURCE'!A53 | B32: ='SOURCE'!B53
A33: ='SOURCE'!A78 | B33: ='SOURCE'!B78
A34: ='SOURCE'!A102 | B34: ='SOURCE'!B102
A35: ='SOURCE'!A103 | B35: ='SOURCE'!B103
A36: ='SOURCE'!A104 | B36: ='SOURCE'!B104
A37: ='SOURCE'!A106 | B37: ='SOURCE'!B106
A38: ='SOURCE'!A108 | B38: ='SOURCE'!B108
A39: ='SOURCE'!A133 | B39: ='SOURCE'!B133
A40: ='SOURCE'!A157 | B40: ='SOURCE'!B157
A41: ='SOURCE'!A158 | B41: ='SOURCE'!B158
A42: ='SOURCE'!A159 | B42: ='SOURCE'!B159
A43: ='SOURCE'!A161 | B43: ='SOURCE'!B161
A44: ='SOURCE'!A163 | B44: ='SOURCE'!B163

Sheet PAPER_TABLE
A1: T4-1 · 논문 표 작업용 결과
A2: ANALYSIS에서 계산된 값만 연결한 최종 작업표입니다. Excel에서 정렬·피벗·표시형식만 조정하면 됩니다.
A4: 계산 결과: oracle_oot_validation
A5: ='CALCULATION'!A25 | B5: ='CALCULATION'!B25
A6: ='CALCULATION'!A26 | B6: ='CALCULATION'!B26
A7: ='CALCULATION'!A27 | B7: ='CALCULATION'!B27
A8: ='CALCULATION'!A28 | B8: ='CALCULATION'!B28
A9: ='CALCULATION'!A29 | B9: ='CALCULATION'!B29
A10: ='CALCULATION'!A30 | B10: ='CALCULATION'!B30
A11: ='CALCULATION'!A31 | B11: ='CALCULATION'!B31
A12: ='CALCULATION'!A32 | B12: ='CALCULATION'!B32
A13: ='CALCULATION'!A33 | B13: ='CALCULATION'!B33
A14: ='CALCULATION'!A34 | B14: ='CALCULATION'!B34
A15: ='CALCULATION'!A35 | B15: ='CALCULATION'!B35
A16: ='CALCULATION'!A36 | B16: ='CALCULATION'!B36
... A24: ='CALCULATION'!A44 | B24: ='CALCULATION'!B44
