Workbook

Sheet README
A1: T5-6 · 표 5-6. GPT-5.4-mini의 정보조건별 정책가치(Oracle-α)
A2: 논문 인쇄값을 계산 입력으로 쓰지 않고, 선택 실행의 실제 산출물에서 값을 계산한 Excel입니다.
A4: 항목 | B4: 내용
A5: 선택 실행 | B5: V11_FINAL_FROZEN_REPLAY_RESUME
A6: 실행 방식 | B6: FrozenReplay
A7: 논문 항목 읽기 | B7: 논문 DOCX에서 번호·제목·위치만 동적으로 읽음
A8: 논문 위치 | B8: 5.4 정보조건과 기업명 인식 · 인쇄면 60
A9: 관측·집계 단위 | B9: source_file + policy
A10: 선택 조건 | B10: [[{"column": "policy", "op": "in", "values": ["C4", "C6"]}]]
A11: 계산 방법 | B11: 같은 기업의 행동 후 Oracle 점수에서 그 기업의 무행동 Oracle 점수를 뺀 뒤 기업 단위로 집계
A12: 생산 코드 | B12: src/credit_recourse/analysis/n5_budget_frontier_holm_inference.py
A13: 실제 입력 산출물 | B13: frozen_outputs/analysis/paper_repro/03_output_contract_diagnostics/n5_generation_budget_frontier_holm/n5_budget_frontier_table_patch.csv frozen_outputs/final_freeze/llm_runs/N5_C6_L1_1p27_ICa_gpt54mini_p50_main_seed1_20260707/stage8_llm_multi_oracle_eval/llm_stage8_multi_oracle_scores.parquet frozen_outputs/final_freeze/llm_runs/N5_C6_L1_1p27_ICb_gpt54mini_p50_main_seed1_20260707/stage8_llm_multi_oracle_eval/llm_stage8_multi_oracle_scores.parquet frozen_outputs/final_freeze/llm_runs/N5_C6_L1_1p27_ICc_gpt54mini_p50_main_seed1_20260707/stage8_llm_multi_oracle_eval/llm_stage8_multi_oracle_scores.parquet frozen_outputs/final_freeze/llm_runs/N5_C6_L1_1p27_ICa_gpt54mini_p50_main_seed1_20260707/stage8_llm_multi_oracle_eval/llm_stage8_policy_summary.csv frozen_outputs/final_freeze/llm_runs/N5_C6_L1_1p27_ICb_gpt54mini_p50_main_seed1_20260707/stage8_llm_multi_oracle_eval/llm_stage8_policy_summary.csv frozen_outputs/final_freeze/llm_runs/N5_C6_L1_1p27_ICc_gpt54mini_p50_main_seed1_20260707/stage8_llm_multi_oracle_eval/llm_stage8_policy_summary.csv

Sheet SOURCE
A1: T5-6 · 실제 입력 산출물
A2: 선택 실행에서 읽은 실제 중간·최종 산출물입니다. 아래 ANALYSIS가 이 셀들을 직접 참조합니다.
A4: 입력 1: frozen_outputs/analysis/paper_repro/03_output_contract_diagnostics/n5_generation_budget_frontier_holm/n5_budget_frontier_table_patch.csv
A5: 파일 크기(bytes) | B5: 1314 | C5: 생산 코드 | D5: src/credit_recourse/analysis/n5_budget_frontier_holm_inference.py | E5: SHA256 | F5: 2EA25F0676901FC49917066769CDD23659B0AD2C60FFB59A6ECCD6E3700C654D | G5: 읽기 상태 | H5: OK
A6: design | B6: oracle_backend | C6: budget_label | D6: l1_budget | E6: run_label | F6: n_pairs | G6: mean_C4 | H6: mean_C6 | I6: mean_C6_minus_C4 | J6: C6_minus_C4_p_holm | K6: C6_minus_C4_sig | L6: C6_minus_unbounded_gap | M6: C6_minus_unbounded_p_holm | N6: C6_minus_unbounded_sig | O6: interaction_or_package_DID_gap | P6: interaction_or_package_DID_p_holm | Q6: interaction_or_package_DID_sig
A7: legacy_c6_only | B7: alpha | C7: 0p75 | D7: 0.75 | E7: N5F_C4C6_L1_0p75_ICb_gpt54mini_p50_main_seed1_20260712_083213 | F7: 575 | G7: 0.84806938 | H7: 0.84954939 | I7: 0.0014800074 | J7: 0.22535094 | K7: n.s. | L7: -0.20934534 | M7: 5.7373954e-13 | N7: *** | O7: -0.18567208 | P7: 2.6114801e-07 | Q7: ***
A8: legacy_c6_only | B8: alpha | C8: 1p27 | D8: 1.27 | E8: N5F_C4C6_L1_1p27_ICb_gpt54mini_p50_main_seed1_20260712_083213 | F8: 575 | G8: 0.82994709 | H8: 0.9114068 | I8: 0.081459712 | J8: 0.03275921 | K8: * | L8: -0.14748793 | M8: 5.283671e-07 | N8: *** | O8: -0.10569237 | P8: 0.0010040514 | Q8: **
A9: legacy_c6_only | B9: alpha | C9: 2p00 | D9: 2 | E9: N5F_C4C6_L1_2p00_ICb_gpt54mini_p50_main_seed1_20260712_083213 | F9: 575 | G9: 0.89564649 | H9: 1.069689 | I9: 0.17404248 | J9: 1.0682402e-07 | K9: *** | L9: 0.010794236 | M9: 0.77426926 | N9: n.s. | O9: -0.013109608 | P9: 0.4786527 | Q9: n.s.
A10: legacy_c6_only | B10: alpha | C10: unbounded | E10: N5F_C4C6_L1_unbounded_ICb_gpt54mini_p50_main_seed1_20260712_083213 | F10: 575 | G10: 0.87174264 | H10: 1.0588947 | I10: 0.18715208 | J10: 3.2477506e-11 | K10: ***
A13: 입력 2: frozen_outputs/final_freeze/llm_runs/N5_C6_L1_1p27_ICa_gpt54mini_p50_main_seed1_20260707/stage8_llm_multi_oracle_eval/llm_stage8_multi_oracle_scores.parquet
A14: 파일 크기(bytes) | B14: 75450 | C14: 생산 코드 | D14: src/credit_recourse/analysis/n5_budget_frontier_holm_inference.py | E14: SHA256 | F14: 8CA3186823E010D031F8A0005EDB4896AE2909ABE43D965DA5D130B49868FE52 | G14: 읽기 상태 | H14: TRUNCATED
A15: row_id | B15: policy | C15: mode | D15: candidate_id | E15: R_score_alpha | F15: R_score_beta | G15: R_score_gamma | H15: noop_R_score_alpha | I15: delta_R_score_alpha | J15: noop_R_score_beta | K15: delta_R_score_beta | L15: noop_R_score_gamma | M15: delta_R_score_gamma
A16: 0 | B16: C4 | C16: free_form_10d | D16: DL1_deleverage_mild | E16: 80.762481 | F16: 71.661882 | G16: 76.170598 | H16: 80.762481 | I16: 0 | J16: 71.550825 | K16: 0.11105726 | L16: 75.110398 | M16: 1.0602005
A17: 0 | B17: C6 | C17: free_form_10d | D17: DL1_deleverage_mild | E17: 80.762481 | F17: 71.661882 | G17: 76.170598 | H17: 80.762481 | I17: 0 | J17: 71.550825 | K17: 0.11105726 | L17: 75.110398 | M17: 1.0602005
A18: 1 | B18: C4 | C18: free_form_10d | D18: OE1_cost_efficiency_mild | E18: 77.977741 | F18: 76.194731 | G18: 78.841487 | H18: 77.977741 | I18: 0 | J18: 76.119154 | K18: 0.075577392 | L18: 78.841487 | M18: 0
A19: 1 | B19: C6 | C19: free_form_10d | D19: OE1_cost_efficiency_mild | E19: 77.977741 | F19: 76.194731 | G19: 78.841487 | H19: 77.977741 | I19: 0 | J19: 76.119154 | K19: 0.075577392 | L19: 78.841487 | M19: 0
A20: 2 | B20: C4 | C20: free_form_10d | D20: OE1_cost_efficiency_mild | E20: 69.166072 | F20: 67.384023 | G20: 69.936775 | H20: 68.2742 | I20: 0.89187138 | J20: 67.243536 | K20: 0.14048718 | L20: 69.936775 | M20: 0
A21: 2 | B21: C6 | C21: free_form_10d | D21: OE2_cost_efficiency_moderate | E21: 69.44826 | F21: 67.443398 | G21: 69.936775 | H21: 68.2742 | I21: 1.1740594 | J21: 67.243536 | K21: 0.19986187 | L21: 69.936775 | M21: 0
A22: 3 | B22: C4 | C22: free_form_10d | D22: MX1_cost_and_deleverage | E22: 72.172397 | F22: 68.447831 | G22: 78.124746 | H22: 70.998337 | I22: 1.1740594 | J22: 68.290359 | K22: 0.15747156 | L22: 77.628703 | M22: 0.49604281
A23: 3 | B23: C6 | C23: free_form_10d | D23: OE2_cost_efficiency_moderate | E23: 72.172397 | F23: 68.485544 | G23: 78.124746 | H23: 70.998337 | I23: 1.1740594 | J23: 68.290359 | K23: 0.19518445 | L23: 77.628703 | M23: 0.49604281
A24: 4 | B24: C4 | C24: free_form_10d | D24: OE1_cost_efficiency_mild | E24: 77.201711 | F24: 75.859954 | G24: 70.40531 | H24: 75.0503 | I24: 2.1514108 | J24: 75.813074 | K24: 0.046879229 | L24: 69.89615 | M24: 0.50916032
A25: 4 | B25: C6 | C25: free_form_10d | D25: OE2_cost_efficiency_moderate | E25: 77.201711 | F25: 75.887708 | G25: 70.40531 | H25: 75.0503 | I25: 2.1514108 | J25: 75.813074 | K25: 0.07463403 | L25: 69.89615 | M25: 0.50916032
A26: 5 | B26: C4 | C26: free_form_10d | D26: OE2_cost_efficiency_moderate | E26: 70.936712 | F26: 68.200615 | G26: 70.814909 | H26: 70.747307 | I26: 0.18940416 | J26: 68.17692 | K26: 0.023695234 | L26: 70.814909 | M26: 0
A27: 5 | B27: C6 | C27: free_form_10d | D27: OE1_cost_efficiency_mild | E27: 70.936712 | F27: 68.198817 | G27: 70.814909 | H27: 70.747307 | I27: 0.18940416 | J27: 68.17692 | K27: 0.021897008 | L27: 70.814909 | M27: 0
... A265: 124 | B265: C6 | C265: free_form_10d | D265: OE2_cost_efficiency_moderate | E265: 83.176164 | F265: 73.513016 | G265: 82.578839 | H265: 80.092817 | I265: 3.0833473 | J265: 73.260612 | K265: 0.25240393 | L265: 80.443514 | M265: 2.1353258
A268: 입력 3: frozen_outputs/final_freeze/llm_runs/N5_C6_L1_1p27_ICb_gpt54mini_p50_main_seed1_20260707/stage8_llm_multi_oracle_eval/llm_stage8_multi_oracle_scores.parquet
A269: 파일 크기(bytes) | B269: 75366 | C269: 생산 코드 | D269: src/credit_recourse/analysis/n5_budget_frontier_holm_inference.py | E269: SHA256 | F269: 3BBB0EB7EF7DB1B9876B94A0A4C0D30C0636FA7A7A95760D318D57DD3183A8FA | G269: 읽기 상태 | H269: TRUNCATED
A270: row_id | B270: policy | C270: mode | D270: candidate_id | E270: R_score_alpha | F270: R_score_beta | G270: R_score_gamma | H270: noop_R_score_alpha | I270: delta_R_score_alpha | J270: noop_R_score_beta | K270: delta_R_score_beta | L270: noop_R_score_gamma | M270: delta_R_score_gamma
A271: 0 | B271: C4 | C271: free_form_10d | D271: MX1_cost_and_deleverage | E271: 80.762481 | F271: 71.645509 | G271: 75.487351 | H271: 80.762481 | I271: 0 | J271: 71.550825 | K271: 0.094684155 | L271: 75.110398 | M271: 0.37695357
A272: 0 | B272: C6 | C272: free_form_10d | D272: MX1_cost_and_deleverage | E272: 80.762481 | F272: 71.645509 | G272: 75.487351 | H272: 80.762481 | I272: 0 | J272: 71.550825 | K272: 0.094684155 | L272: 75.110398 | M272: 0.37695357
A273: 1 | B273: C4 | C273: free_form_10d | D273: DL1_deleverage_mild | E273: 82.740507 | F273: 76.263202 | G273: 79.076382 | H273: 77.977741 | I273: 4.7627666 | J273: 76.119154 | K273: 0.14404767 | L273: 78.841487 | M273: 0.23489484
A274: 1 | B274: C6 | C274: free_form_10d | D274: OE1_cost_efficiency_mild | E274: 82.740507 | F274: 76.235078 | G274: 78.760402 | H274: 77.977741 | I274: 4.7627666 | J274: 76.119154 | K274: 0.11592349 | L274: 78.841487 | M274: -0.08108462
A275: 2 | B275: C4 | C275: free_form_10d | D275: OE2_cost_efficiency_moderate | E275: 68.2742 | F275: 67.369476 | G275: 69.936775 | H275: 68.2742 | I275: 0 | J275: 67.243536 | K275: 0.12593987 | L275: 69.936775 | M275: 0
A276: 2 | B276: C6 | C276: free_form_10d | D276: OE2_cost_efficiency_moderate | E276: 69.44826 | F276: 67.414209 | G276: 69.936775 | H276: 68.2742 | I276: 1.1740594 | J276: 67.243536 | K276: 0.17067292 | L276: 69.936775 | M276: 0
A277: 3 | B277: C4 | C277: free_form_10d | D277: MX2_liquidity_rescue | E277: 71.890209 | F277: 68.32578 | G277: 78.124746 | H277: 70.998337 | I277: 0.89187138 | J277: 68.290359 | K277: 0.035421365 | L277: 77.628703 | M277: 0.49604281
A278: 3 | B278: C6 | C278: free_form_10d | D278: OE2_cost_efficiency_moderate | E278: 72.172397 | F278: 68.499428 | G278: 78.124746 | H278: 70.998337 | I278: 1.1740594 | J278: 68.290359 | K278: 0.20906886 | L278: 77.628703 | M278: 0.49604281
A279: 4 | B279: C4 | C279: free_form_10d | D279: OE2_cost_efficiency_moderate | E279: 77.201711 | F279: 75.875634 | G279: 70.40531 | H279: 75.0503 | I279: 2.1514108 | J279: 75.813074 | K279: 0.062559941 | L279: 69.89615 | M279: 0.50916032
A280: 4 | B280: C6 | C280: free_form_10d | D280: OE2_cost_efficiency_moderate | E280: 77.201711 | F280: 75.89272 | G280: 73.102977 | H280: 75.0503 | I280: 2.1514108 | J280: 75.813074 | K280: 0.07964573 | L280: 69.89615 | M280: 3.206827
A281: 5 | B281: C4 | C281: free_form_10d | D281: OE2_cost_efficiency_moderate | E281: 70.936712 | F281: 68.199531 | G281: 70.814909 | H281: 70.747307 | I281: 0.18940416 | J281: 68.17692 | K281: 0.022611298 | L281: 70.814909 | M281: 0
A282: 5 | B282: C6 | C282: free_form_10d | D282: OE2_cost_efficiency_moderate | E282: 70.936712 | F282: 68.199531 | G282: 70.814909 | H282: 70.747307 | I282: 0.18940416 | J282: 68.17692 | K282: 0.022611298 | L282: 70.814909 | M282: 0
...

Sheet CALCULATION
A1: T5-6 · 분석 과정
A2: 필터·분석단위와 실제 계산 결과입니다. 수치 셀은 SOURCE를 직접 참조합니다.
A4: 항목 | B4: 내용
A5: 계산 방법 | B5: 같은 기업의 행동 후 Oracle 점수에서 그 기업의 무행동 Oracle 점수를 뺀 뒤 기업 단위로 집계
A6: 생산 코드 | B6: src/credit_recourse/analysis/n5_budget_frontier_holm_inference.py
A7: 선택 실행 | B7: V11_FINAL_FROZEN_REPLAY_RESUME
A11: 동일기업 정책가치 계산
A12: 입력 산출물 | B12: 기업 행 수 | C12: 결합 방식 | D12: 정책가치 정의
A13: frozen_outputs/final_freeze/llm_runs/N5_C6_L1_1p27_ICa_gpt54mini_p50_main_seed1_20260707/stage8_llm_multi_oracle_eval/llm_stage8_multi_oracle_scores.parquet | B13: 1150 | C13: EXPLICIT_NOOP_SCORE_SAME_ROW | D13: 동일기업 행동 점수 − 동일기업 무행동 점수
A14: frozen_outputs/final_freeze/llm_runs/N5_C6_L1_1p27_ICb_gpt54mini_p50_main_seed1_20260707/stage8_llm_multi_oracle_eval/llm_stage8_multi_oracle_scores.parquet | B14: 1150 | C14: EXPLICIT_NOOP_SCORE_SAME_ROW | D14: 동일기업 행동 점수 − 동일기업 무행동 점수
A15: frozen_outputs/final_freeze/llm_runs/N5_C6_L1_1p27_ICc_gpt54mini_p50_main_seed1_20260707/stage8_llm_multi_oracle_eval/llm_stage8_multi_oracle_scores.parquet | B15: 1150 | C15: EXPLICIT_NOOP_SCORE_SAME_ROW | D15: 동일기업 행동 점수 − 동일기업 무행동 점수
A18: 계산 데이터: n5_information_condition_summaries
A19: 입력 파일 | B19: data/final_freeze/llm_runs/N5_C6_L1_1p27_ICa_gpt54mini_p50_main_seed1_20260707/stage8_llm_multi_oracle_eval/llm_stage8_policy_summary.csv; data/final_freeze/llm_runs/N5_C6_L1_1p27_ICb_gpt54mini_p50_main_seed1_20260707/stage8_llm_multi_oracle_eval/llm_stage8_policy_summary.csv; data/final_freeze/llm_runs/N5_C6_L1_1p27_ICc_gpt54mini_p50_main_seed1_20260707/stage8_llm_multi_oracle_eval/llm_stage8_policy_summary.csv
A20: 선택 조건 | B20: [{"column": "policy", "op": "in", "values": ["C4", "C6"]}]
A21: 분석 단위 | B21: source_file; policy
A22: 집계 | B22: PRODUCER_MEAN_AFTER_SAME_FIRM_PAIRING_VERIFIED
A23: source_file | B23: policy | C23: n_rows | D23: mean_delta_R_score_alpha | E23: mean_delta_R_score_beta | F23: mean_delta_R_score_gamma
A24: data/final_freeze/llm_runs/N5_C6_L1_1p27_ICa_gpt54mini_p50_main_seed1_20260707/stage8_llm_multi_oracle_eval/llm_stage8_policy_summary.csv | B24: ='SOURCE'!A781 | C24: ='SOURCE'!B781 | D24: ='SOURCE'!C781 | E24: ='SOURCE'!G781 | F24: ='SOURCE'!K781
A25: data/final_freeze/llm_runs/N5_C6_L1_1p27_ICa_gpt54mini_p50_main_seed1_20260707/stage8_llm_multi_oracle_eval/llm_stage8_policy_summary.csv | B25: ='SOURCE'!A782 | C25: ='SOURCE'!B782 | D25: ='SOURCE'!C782 | E25: ='SOURCE'!G782 | F25: ='SOURCE'!K782
A26: data/final_freeze/llm_runs/N5_C6_L1_1p27_ICb_gpt54mini_p50_main_seed1_20260707/stage8_llm_multi_oracle_eval/llm_stage8_policy_summary.csv | B26: ='SOURCE'!A788 | C26: ='SOURCE'!B788 | D26: ='SOURCE'!C788 | E26: ='SOURCE'!G788 | F26: ='SOURCE'!K788
A27: data/final_freeze/llm_runs/N5_C6_L1_1p27_ICb_gpt54mini_p50_main_seed1_20260707/stage8_llm_multi_oracle_eval/llm_stage8_policy_summary.csv | B27: ='SOURCE'!A789 | C27: ='SOURCE'!B789 | D27: ='SOURCE'!C789 | E27: ='SOURCE'!G789 | F27: ='SOURCE'!K789
A28: data/final_freeze/llm_runs/N5_C6_L1_1p27_ICc_gpt54mini_p50_main_seed1_20260707/stage8_llm_multi_oracle_eval/llm_stage8_policy_summary.csv | B28: ='SOURCE'!A795 | C28: ='SOURCE'!B795 | D28: ='SOURCE'!C795 | E28: ='SOURCE'!G795 | F28: ='SOURCE'!K795
A29: data/final_freeze/llm_runs/N5_C6_L1_1p27_ICc_gpt54mini_p50_main_seed1_20260707/stage8_llm_multi_oracle_eval/llm_stage8_policy_summary.csv | B29: ='SOURCE'!A796 | C29: ='SOURCE'!B796 | D29: ='SOURCE'!C796 | E29: ='SOURCE'!G796 | F29: ='SOURCE'!K796

Sheet PAPER_TABLE
A1: T5-6 · 논문 표 작업용 결과
A2: ANALYSIS에서 계산된 값만 연결한 최종 작업표입니다. Excel에서 정렬·피벗·표시형식만 조정하면 됩니다.
A4: 계산 결과: n5_information_condition_summaries
A5: ='CALCULATION'!A23 | B5: ='CALCULATION'!B23 | C5: ='CALCULATION'!C23 | D5: ='CALCULATION'!D23 | E5: ='CALCULATION'!E23 | F5: ='CALCULATION'!F23
A6: ='CALCULATION'!A24 | B6: ='CALCULATION'!B24 | C6: ='CALCULATION'!C24 | D6: ='CALCULATION'!D24 | E6: ='CALCULATION'!E24 | F6: ='CALCULATION'!F24
A7: ='CALCULATION'!A25 | B7: ='CALCULATION'!B25 | C7: ='CALCULATION'!C25 | D7: ='CALCULATION'!D25 | E7: ='CALCULATION'!E25 | F7: ='CALCULATION'!F25
A8: ='CALCULATION'!A26 | B8: ='CALCULATION'!B26 | C8: ='CALCULATION'!C26 | D8: ='CALCULATION'!D26 | E8: ='CALCULATION'!E26 | F8: ='CALCULATION'!F26
A9: ='CALCULATION'!A27 | B9: ='CALCULATION'!B27 | C9: ='CALCULATION'!C27 | D9: ='CALCULATION'!D27 | E9: ='CALCULATION'!E27 | F9: ='CALCULATION'!F27
A10: ='CALCULATION'!A28 | B10: ='CALCULATION'!B28 | C10: ='CALCULATION'!C28 | D10: ='CALCULATION'!D28 | E10: ='CALCULATION'!E28 | F10: ='CALCULATION'!F28
A11: ='CALCULATION'!A29 | B11: ='CALCULATION'!B29 | C11: ='CALCULATION'!C29 | D11: ='CALCULATION'!D29 | E11: ='CALCULATION'!E29 | F11: ='CALCULATION'!F29
