Workbook

Sheet README
A1: T4-5 · 표 4-5. Candidate-IQL과 무행동·휴리스틱의 비교
A2: 논문 인쇄값을 계산 입력으로 쓰지 않고, 선택 실행의 실제 산출물에서 값을 계산한 Excel입니다.
A4: 항목 | B4: 내용
A5: 선택 실행 | B5: V11_FINAL_FROZEN_REPLAY_RESUME
A6: 실행 방식 | B6: FrozenReplay
A7: 논문 항목 읽기 | B7: 논문 DOCX에서 번호·제목·위치만 동적으로 읽음
A8: 논문 위치 | B8: 4.4 비교정책 Candidate-IQL의 정책가치 · 인쇄면 51
A9: 관측·집계 단위 | B9: source_file + policy_a + policy_b
A10: 선택 조건 | B10: [[{"column": "policy_a", "op": "equals", "value": "C3_candidate_iql"}, {"column": "policy_b", "op": "in", "values": ["C0_noop", "C2_weakest_component_rule"]}]]
A11: 계산 방법 | B11: 같은 기업의 행동 후 Oracle 점수에서 그 기업의 무행동 Oracle 점수를 뺀 뒤 기업 단위로 집계
A12: 생산 코드 | B12: src/credit_recourse/rl/pipelines/final_stage6_candidate_iql_multi_oracle_eval/pipeline.py
A13: 실제 입력 산출물 | B13: frozen_outputs/final_freeze/stage6_candidate_selector_eval/multi_oracle_policy_eval.parquet frozen_outputs/final_freeze/stage6_multi_oracle_eval/policy_paired_inference_alpha.csv frozen_outputs/final_freeze/stage6_multi_oracle_eval/policy_paired_inference_beta.csv frozen_outputs/final_freeze/stage6_multi_oracle_eval/policy_paired_inference_gamma.csv frozen_outputs/final_freeze/stage6_multi_oracle_eval/paired_tests_alpha.csv frozen_outputs/final_freeze/stage6_multi_oracle_eval/paired_tests_beta.csv frozen_outputs/final_freeze/stage6_multi_oracle_eval/paired_tests_gamma.csv

Sheet SOURCE
A1: T4-5 · 실제 입력 산출물
A2: 선택 실행에서 읽은 실제 중간·최종 산출물입니다. 아래 ANALYSIS가 이 셀들을 직접 참조합니다.
A4: 입력 1: frozen_outputs/final_freeze/stage6_candidate_selector_eval/multi_oracle_policy_eval.parquet
A5: 파일 크기(bytes) | B5: 246988 | C5: 생산 코드 | D5: src/credit_recourse/rl/pipelines/final_stage6_candidate_iql_multi_oracle_eval/pipeline.py | E5: SHA256 | F5: 291318BABC39CF3011CA117623D6AD5CB6019A8A917188D51C3A64FE5819D248 | G5: 읽기 상태 | H5: TRUNCATED
A6: row_id | B6: policy | C6: candidate_id | D6: R_score_alpha | E6: R_score_beta | F6: R_score_gamma | G6: derived_policy_type | H6: rerank_k | I6: actor_rank | J6: actor_probability | K6: critic_q_min | L6: q_argmax_scope | M6: delta_R_score_alpha | N6: delta_R_score_beta | O6: delta_R_score_gamma
A7: 0 | B7: C0_noop | C7: A0_noop | D7: 80.762481 | E7: 71.550825 | F7: 75.110398 | M7: 0 | N7: 0 | O7: 0
A8: 0 | B8: C2_weakest_component_rule | C8: C2_weakest_component_rule | D8: 80.762481 | E8: 71.722516 | F8: 75.764506 | M8: 0 | N8: 0.17169084 | O8: 0.65410797
A9: 0 | B9: C3_candidate_iql | C9: DL2_deleverage_moderate | D9: 80.762481 | E9: 71.593999 | F9: 76.714897 | M9: 0 | N9: 0.043174564 | O9: 1.604499
A10: 0 | B10: CX1_capex_discipline | C10: CX1_capex_discipline | D10: 80.762481 | E10: 71.56929 | F10: 75.764506 | M10: 0 | N10: 0.018465438 | O10: 0.65410797
A11: 0 | B11: DL1_deleverage_mild | C11: DL1_deleverage_mild | D11: 80.762481 | E11: 71.573407 | F11: 75.51649 | M11: 0 | N11: 0.022581829 | O11: 0.40609248
A12: 0 | B12: DL2_deleverage_moderate | C12: DL2_deleverage_moderate | D12: 80.762481 | E12: 71.593999 | F12: 76.714897 | M12: 0 | N12: 0.043174564 | O12: 1.604499
A13: 0 | B13: MX1_cost_and_deleverage | C13: MX1_cost_and_deleverage | D13: 80.762481 | E13: 71.645509 | F13: 75.487351 | M13: 0 | N13: 0.094684156 | O13: 0.37695357
A14: 0 | B14: MX2_liquidity_rescue | C14: MX2_liquidity_rescue | D14: 80.762481 | E14: 71.569712 | F14: 75.764506 | M14: 0 | N14: 0.018887343 | O14: 0.65410797
A15: 0 | B15: OE1_cost_efficiency_mild | C15: OE1_cost_efficiency_mild | D15: 80.762481 | E15: 71.637147 | F15: 75.239489 | M15: 0 | N15: 0.086321614 | O15: 0.12909112
A16: 0 | B16: OE2_cost_efficiency_moderate | C16: OE2_cost_efficiency_moderate | D16: 80.762481 | E16: 71.722516 | F16: 75.764506 | M16: 0 | N16: 0.17169084 | O16: 0.65410797
A17: 0 | B17: RF1_short_debt_refinance | C17: RF1_short_debt_refinance | D17: 80.762481 | E17: 71.538728 | F17: 75.110398 | M17: 0 | N17: -0.012096635 | O17: 0
A18: 0 | B18: WC1_working_capital_tightening | C18: WC1_working_capital_tightening | D18: 80.762481 | E18: 71.570855 | F18: 75.764506 | M18: 0 | N18: 0.020030432 | O18: 0.65410797
... A256: 19 | B256: C3_candidate_iql | C256: MX2_liquidity_rescue | D256: 71.639402 | E256: 69.069917 | F256: 74.799192 | M256: 0.6696426 | N256: -0.0011766125 | O256: 0.57390508
A259: 입력 2: frozen_outputs/final_freeze/stage6_multi_oracle_eval/policy_paired_inference_alpha.csv
A260: 파일 크기(bytes) | B260: 64499 | C260: 생산 코드 | D260: src/credit_recourse/rl/pipelines/final_stage6_candidate_iql_multi_oracle_eval/pipeline.py | E260: SHA256 | F260: 42EED0A65F078518B7C6CCEFB8F2D5248DD6BD6C181B1569150159CC4BB355BF | G260: 읽기 상태 | H260: OK
A261: policy_a | B261: policy_b | C261: comparison | D261: n_pairs | E261: mean_diff | F261: median_diff | G261: cluster_se | H261: ci95_lo | I261: ci95_hi | J261: wilcoxon_W | K261: wilcoxon_p | L261: holm_adjusted_p
A262: C2_weakest_component_rule | B262: C0_noop | C262: policy_a_minus_policy_b | D262: 575 | E262: 0.50561586 | F262: 0.14214537 | G262: 0.031963424 | H262: 0.44452751 | I262: 0.56594422 | J262: 316 | K262: 2.8687058e-52 | L262: 8.6634917e-50
A263: C3_candidate_iql | B263: C0_noop | C263: policy_a_minus_policy_b | D263: 575 | E263: 0.63031255 | F263: 0.14214537 | G263: 0.039020557 | H263: 0.55560226 | I263: 0.70426204 | J263: 274.5 | K263: 6.3376685e-49 | L263: 1.8505992e-46
A264: C3_candidate_iql_q_argmax | B264: C0_noop | C264: policy_a_minus_policy_b | D264: 575 | E264: 0.49103939 | F264: 0 | G264: 0.036211647 | H264: 0.42229198 | I264: 0.56150642 | J264: 325 | K264: 5.2060946e-46 | L264: 1.4785309e-43
A265: C3_candidate_iql_q_rerank_at_3 | B265: C0_noop | C265: policy_a_minus_policy_b | D265: 575 | E265: 0.59293687 | F265: 0.14214537 | G265: 0.039921178 | H265: 0.51825961 | I265: 0.67199159 | J265: 303 | K265: 1.7624718e-50 | L265: 5.2874153e-48
A266: C3_candidate_iql_q_rerank_at_5 | B266: C0_noop | C266: policy_a_minus_policy_b | D266: 575 | E266: 0.54447179 | F266: 0.14214537 | G266: 0.039590222 | H266: 0.47347333 | I266: 0.62373631 | J266: 295 | K266: 3.5774015e-49 | L266: 1.0589108e-46
A267: C3_candidate_iql_q_rerank_at_7 | B267: C0_noop | C267: policy_a_minus_policy_b | D267: 575 | E267: 0.51225163 | F267: 0 | G267: 0.035206914 | H267: 0.44894083 | I267: 0.58187828 | J267: 292 | K267: 2.4357788e-47 | L267: 7.015043e-45
A268: C3_candidate_iql_q_rerank_at_9 | B268: C0_noop | C268: policy_a_minus_policy_b | D268: 575 | E268: 0.50993899 | F268: 0 | G268: 0.037046248 | H268: 0.44099994 | I268: 0.58225243 | J268: 289 | K268: 5.1196086e-47 | L268: 1.464208e-44
A269: CX1_capex_discipline | B269: C0_noop | C269: policy_a_minus_policy_b | D269: 575 | E269: 0.20018234 | F269: 0 | G269: 0.015150785 | H269: 0.16828525 | I269: 0.22970899 | J269: 0 | K269: 2.5191859e-30 | L269: 6.2475811e-28
A270: DL1_deleverage_mild | B270: C0_noop | C270: policy_a_minus_policy_b | D270: 575 | E270: 0.27808795 | F270: 0 | G270: 0.032125973 | H270: 0.21330402 | I270: 0.3399555 | J270: 148 | K270: 5.1734233e-23 | L270: 1.2105811e-20
A271: DL2_deleverage_moderate | B271: C0_noop | C271: policy_a_minus_policy_b | D271: 575 | E271: 0.51991642 | F271: 0 | G271: 0.041181675 | H271: 0.44260166 | I271: 0.59937671 | J271: 176 | K271: 6.0851372e-34 | L271: 1.6064762e-31
A272: MX1_cost_and_deleverage | B272: C0_noop | C272: policy_a_minus_policy_b | D272: 575 | E272: 0.50033695 | F272: 0.14214537 | G272: 0.034567219 | H272: 0.43688108 | I272: 0.56912134 | J272: 305 | K272: 1.798785e-50 | L272: 5.3603792e-48
A273: MX2_liquidity_rescue | B273: C0_noop | C273: policy_a_minus_policy_b | D273: 575 | E273: 0.60126837 | F273: 0.52620402 | G273: 0.032086962 | H273: 0.53560229 | I273: 0.65867352 | J273: 390 | K273: 1.0032672e-59 | L273: 3.0499322e-57
... A567: WC1_working_capital_tightening | B567: WC2_supplier_financing | C567: policy_a_minus_policy_b | D567: 575 | E567: -0.17269138 | F567: 0 | G567: 0.019838241 | H567: -0.21180559 | I567: -0.133243 | J567: 4560 | K567: 3.3358929e-16 | L567: 6.605068e-14
A570: 입력 3: frozen_outputs/final_freeze/stage6_multi_oracle_eval/policy_paired_inference_beta.csv
A571: 파일 크기(bytes) | B571: 70936 | C571: 생산 코드 | D571: src/credit_recourse/rl/pipelines/final_stage6_candidate_iql_multi_oracle_eval/pipeline.py | E571: SHA256 | F571: 7D3E3DC216700F63CC8A58B235A8F48C9118DA16CB51C904C17ED511923199DC | G571: 읽기 상태 | H571: OK
A572: policy_a | B572: policy_b | C572: comparison | D572: n_pairs | E572: mean_diff | F572: median_diff | G572: cluster_se | H572: ci95_lo | I572: ci95_hi | J572: wilcoxon_W | K572: wilcoxon_p | L572: holm_adjusted_p
A573: C2_weakest_component_rule | B573: C0_noop | C573: policy_a_minus_policy_b | D573: 575 | E573: 0.13483053 | F573: 0.12601525 | G573: 0.0041995312 | H573: 0.1268212 | I573: 0.14269013 | J573: 537 | K573: 7.5303646e-91 | L573: 1.9127126e-88
A574: C3_candidate_iql | B574: C0_noop | C574: policy_a_minus_policy_b | D574: 575 | E574: 0.07583031 | F574: 0.038370021 | G574: 0.0037390097 | H574: 0.068243345 | I574: 0.083152109 | J574: 1925 | K574: 1.8229094e-77 | L574: 4.0104006e-75
A575: C3_candidate_iql_q_argmax | B575: C0_noop | C575: policy_a_minus_policy_b | D575: 575 | E575: 0.052867882 | F575: 0.024252622 | G575: 0.0032195769 | H575: 0.04729078 | I575: 0.059790288 | J575: 5511 | K575: 4.1258085e-75 | L575: 8.7467139e-73
...

Sheet CALCULATION
A1: T4-5 · 분석 과정
A2: 필터·분석단위와 실제 계산 결과입니다. 수치 셀은 SOURCE를 직접 참조합니다.
A4: 항목 | B4: 내용
A5: 계산 방법 | B5: 같은 기업의 행동 후 Oracle 점수에서 그 기업의 무행동 Oracle 점수를 뺀 뒤 기업 단위로 집계
A6: 생산 코드 | B6: src/credit_recourse/rl/pipelines/final_stage6_candidate_iql_multi_oracle_eval/pipeline.py
A7: 선택 실행 | B7: V11_FINAL_FROZEN_REPLAY_RESUME
A11: 이 표·그림과 연결된 본문 핵심 수치
A12: 수치 ID | B12: 본문 주장 | C12: 논문 표시값 | D12: 재계산값 | E12: 확인 결과 | F12: 계산식 | G12: 실제 입력 산출물
A13: NC0127-01 | B13: Candidate-IQL의 무행동 대비 정책가치는 Oracle-α에서 +0.630, β에서 +0.076, γ에서 +0.595였으며 세 Oracle에서 모두 유의하였다. 휴리스틱과 비교한 C3−C2는 α에서 +0.125였지만 유의하지 않았고, β에서는 −0.059, γ에서는 +0.193이었다. Candidate-IQL은 세 Oracle에서 모두 무행동보다 높은 정책가치를 보였지만, 휴리스틱보다 항상 높은 정책가치를 보인 것은 아니다. 따라서 Candidate-IQL은 최고 성능의 정책이 아니라 LLM 정책과 비교하기 위한 기준정책으로 사용한다. | C13: +0.630 | D13: 0.63 | E13: 논문값과 일치 | F13: MEAN_i(R_score_alpha(action_i) - R_score_alpha(noop_i)) | G13: frozen_outputs/final_freeze/stage6_multi_oracle_eval/final_policy_summary.csv
A14: NC0127-02 | B14: Candidate-IQL의 무행동 대비 정책가치는 Oracle-α에서 +0.630, β에서 +0.076, γ에서 +0.595였으며 세 Oracle에서 모두 유의하였다. 휴리스틱과 비교한 C3−C2는 α에서 +0.125였지만 유의하지 않았고, β에서는 −0.059, γ에서는 +0.193이었다. Candidate-IQL은 세 Oracle에서 모두 무행동보다 높은 정책가치를 보였지만, 휴리스틱보다 항상 높은 정책가치를 보인 것은 아니다. 따라서 Candidate-IQL은 최고 성능의 정책이 아니라 LLM 정책과 비교하기 위한 기준정책으로 사용한다. | C14: +0.076 | D14: 0.076 | E14: 논문값과 일치 | F14: MEAN_i(R_score_beta(action_i) - R_score_beta(noop_i)) | G14: frozen_outputs/final_freeze/stage6_multi_oracle_eval/final_policy_summary.csv
A15: NC0127-03 | B15: Candidate-IQL의 무행동 대비 정책가치는 Oracle-α에서 +0.630, β에서 +0.076, γ에서 +0.595였으며 세 Oracle에서 모두 유의하였다. 휴리스틱과 비교한 C3−C2는 α에서 +0.125였지만 유의하지 않았고, β에서는 −0.059, γ에서는 +0.193이었다. Candidate-IQL은 세 Oracle에서 모두 무행동보다 높은 정책가치를 보였지만, 휴리스틱보다 항상 높은 정책가치를 보인 것은 아니다. 따라서 Candidate-IQL은 최고 성능의 정책이 아니라 LLM 정책과 비교하기 위한 기준정책으로 사용한다. | C15: +0.595 | D15: 0.595 | E15: 논문값과 일치 | F15: MEAN_i(R_score_gamma(action_i) - R_score_gamma(noop_i)) | G15: frozen_outputs/final_freeze/stage6_multi_oracle_eval/final_policy_summary.csv
A16: NC0127-04 | B16: Candidate-IQL의 무행동 대비 정책가치는 Oracle-α에서 +0.630, β에서 +0.076, γ에서 +0.595였으며 세 Oracle에서 모두 유의하였다. 휴리스틱과 비교한 C3−C2는 α에서 +0.125였지만 유의하지 않았고, β에서는 −0.059, γ에서는 +0.193이었다. Candidate-IQL은 세 Oracle에서 모두 무행동보다 높은 정책가치를 보였지만, 휴리스틱보다 항상 높은 정책가치를 보인 것은 아니다. 따라서 Candidate-IQL은 최고 성능의 정책이 아니라 LLM 정책과 비교하기 위한 기준정책으로 사용한다. | C16: +0.125 | D16: 0.125 | E16: 논문값과 일치 | F16: 575개 동일 기업 각각에서 Candidate-IQL 정책가치에서 최약요인 휴리스틱 정책가치를 뺀 뒤 평균 (alpha); 선택 실행 Stage6의 575개 기업 행을 row_id로 직접 대응해 재계산 | G16: frozen_outputs/final_freeze/stage6_candidate_selector_eval/multi_oracle_policy_eval.parquet embedded://thesis-output-calculation/derived/reviewer_core_direct_calculations.csv
A17: NC0127-05 | B17: Candidate-IQL의 무행동 대비 정책가치는 Oracle-α에서 +0.630, β에서 +0.076, γ에서 +0.595였으며 세 Oracle에서 모두 유의하였다. 휴리스틱과 비교한 C3−C2는 α에서 +0.125였지만 유의하지 않았고, β에서는 −0.059, γ에서는 +0.193이었다. Candidate-IQL은 세 Oracle에서 모두 무행동보다 높은 정책가치를 보였지만, 휴리스틱보다 항상 높은 정책가치를 보인 것은 아니다. 따라서 Candidate-IQL은 최고 성능의 정책이 아니라 LLM 정책과 비교하기 위한 기준정책으로 사용한다. | C17: −0.059 | D17: -0.059 | E17: 논문값과 일치 | F17: 575개 동일 기업 각각에서 Candidate-IQL 정책가치에서 최약요인 휴리스틱 정책가치를 뺀 뒤 평균 (beta); 선택 실행 Stage6의 575개 기업 행을 row_id로 직접 대응해 재계산 | G17: frozen_outputs/final_freeze/stage6_candidate_selector_eval/multi_oracle_policy_eval.parquet embedded://thesis-output-calculation/derived/reviewer_core_direct_calculations.csv
A18: NC0127-06 | B18: Candidate-IQL의 무행동 대비 정책가치는 Oracle-α에서 +0.630, β에서 +0.076, γ에서 +0.595였으며 세 Oracle에서 모두 유의하였다. 휴리스틱과 비교한 C3−C2는 α에서 +0.125였지만 유의하지 않았고, β에서는 −0.059, γ에서는 +0.193이었다. Candidate-IQL은 세 Oracle에서 모두 무행동보다 높은 정책가치를 보였지만, 휴리스틱보다 항상 높은 정책가치를 보인 것은 아니다. 따라서 Candidate-IQL은 최고 성능의 정책이 아니라 LLM 정책과 비교하기 위한 기준정책으로 사용한다. | C18: +0.193 | D18: 0.193 | E18: 논문값과 일치 | F18: 575개 동일 기업 각각에서 Candidate-IQL 정책가치에서 최약요인 휴리스틱 정책가치를 뺀 뒤 평균 (gamma); 선택 실행 Stage6의 575개 기업 행을 row_id로 직접 대응해 재계산 | G18: frozen_outputs/final_freeze/stage6_candidate_selector_eval/multi_oracle_policy_eval.parquet embedded://thesis-output-calculation/derived/reviewer_core_direct_calculations.csv
A21: 동일기업 정책가치 계산
A22: 입력 산출물 | B22: 기업 행 수 | C22: 결합 방식 | D22: 정책가치 정의
A23: frozen_outputs/final_freeze/stage6_candidate_selector_eval/multi_oracle_policy_eval.parquet | B23: 10350 | C23: ROW_ID_TO_UNIQUE_NOOP_POLICY_JOIN | D23: 동일기업 행동 점수 − 동일기업 무행동 점수
A26: 계산 데이터: stage6_paired_inference
A27: 입력 파일 | B27: data/final_freeze/stage6_multi_oracle_eval/policy_paired_inference_alpha.csv; data/final_freeze/stage6_multi_oracle_eval/policy_paired_inference_beta.csv; data/final_freeze/stage6_multi_oracle_eval/policy_paired_inference_gamma.csv
A28: 선택 조건 | B28: [{"column": "policy_a", "op": "equals", "value": "C3_candidate_iql"}, {"column": "policy_b", "op": "in", "values": ["C0_noop", "C2_weakest_component_rule"]}]
A29: 분석 단위 | B29: source_file; policy_a; policy_b
A30: 집계 | B30: PRODUCER_MEAN_AFTER_SAME_FIRM_PAIRING_VERIFIED
A31: source_file | B31: policy_a | C31: policy_b | D31: n_pairs | E31: mean_diff | F31: cluster_se | G31: ci95_lo | H31: ci95_hi | I31: wilcoxon_p | J31: holm_adjusted_p
A32: data/final_freeze/stage6_multi_oracle_eval/policy_paired_inference_alpha.csv | B32: ='SOURCE'!A263 | C32: ='SOURCE'!B263 | D32: ='SOURCE'!D263 | E32: ='SOURCE'!E263 | F32: ='SOURCE'!G263 | G32: ='SOURCE'!H263 | H32: ='SOURCE'!I263 | I32: ='SOURCE'!K263 | J32: ='SOURCE'!L263
A33: data/final_freeze/stage6_multi_oracle_eval/policy_paired_inference_alpha.csv | B33: ='SOURCE'!A280 | C33: ='SOURCE'!B280 | D33: ='SOURCE'!D280 | E33: ='SOURCE'!E280 | F33: ='SOURCE'!G280 | G33: ='SOURCE'!H280 | H33: ='SOURCE'!I280 | I33: ='SOURCE'!K280 | J33: ='SOURCE'!L280
A34: data/final_freeze/stage6_multi_oracle_eval/policy_paired_inference_beta.csv | B34: ='SOURCE'!A574 | C34: ='SOURCE'!B574 | D34: ='SOURCE'!D574 | E34: ='SOURCE'!E574 | F34: ='SOURCE'!G574 | G34: ='SOURCE'!H574 | H34: ='SOURCE'!I574 | I34: ='SOURCE'!K574 | J34: ='SOURCE'!L574
A35: data/final_freeze/stage6_multi_oracle_eval/policy_paired_inference_beta.csv | B35: ='SOURCE'!A591 | C35: ='SOURCE'!B591 | D35: ='SOURCE'!D591 | E35: ='SOURCE'!E591 | F35: ='SOURCE'!G591 | G35: ='SOURCE'!H591 | H35: ='SOURCE'!I591 | I35: ='SOURCE'!K591 | J35: ='SOURCE'!L591
A36: data/final_freeze/stage6_multi_oracle_eval/policy_paired_inference_gamma.csv | B36: ='SOURCE'!A885 | C36: ='SOURCE'!B885 | D36: ='SOURCE'!D885 | E36: ='SOURCE'!E885 | F36: ='SOURCE'!G885 | G36: ='SOURCE'!H885 | H36: ='SOURCE'!I885 | I36: ='SOURCE'!K885 | J36: ='SOURCE'!L885
A37: data/final_freeze/stage6_multi_oracle_eval/policy_paired_inference_gamma.csv | B37: ='SOURCE'!A902 | C37: ='SOURCE'!B902 | D37: ='SOURCE'!D902 | E37: ='SOURCE'!E902 | F37: ='SOURCE'!G902 | G37: ='SOURCE'!H902 | H37: ='SOURCE'!I902 | I37: ='SOURCE'!K902 | J37: ='SOURCE'!L902

Sheet PAPER_TABLE
A1: T4-5 · 논문 표 작업용 결과
A2: ANALYSIS에서 계산된 값만 연결한 최종 작업표입니다. Excel에서 정렬·피벗·표시형식만 조정하면 됩니다.
A4: 계산 결과: stage6_paired_inference
A5: ='CALCULATION'!A31 | B5: ='CALCULATION'!B31 | C5: ='CALCULATION'!C31 | D5: ='CALCULATION'!D31 | E5: ='CALCULATION'!E31 | F5: ='CALCULATION'!F31 | G5: ='CALCULATION'!G31 | H5: ='CALCULATION'!H31 | ... J5: ='CALCULATION'!J31
A6: ='CALCULATION'!A32 | B6: ='CALCULATION'!B32 | C6: ='CALCULATION'!C32 | D6: ='CALCULATION'!D32 | E6: ='CALCULATION'!E32 | F6: ='CALCULATION'!F32 | G6: ='CALCULATION'!G32 | H6: ='CALCULATION'!H32 | ... J6: ='CALCULATION'!J32
A7: ='CALCULATION'!A33 | B7: ='CALCULATION'!B33 | C7: ='CALCULATION'!C33 | D7: ='CALCULATION'!D33 | E7: ='CALCULATION'!E33 | F7: ='CALCULATION'!F33 | G7: ='CALCULATION'!G33 | H7: ='CALCULATION'!H33 | ... J7: ='CALCULATION'!J33
A8: ='CALCULATION'!A34 | B8: ='CALCULATION'!B34 | C8: ='CALCULATION'!C34 | D8: ='CALCULATION'!D34 | E8: ='CALCULATION'!E34 | F8: ='CALCULATION'!F34 | G8: ='CALCULATION'!G34 | H8: ='CALCULATION'!H34 | ... J8: ='CALCULATION'!J34
A9: ='CALCULATION'!A35 | B9: ='CALCULATION'!B35 | C9: ='CALCULATION'!C35 | D9: ='CALCULATION'!D35 | E9: ='CALCULATION'!E35 | F9: ='CALCULATION'!F35 | G9: ='CALCULATION'!G35 | H9: ='CALCULATION'!H35 | ... J9: ='CALCULATION'!J35
A10: ='CALCULATION'!A36 | B10: ='CALCULATION'!B36 | C10: ='CALCULATION'!C36 | D10: ='CALCULATION'!D36 | E10: ='CALCULATION'!E36 | F10: ='CALCULATION'!F36 | G10: ='CALCULATION'!G36 | H10: ='CALCULATION'!H36 | ... J10: ='CALCULATION'!J36
A11: ='CALCULATION'!A37 | B11: ='CALCULATION'!B37 | C11: ='CALCULATION'!C37 | D11: ='CALCULATION'!D37 | E11: ='CALCULATION'!E37 | F11: ='CALCULATION'!F37 | G11: ='CALCULATION'!G37 | H11: ='CALCULATION'!H37 | ... J11: ='CALCULATION'!J37
