Workbook

Sheet README
A1: F4 · 그림 4. Oracle별 표준행동 선호 양상
A2: 논문 인쇄값을 계산 입력으로 쓰지 않고, 선택 실행의 실제 산출물에서 값을 계산한 Excel입니다.
A4: 항목 | B4: 내용
A5: 선택 실행 | B5: V11_FINAL_FROZEN_REPLAY_RESUME
A6: 실행 방식 | B6: FrozenReplay
A7: 논문 항목 읽기 | B7: 논문 DOCX에서 번호·제목·위치만 동적으로 읽음
A8: 논문 위치 | B8: 4.3 Oracle별 정책행동의 신용평점 차이와 동률 · 인쇄면 49
A9: 관측·집계 단위 | B9: json_path; policy
A10: 선택 조건 | B10: [[{"column": "json_path", "op": "equals", "value": "per_backend.alpha.oracle_best_mean_noop_adjusted_score"}]]
A11: 계산 방법 | B11: 같은 기업의 행동 후 Oracle 점수에서 그 기업의 무행동 Oracle 점수를 뺀 뒤 기업 단위로 집계
A12: 생산 코드 | B12: src/credit_recourse/rl/pipelines/final_stage6_candidate_iql_multi_oracle_eval/pipeline.py
A13: 실제 입력 산출물 | B13: frozen_outputs/final_freeze/stage6_candidate_selector_eval/multi_oracle_policy_eval.parquet frozen_outputs/final_freeze/stage6_multi_oracle_eval/iql_q_rerank_candidate_distribution.csv frozen_outputs/final_freeze/stage6_multi_oracle_eval/summary_by_policy_alpha.csv frozen_outputs/final_freeze/stage6_multi_oracle_eval/summary_by_policy_beta.csv frozen_outputs/final_freeze/stage6_multi_oracle_eval/summary_by_policy_gamma.csv frozen_outputs/final_freeze/stage6_multi_oracle_eval/final_policy_summary.csv frozen_outputs/final_freeze/stage6_candidate_selector_eval/derived_comparators_runtime.json

Sheet SOURCE
A1: F4 · 실제 입력 산출물
A2: 선택 실행에서 읽은 실제 중간·최종 산출물입니다. 아래 ANALYSIS가 이 셀들을 직접 참조합니다.
A4: 입력 1: frozen_outputs/final_freeze/stage6_candidate_selector_eval/multi_oracle_policy_eval.parquet
A5: 파일 크기(bytes) | B5: 246988 | C5: 생산 코드 | D5: src/credit_recourse/rl/pipelines/final_stage6_candidate_iql_multi_oracle_eval/pipeline.py | E5: SHA256 | F5: 291318BABC39CF3011CA117623D6AD5CB6019A8A917188D51C3A64FE5819D248 | G5: 읽기 상태 | H5: TRUNCATED
A6: row_id | B6: policy | C6: candidate_id | D6: R_score_alpha | E6: R_score_beta | F6: R_score_gamma | G6: derived_policy_type | H6: rerank_k | I6: actor_rank | J6: actor_probability | K6: critic_q_min | L6: q_argmax_scope | M6: delta_R_score_alpha | N6: delta_R_score_beta | O6: delta_R_score_gamma
A7: 0 | B7: C0_noop | C7: A0_noop | D7: 80.762481 | E7: 71.550825 | F7: 75.110398 | M7: 0 | N7: 0 | O7: 0
A8: 0 | B8: C2_weakest_component_rule | C8: C2_weakest_component_rule | D8: 80.762481 | E8: 71.722516 | F8: 75.764506 | M8: 0 | N8: 0.17169084 | O8: 0.65410797
A9: 0 | B9: C3_candidate_iql | C9: DL2_deleverage_moderate | D9: 80.762481 | E9: 71.593999 | F9: 76.714897 | M9: 0 | N9: 0.043174564 | O9: 1.604499
A10: 0 | B10: CX1_capex_discipline | C10: CX1_capex_discipline | D10: 80.762481 | E10: 71.56929 | F10: 75.764506 | M10: 0 | N10: 0.018465438 | O10: 0.65410797
A11: 0 | B11: DL1_deleverage_mild | C11: DL1_deleverage_mild | D11: 80.762481 | E11: 71.573407 | F11: 75.51649 | M11: 0 | N11: 0.022581829 | O11: 0.40609248
A12: 0 | B12: DL2_deleverage_moderate | C12: DL2_deleverage_moderate | D12: 80.762481 | E12: 71.593999 | F12: 76.714897 | M12: 0 | N12: 0.043174564 | O12: 1.604499
A13: 0 | B13: MX1_cost_and_deleverage | C13: MX1_cost_and_deleverage | D13: 80.762481 | E13: 71.645509 | F13: 75.487351 | M13: 0 | N13: 0.094684156 | O13: 0.37695357
A14: 0 | B14: MX2_liquidity_rescue | C14: MX2_liquidity_rescue | D14: 80.762481 | E14: 71.569712 | F14: 75.764506 | M14: 0 | N14: 0.018887343 | O14: 0.65410797
A15: 0 | B15: OE1_cost_efficiency_mild | C15: OE1_cost_efficiency_mild | D15: 80.762481 | E15: 71.637147 | F15: 75.239489 | M15: 0 | N15: 0.086321614 | O15: 0.12909112
A16: 0 | B16: OE2_cost_efficiency_moderate | C16: OE2_cost_efficiency_moderate | D16: 80.762481 | E16: 71.722516 | F16: 75.764506 | M16: 0 | N16: 0.17169084 | O16: 0.65410797
A17: 0 | B17: RF1_short_debt_refinance | C17: RF1_short_debt_refinance | D17: 80.762481 | E17: 71.538728 | F17: 75.110398 | M17: 0 | N17: -0.012096635 | O17: 0
A18: 0 | B18: WC1_working_capital_tightening | C18: WC1_working_capital_tightening | D18: 80.762481 | E18: 71.570855 | F18: 75.764506 | M18: 0 | N18: 0.020030432 | O18: 0.65410797
... A256: 19 | B256: C3_candidate_iql | C256: MX2_liquidity_rescue | D256: 71.639402 | E256: 69.069917 | F256: 74.799192 | M256: 0.6696426 | N256: -0.0011766125 | O256: 0.57390508
A259: 입력 2: frozen_outputs/final_freeze/stage6_multi_oracle_eval/iql_q_rerank_candidate_distribution.csv
A260: 파일 크기(bytes) | B260: 2567 | C260: 생산 코드 | D260: src/credit_recourse/rl/pipelines/final_stage6_candidate_iql_multi_oracle_eval/pipeline.py | E260: SHA256 | F260: C4F6D040EF0A23B46A2CE16FF03DF3B727899FE273D5D42186AE0836903EFE05 | G260: 읽기 상태 | H260: OK
A261: policy | B261: candidate_id | C261: count
A262: C3_candidate_iql_q_rerank_at_3 | B262: DL2_deleverage_moderate | C262: 219
A263: C3_candidate_iql_q_rerank_at_3 | B263: WC1_working_capital_tightening | C263: 130
A264: C3_candidate_iql_q_rerank_at_3 | B264: OE2_cost_efficiency_moderate | C264: 104
A265: C3_candidate_iql_q_rerank_at_3 | B265: MX2_liquidity_rescue | C265: 52
A266: C3_candidate_iql_q_rerank_at_3 | B266: MX1_cost_and_deleverage | C266: 49
A267: C3_candidate_iql_q_rerank_at_3 | B267: A0_noop | C267: 8
A268: C3_candidate_iql_q_rerank_at_3 | B268: RF1_short_debt_refinance | C268: 5
A269: C3_candidate_iql_q_rerank_at_3 | B269: WC2_supplier_financing | C269: 3
A270: C3_candidate_iql_q_rerank_at_3 | B270: CX1_capex_discipline | C270: 2
A271: C3_candidate_iql_q_rerank_at_3 | B271: OE1_cost_efficiency_mild | C271: 2
A272: C3_candidate_iql_q_rerank_at_3 | B272: DL1_deleverage_mild | C272: 1
A273: C3_candidate_iql_q_rerank_at_5 | B273: DL2_deleverage_moderate | C273: 182
... A305: C3_candidate_iql_q_rerank_at_9 | B305: OE1_cost_efficiency_mild | C305: 7
A308: 입력 3: frozen_outputs/final_freeze/stage6_multi_oracle_eval/summary_by_policy_alpha.csv
A309: 파일 크기(bytes) | B309: 1532 | C309: 생산 코드 | D309: src/credit_recourse/rl/pipelines/final_stage6_candidate_iql_multi_oracle_eval/pipeline.py | E309: SHA256 | F309: B00CD717633BCDA601A233469069FB67B3B04852EC8ED5036FB2E4E7260398F0 | G309: 읽기 상태 | H309: OK
A310: policy | B310: count | C310: mean | D310: median | E310: std
A311: C0_noop | B311: 575 | C311: 68.758255 | D311: 69.677193 | E311: 7.876943
A312: C2_weakest_component_rule | B312: 575 | C312: 69.26387 | D312: 70.10155 | E312: 7.9268328
A313: C3_candidate_iql | B313: 575 | C313: 69.388567 | D313: 70.145398 | E313: 7.834502
...

Sheet CHART_DATA
A1: F4 · 그림 데이터
A2: 실제 실행 산출물과 연결된 데이터입니다. 차트는 이 시트의 값을 참조하므로 Excel에서 직접 편집할 수 있습니다.
A4: policy | B4: mean_delta_R_score_alpha | C4: mean_delta_R_score_beta | D4: mean_delta_R_score_gamma
A5: ='SOURCE'!A380 | B5: ='SOURCE'!F380 | C5: ='SOURCE'!J380 | D5: ='SOURCE'!N380
A6: ='SOURCE'!A381 | B6: ='SOURCE'!F381 | C6: ='SOURCE'!J381 | D6: ='SOURCE'!N381
A7: ='SOURCE'!A382 | B7: ='SOURCE'!F382 | C7: ='SOURCE'!J382 | D7: ='SOURCE'!N382
A8: ='SOURCE'!A383 | B8: ='SOURCE'!F383 | C8: ='SOURCE'!J383 | D8: ='SOURCE'!N383
A9: ='SOURCE'!A384 | B9: ='SOURCE'!F384 | C9: ='SOURCE'!J384 | D9: ='SOURCE'!N384
A10: ='SOURCE'!A385 | B10: ='SOURCE'!F385 | C10: ='SOURCE'!J385 | D10: ='SOURCE'!N385
A11: ='SOURCE'!A386 | B11: ='SOURCE'!F386 | C11: ='SOURCE'!J386 | D11: ='SOURCE'!N386
A12: ='SOURCE'!A387 | B12: ='SOURCE'!F387 | C12: ='SOURCE'!J387 | D12: ='SOURCE'!N387
A13: ='SOURCE'!A388 | B13: ='SOURCE'!F388 | C13: ='SOURCE'!J388 | D13: ='SOURCE'!N388
A14: ='SOURCE'!A389 | B14: ='SOURCE'!F389 | C14: ='SOURCE'!J389 | D14: ='SOURCE'!N389
A15: ='SOURCE'!A390 | B15: ='SOURCE'!F390 | C15: ='SOURCE'!J390 | D15: ='SOURCE'!N390
A16: ='SOURCE'!A391 | B16: ='SOURCE'!F391 | C16: ='SOURCE'!J391 | D16: ='SOURCE'!N391
... A22: ='SOURCE'!A397 | B22: ='SOURCE'!F397 | C22: ='SOURCE'!J397 | D22: ='SOURCE'!N397

Sheet CHART
A1: F4 · 그림 4. Oracle별 표준행동 선호 양상
A2: CHART_DATA를 참조하는 편집 가능한 Excel 차트입니다.
