Workbook

Sheet README
A1: F7 · 그림 7. 기업별 연결·행동크기·재무항목 조합에 따른 정책가치(IC-b, Oracle-α)
A2: 논문 인쇄값을 계산 입력으로 쓰지 않고, 선택 실행의 실제 산출물에서 값을 계산한 Excel입니다.
A4: 항목 | B4: 내용
A5: 선택 실행 | B5: V11_FINAL_FROZEN_REPLAY_RESUME
A6: 실행 방식 | B6: FrozenReplay
A7: 논문 항목 읽기 | B7: 논문 DOCX에서 번호·제목·위치만 동적으로 읽음
A8: 논문 위치 | B8: 6.2 자유작성 우위의 출처 분석 · 인쇄면 70
A9: 관측·집계 단위 | B9: policy + mode; policy + mode + oracle_backend + shuffle_within; source_file + policy + mode
A10: 선택 조건 | B10: [[{"column": "policy", "op": "in", "values": ["C4", "C6"]}], [{"column": "policy", "op": "equals", "value": "C6"}, {"column": "mode", "op": "equals", "value": "free_form_10d"}], [{"column": "policy", "op": "equals", "value": "C6"}, {"column": "mode", "op": "equals", "value": "free_form_10d"}, {"column": "oracle_backend", "op": "equals", "value": "alpha"}, {"column": "shuffle_within", "op": "equals", "value": "none"}], [{"column": "policy", "op": "equals", "value": "C6"}, {"column": "mode", "op": "equals", "value": "free_form_10d"}], [{"column": "policy", "op": "equals", "value": "C6"}, {"column": "mode", "op": "equals", "value": "free_form_10d"}]]
A11: 계산 방법 | B11: 같은 기업의 행동 후 Oracle 점수에서 그 기업의 무행동 Oracle 점수를 뺀 뒤 기업 단위로 집계
A12: 생산 코드 | B12: src/credit_recourse/analysis/llm_action_budget_ablation.py
A13: 실제 입력 산출물 | B13: frozen_outputs/analysis/paper_repro/03_output_contract_diagnostics/ablation/IC-a/ICa_gpt54mini_p50_live_seed1/global_mean_vector_null_native/ablation_policy_summary.csv frozen_outputs/analysis/paper_repro/03_output_contract_diagnostics/ablation/IC-a/ICa_gpt54mini_p50_live_seed1/global_mean_vector_null_same_policy_candidate_mean/ablation_policy_summary.csv frozen_outputs/analysis/paper_repro/03_output_contract_diagnostics/ablation/IC-a/ICa_gpt54mini_p50_live_seed1/l1_rescale_same_policy_candidate_mean/ablation_policy_summary.csv frozen_outputs/analysis/paper_repro/03_output_contract_diagnostics/ablation/IC-a/ICa_gpt54mini_p50_live_seed1/nearest_candidate_projection_native/ablation_policy_summary.csv frozen_outputs/analysis/paper_repro/03_output_contract_diagnostics/ablation/IC-a/ICa_gpt54mini_p50_live_seed1/row_shuffle_vector_null_native/ablation_policy_summary.csv frozen_outputs/analysis/paper_repro/03_output_contract_diagnostics/ablation/IC-a/ICa_gpt54mini_p50_live_seed1/row_shuffle_vector_null_native_industry/ablation_policy_summary.csv frozen_outputs/analysis/paper_repro/03_output_contract_diagnostics/ablation/IC-a/ICa_gpt54mini_p50_live_seed1/row_shuffle_vector_null_native_rating_band/ablation_policy_summary.csv frozen_outputs/analysis/paper_repro/03_output_contract_diagnostics/ablation/IC-a/ICa_gpt54mini_p50_live_seed1/row_shuffle_vector_null_same_policy_candidate_mean/ablation_policy_summary.csv frozen_outputs/analysis/paper_repro/03_output_contract_diagnostics/ablation/IC-b/ICb_gpt54mini_p50_live_seed1/global_mean_vector_null_native/ablation_policy_summary.csv frozen_outputs/analysis/paper_repro/03_output_contract_diagnostics/ablation/IC-b/ICb_gpt54mini_p50_live_seed1/global_mean_vector_null_same_policy_candidate_mean/ablation_policy_summary.csv frozen_outputs/analysis/paper_repro/03_output_contract_diagnostics/ablation/IC-b/ICb_gpt54mini_p50_live_seed1/l1_rescale_same_policy_candidate_mean/ablation_policy_summary.csv frozen_outputs/analysis/paper_repro/03_output_contract_diagnostics/ablation/IC-b/ICb_gpt54mini_p50_live_seed1/nearest_candidate_projection_native/ablation_policy_summary.csv frozen_outputs/analysis/paper_repro/03_output_contract_diagnostics/ablation/IC-b/ICb_gpt54mini_p50_live_seed1/row_shuffle_vector_null_native/ablation_policy_summary.csv frozen_outputs/analysis/paper_repro/03_output_contract_diagnostics/ablation/IC-b/ICb_gpt54mini_p50_live_seed1/row_shuffle_vector_null_native_industry/ablation_policy_summary.csv frozen_outputs/analysis/paper_repro/03_output_contract_diagnostics/ablation/IC-b/ICb_gpt54mini_p50_live_seed1/row_shuffle_vector_null_native_rating_band/ablation_policy_summary.csv frozen_outputs/analysis/paper_repro/03_output_contract_diagnostics/ablation/IC-b/ICb_gpt54mini_p50_live_seed1/row_shuffle_vector_null_same_policy_candidate_mean/ablation_policy_summary.csv frozen_outputs/analysis/paper_repro/03_output_contract_diagnostics/ablation/IC-c/ICc_gpt54mini_p50_live_seed1/global_mean_vector_null_native/ablation_policy_summary.csv frozen_outputs/analysis/paper_repro/03_output_contract_diagnostics/ablation/IC-c/ICc_gpt54mini_p50_live_seed1/global_mean_vector_null_same_policy_candidate_mean/ablation_policy_summary.csv frozen_outputs/analysis/paper_repro/03_output_contract_diagnostics/ablation/IC-c/ICc_gpt54mini_p50_live_seed1/l1_rescale_same_policy_candidate_mean/ablation_policy_summary.csv frozen_outputs/analysis/paper_repro/03_output_contract_diagnostics/ablation/IC-c/ICc_gpt54mini_p50_live_seed1/nearest_candidate_projection_native/ablation_policy_summary.csv frozen_outputs/analysis/paper_repro/03_output_contract_diagnostics/ablation/IC-c/ICc_gpt54mini_p50_live_seed1/row_shuffle_vector_null_native/ablation_policy_summary.csv frozen_outputs/analysis/paper_repro/03_output_contract_diagnostics/ablation/IC-c/ICc_gpt54mini_p50_live_seed1/row_shuffle_vector_null_native_industry/ablation_policy_summary.csv frozen_outputs/analysis/paper_repro/03_output_contract_diagnostics/ablation/IC-c/ICc_gpt54mini_p50_live_seed1/row_shuffle_vector_null_native_rating_band/ablation_policy_summary.csv frozen_outputs/analysis/paper_repro/03_output_contract_diagnostics/ablation/IC-c/ICc_gpt54mini_p50_live_seed1/row_shuffle_vector_null_same_policy_candidate_mean/ablation_policy_summary.csv frozen_outputs/analysis/paper_repro/03_output_contract_diagnostics/ablation/IC-a/ICa_gpt54mini_p50_live_seed1/row_shuffle_vector_null_native/shuffle_permutation_ci.csv frozen_outputs/analysis/paper_repro/03_output_contract_diagnostics/ablation/IC-a/ICa_gpt54mini_p50_live_seed1/row_shuffle_vector_null_native_industry/shuffle_permutation_ci.csv frozen_outputs/analysis/paper_repro/03_output_contract_diagnostics/ablation/IC-a/ICa_gpt54mini_p50_live_seed1/row_shuffle_vector_null_native_rating_band/shuffle_permutation_ci.csv frozen_outputs/analysis/paper_repro/03_output_contract_diagnostics/ablation/IC-b/ICb_gpt54mini_p50_live_seed1/row_shuffle_vector_null_native/shuffle_permutation_ci.csv frozen_outputs/analysis/paper_repro/03_output_contract_diagnostics/ablation/IC-b/ICb_gpt54mini_p50_live_seed1/row_shuffle_vector_null_native_industry/shuffle_permutation_ci.csv frozen_outputs/analysis/paper_repro/03_output_contract_diagnostics/ablation/IC-b/ICb_gpt54mini_p50_live_seed1/row_shuffle_vector_null_native_rating_band/shuffle_permutation_ci.csv frozen_outputs/analysis/paper_repro/03_output_contract_diagnostics/ablation/IC-c/ICc_gpt54mini_p50_live_seed1/row_shuffle_vector_null_native/shuffle_permutation_ci.csv frozen_outputs/analysis/paper_repro/03_output_contract_diagnostics/ablation/IC-c/ICc_gpt54mini_p50_live_seed1/row_shuffle_vector_null_native_industry/shuffle_permutation_ci.csv frozen_outputs/analysis/paper_repro/03_output_contract_diagnostics/ablation/IC-c/ICc_gpt54mini_p50_live_seed1/row_shuffle_vector_null_native_rating_band/shuffle_permutation_ci.csv

Sheet SOURCE
A1: F7 · 실제 입력 산출물
A2: 선택 실행에서 읽은 실제 중간·최종 산출물입니다. 아래 ANALYSIS가 이 셀들을 직접 참조합니다.
A4: 입력 1: frozen_outputs/analysis/paper_repro/03_output_contract_diagnostics/ablation/IC-a/ICa_gpt54mini_p50_live_seed1/global_mean_vector_null_native/ablation_policy_summary.csv
A5: 파일 크기(bytes) | B5: 2782 | C5: 생산 코드 | D5: src/credit_recourse/analysis/llm_action_budget_ablation.py | E5: SHA256 | F5: 985D961B439EA796BA8A4D1E48F65135B53F9C6A543319B3A002AE6BDB267864 | G5: 읽기 상태 | H5: OK
A6: policy | B6: mode | C6: n_rows | D6: mean_delta_R_score_alpha | E6: median_delta_R_score_alpha | F6: positive_fraction_alpha | G6: valid_fraction_alpha | H6: mean_delta_R_score_beta | I6: median_delta_R_score_beta | J6: positive_fraction_beta | K6: valid_fraction_beta | L6: mean_delta_R_score_gamma | M6: median_delta_R_score_gamma | N6: positive_fraction_gamma | O6: valid_fraction_gamma
A7: C4 | B7: candidate_selection | C7: 575 | D7: 0.5203648 | E7: 0.19649361 | F7: 0.56869565 | G7: 1 | H7: 0.1050754 | I7: 0.083211833 | J7: 0.91478261 | K7: 1 | L7: 0.38433277 | M7: 0.06483086 | N7: 0.51478261 | O7: 1
A8: C4 | B8: free_form_10d | C8: 575 | D8: 1.1308527 | E8: 0.89187138 | F8: 0.85565217 | G8: 1 | H8: 0.13267197 | I8: 0.13065226 | J8: 0.99304348 | K8: 1 | L8: 0.98064338 | M8: 0.69132878 | N8: 0.79652174 | O8: 1
A9: C5 | B9: candidate_selection | C9: 575 | D9: 0.57026885 | E9: 0.28218806 | F9: 0.61913043 | G9: 1 | H9: 0.12812041 | I9: 0.11901649 | J9: 0.95478261 | K9: 1 | L9: 0.4046401 | M9: 0.098978989 | N9: 0.54608696 | O9: 1
A10: C5 | B10: free_form_10d | C10: 557 | D10: 0.93161472 | E10: 0.87544054 | F10: 0.77199282 | G10: 1 | H10: 0.10045887 | I10: 0.096032381 | J10: 0.96050269 | K10: 1 | L10: 0.83238329 | M10: 0.59277789 | N10: 0.74147217 | O10: 1
A11: C6 | B11: candidate_selection | C11: 575 | D11: 0.56204636 | E11: 0.28218806 | F11: 0.60695652 | G11: 1 | H11: 0.11064924 | I11: 0.087368589 | J11: 0.9373913 | K11: 1 | L11: 0.42177443 | M11: 0.11480098 | N11: 0.54782609 | O11: 1
A12: C6 | B12: free_form_10d | C12: 575 | D12: 1.1311019 | E12: 0.89187138 | F12: 0.85565217 | G12: 1 | H12: 0.16557804 | I12: 0.16236038 | J12: 0.99652174 | K12: 1 | L12: 0.95611759 | M12: 0.6728615 | N12: 0.8 | O12: 1
A13: C6X | B13: candidate_selection | C13: 575 | D13: 0.52751836 | E13: 0.19649361 | F13: 0.57217391 | G13: 1 | H13: 0.097591032 | I13: 0.076475569 | J13: 0.90956522 | K13: 1 | L13: 0.39899899 | M13: 0.073779485 | N13: 0.52869565 | O13: 1
A14: C6X | B14: free_form_10d | C14: 575 | D14: 1.0594591 | E14: 0.89187138 | F14: 0.82782609 | G14: 1 | H14: 0.13849209 | I14: 0.13140495 | J14: 0.99130435 | K14: 1 | L14: 0.90655559 | M14: 0.63668626 | N14: 0.77565217 | O14: 1
A15: C7 | B15: candidate_selection | C15: 575 | D15: 0.58327923 | E15: 0.28218806 | F15: 0.63130435 | G15: 1 | H15: 0.12936562 | I15: 0.12021108 | J15: 0.96 | K15: 1 | L15: 0.42668995 | M15: 0.12909112 | N15: 0.56 | O15: 1
A16: C7 | B16: free_form_10d | C16: 574 | D16: 1.0039093 | E16: 0.87544054 | F16: 0.76829268 | G16: 1 | H16: 0.13614607 | I16: 0.12378602 | J16: 0.95993031 | K16: 1 | L16: 0.92013108 | M16: 0.63373686 | N16: 0.7456446 | O16: 1
A17: C8 | B17: candidate_selection | C17: 575 | D17: 0.55533533 | E17: 0.19649361 | F17: 0.56 | G17: 1 | H17: 0.096353518 | I17: 0.077772528 | J17: 0.89217391 | K17: 1 | L17: 0.44872374 | M17: 0.073779485 | N17: 0.53217391 | O17: 1
A18: C8 | B18: free_form_10d | C18: 575 | D18: 0.89166204 | E18: 0.6749064 | F18: 0.71304348 | G18: 1 | H18: 0.14223823 | I18: 0.13031156 | J18: 0.97391304 | K18: 1 | L18: 0.80058058 | M18: 0.45895988 | N18: 0.68347826 | O18: 1
A21: 입력 2: frozen_outputs/analysis/paper_repro/03_output_contract_diagnostics/ablation/IC-a/ICa_gpt54mini_p50_live_seed1/global_mean_vector_null_same_policy_candidate_mean/ablation_policy_summary.csv
A22: 파일 크기(bytes) | B22: 2799 | C22: 생산 코드 | D22: src/credit_recourse/analysis/llm_action_budget_ablation.py | E22: SHA256 | F22: CB8F6230C18B22FF7CBD6EE3818CF0ADA685A47AB8AA0F51F1A71927D81209B4 | G22: 읽기 상태 | H22: OK
A23: policy | B23: mode | C23: n_rows | D23: mean_delta_R_score_alpha | E23: median_delta_R_score_alpha | F23: positive_fraction_alpha | G23: valid_fraction_alpha | H23: mean_delta_R_score_beta | I23: median_delta_R_score_beta | J23: positive_fraction_beta | K23: valid_fraction_beta | L23: mean_delta_R_score_gamma | M23: median_delta_R_score_gamma | N23: positive_fraction_gamma | O23: valid_fraction_gamma
A24: C4 | B24: candidate_selection | C24: 575 | D24: 0.5203648 | E24: 0.19649361 | F24: 0.56869565 | G24: 1 | H24: 0.1050754 | I24: 0.083211833 | J24: 0.91478261 | K24: 1 | L24: 0.38433277 | M24: 0.06483086 | N24: 0.51478261 | O24: 1
A25: C4 | B25: free_form_10d | C25: 575 | D25: 1.1308527 | E25: 0.89187138 | F25: 0.85565217 | G25: 1 | H25: 0.13267197 | I25: 0.13065226 | J25: 0.99304348 | K25: 1 | L25: 0.98064338 | M25: 0.69132878 | N25: 0.79652174 | O25: 1
A26: C5 | B26: candidate_selection | C26: 575 | D26: 0.57026885 | E26: 0.28218806 | F26: 0.61913043 | G26: 1 | H26: 0.12812041 | I26: 0.11901649 | J26: 0.95478261 | K26: 1 | L26: 0.4046401 | M26: 0.098978989 | N26: 0.54608696 | O26: 1
A27: C5 | B27: free_form_10d | C27: 557 | D27: 0.93161472 | E27: 0.87544054 | F27: 0.77199282 | G27: 1 | H27: 0.10045887 | I27: 0.096032381 | J27: 0.96050269 | K27: 1 | L27: 0.83238329 | M27: 0.59277789 | N27: 0.74147217 | O27: 1
A28: C6 | B28: candidate_selection | C28: 575 | D28: 0.56204636 | E28: 0.28218806 | F28: 0.60695652 | G28: 1 | H28: 0.11064924 | I28: 0.087368589 | J28: 0.9373913 | K28: 1 | L28: 0.42177443 | M28: 0.11480098 | N28: 0.54782609 | O28: 1
A29: C6 | B29: free_form_10d | C29: 575 | D29: 0.42404803 | E29: 0.14214537 | F29: 0.53043478 | G29: 1 | H29: 0.062161056 | I29: 0.060812127 | J29: 0.99652174 | K29: 1 | L29: 0.36680102 | M29: 0.095162637 | N29: 0.54608696 | O29: 1
A30: C6X | B30: candidate_selection | C30: 575 | D30: 0.52751836 | E30: 0.19649361 | F30: 0.57217391 | G30: 1 | H30: 0.097591032 | I30: 0.076475569 | J30: 0.90956522 | K30: 1 | L30: 0.39899899 | M30: 0.073779485 | N30: 0.52869565 | O30: 1
A31: C6X | B31: free_form_10d | C31: 575 | D31: 1.0594591 | E31: 0.89187138 | F31: 0.82782609 | G31: 1 | H31: 0.13849209 | I31: 0.13140495 | J31: 0.99130435 | K31: 1 | L31: 0.90655559 | M31: 0.63668626 | N31: 0.77565217 | O31: 1
A32: C7 | B32: candidate_selection | C32: 575 | D32: 0.58327923 | E32: 0.28218806 | F32: 0.63130435 | G32: 1 | H32: 0.12936562 | I32: 0.12021108 | J32: 0.96 | K32: 1 | L32: 0.42668995 | M32: 0.12909112 | N32: 0.56 | O32: 1
A33: C7 | B33: free_form_10d | C33: 574 | D33: 1.0039093 | E33: 0.87544054 | F33: 0.76829268 | G33: 1 | H33: 0.13614607 | I33: 0.12378602 | J33: 0.95993031 | K33: 1 | L33: 0.92013108 | M33: 0.63373686 | N33: 0.7456446 | O33: 1
A34: C8 | B34: candidate_selection | C34: 575 | D34: 0.55533533 | E34: 0.19649361 | F34: 0.56 | G34: 1 | H34: 0.096353518 | I34: 0.077772528 | J34: 0.89217391 | K34: 1 | L34: 0.44872374 | M34: 0.073779485 | N34: 0.53217391 | O34: 1
A35: C8 | B35: free_form_10d | C35: 575 | D35: 0.89166204 | E35: 0.6749064 | F35: 0.71304348 | G35: 1 | H35: 0.14223823 | I35: 0.13031156 | J35: 0.97391304 | K35: 1 | L35: 0.80058058 | M35: 0.45895988 | N35: 0.68347826 | O35: 1
A38: 입력 3: frozen_outputs/analysis/paper_repro/03_output_contract_diagnostics/ablation/IC-a/ICa_gpt54mini_p50_live_seed1/l1_rescale_same_policy_candidate_mean/ablation_policy_summary.csv
A39: 파일 크기(bytes) | B39: 2797 | C39: 생산 코드 | D39: src/credit_recourse/analysis/llm_action_budget_ablation.py | E39: SHA256 | F39: 8192BC1EC5E6F31E7C77D92A93B74130292376CCD4590DC5B38E4E7EF835A9CA | G39: 읽기 상태 | H39: OK
A40: policy | B40: mode | C40: n_rows | D40: mean_delta_R_score_alpha | E40: median_delta_R_score_alpha | F40: positive_fraction_alpha | G40: valid_fraction_alpha | H40: mean_delta_R_score_beta | I40: median_delta_R_score_beta | J40: positive_fraction_beta | K40: valid_fraction_beta | L40: mean_delta_R_score_gamma | M40: median_delta_R_score_gamma | N40: positive_fraction_gamma | O40: valid_fraction_gamma
A41: C4 | B41: candidate_selection | C41: 575 | D41: 0.5203648 | E41: 0.19649361 | F41: 0.56869565 | G41: 1 | H41: 0.1050754 | I41: 0.083211833 | J41: 0.91478261 | K41: 1 | L41: 0.38433277 | M41: 0.06483086 | N41: 0.51478261 | O41: 1
A42: C4 | B42: free_form_10d | C42: 575 | D42: 1.1308527 | E42: 0.89187138 | F42: 0.85565217 | G42: 1 | H42: 0.13267197 | I42: 0.13065226 | J42: 0.99304348 | K42: 1 | L42: 0.98064338 | M42: 0.69132878 | N42: 0.79652174 | O42: 1
A43: C5 | B43: candidate_selection | C43: 575 | D43: 0.57026885 | E43: 0.28218806 | F43: 0.61913043 | G43: 1 | H43: 0.12812041 | I43: 0.11901649 | J43: 0.95478261 | K43: 1 | L43: 0.4046401 | M43: 0.098978989 | N43: 0.54608696 | O43: 1
A44: C5 | B44: free_form_10d | C44: 557 | D44: 0.93161472 | E44: 0.87544054 | F44: 0.77199282 | G44: 1 | H44: 0.10045887 | I44: 0.096032381 | J44: 0.96050269 | K44: 1 | L44: 0.83238329 | M44: 0.59277789 | N44: 0.74147217 | O44: 1
A45: C6 | B45: candidate_selection | C45: 575 | D45: 0.56204636 | E45: 0.28218806 | F45: 0.60695652 | G45: 1 | H45: 0.11064924 | I45: 0.087368589 | J45: 0.9373913 | K45: 1 | L45: 0.42177443 | M45: 0.11480098 | N45: 0.54782609 | O45: 1
...

Sheet CHART_DATA
A1: F7 · 그림 데이터
A2: 실제 실행 산출물과 연결된 데이터입니다. 차트는 이 시트의 값을 참조하므로 Excel에서 직접 편집할 수 있습니다.
A4: source_file × policy × mode | B4: mean_delta_R_score_alpha
A5: data/analysis/paper_repro/03_output_contract_diagnostics/ablation/IC-a/ICa_gpt54mini_p50_live_seed1/global_mean_vector_null_native/ablation_policy_summary.csv | C4 | candidate_selection | B5: ='SOURCE'!D7
A6: data/analysis/paper_repro/03_output_contract_diagnostics/ablation/IC-a/ICa_gpt54mini_p50_live_seed1/global_mean_vector_null_native/ablation_policy_summary.csv | C4 | free_form_10d | B6: ='SOURCE'!D8
A7: data/analysis/paper_repro/03_output_contract_diagnostics/ablation/IC-a/ICa_gpt54mini_p50_live_seed1/global_mean_vector_null_native/ablation_policy_summary.csv | C6 | candidate_selection | B7: ='SOURCE'!D11
A8: data/analysis/paper_repro/03_output_contract_diagnostics/ablation/IC-a/ICa_gpt54mini_p50_live_seed1/global_mean_vector_null_native/ablation_policy_summary.csv | C6 | free_form_10d | B8: ='SOURCE'!D12
A9: data/analysis/paper_repro/03_output_contract_diagnostics/ablation/IC-a/ICa_gpt54mini_p50_live_seed1/global_mean_vector_null_same_policy_candidate_mean/ablation_policy_summary.csv | C4 | candidate_selection | B9: ='SOURCE'!D24
A10: data/analysis/paper_repro/03_output_contract_diagnostics/ablation/IC-a/ICa_gpt54mini_p50_live_seed1/global_mean_vector_null_same_policy_candidate_mean/ablation_policy_summary.csv | C4 | free_form_10d | B10: ='SOURCE'!D25
A11: data/analysis/paper_repro/03_output_contract_diagnostics/ablation/IC-a/ICa_gpt54mini_p50_live_seed1/global_mean_vector_null_same_policy_candidate_mean/ablation_policy_summary.csv | C6 | candidate_selection | B11: ='SOURCE'!D28
A12: data/analysis/paper_repro/03_output_contract_diagnostics/ablation/IC-a/ICa_gpt54mini_p50_live_seed1/global_mean_vector_null_same_policy_candidate_mean/ablation_policy_summary.csv | C6 | free_form_10d | B12: ='SOURCE'!D29
A13: data/analysis/paper_repro/03_output_contract_diagnostics/ablation/IC-a/ICa_gpt54mini_p50_live_seed1/l1_rescale_same_policy_candidate_mean/ablation_policy_summary.csv | C4 | candidate_selection | B13: ='SOURCE'!D41
A14: data/analysis/paper_repro/03_output_contract_diagnostics/ablation/IC-a/ICa_gpt54mini_p50_live_seed1/l1_rescale_same_policy_candidate_mean/ablation_policy_summary.csv | C4 | free_form_10d | B14: ='SOURCE'!D42
A15: data/analysis/paper_repro/03_output_contract_diagnostics/ablation/IC-a/ICa_gpt54mini_p50_live_seed1/l1_rescale_same_policy_candidate_mean/ablation_policy_summary.csv | C6 | candidate_selection | B15: ='SOURCE'!D45
A16: data/analysis/paper_repro/03_output_contract_diagnostics/ablation/IC-a/ICa_gpt54mini_p50_live_seed1/l1_rescale_same_policy_candidate_mean/ablation_policy_summary.csv | C6 | free_form_10d | B16: ='SOURCE'!D46
A17: data/analysis/paper_repro/03_output_contract_diagnostics/ablation/IC-a/ICa_gpt54mini_p50_live_seed1/nearest_candidate_projection_native/ablation_policy_summary.csv | C4 | candidate_selection | B17: ='SOURCE'!D58
A18: data/analysis/paper_repro/03_output_contract_diagnostics/ablation/IC-a/ICa_gpt54mini_p50_live_seed1/nearest_candidate_projection_native/ablation_policy_summary.csv | C4 | free_form_10d | B18: ='SOURCE'!D59
A19: data/analysis/paper_repro/03_output_contract_diagnostics/ablation/IC-a/ICa_gpt54mini_p50_live_seed1/nearest_candidate_projection_native/ablation_policy_summary.csv | C6 | candidate_selection | B19: ='SOURCE'!D62
A20: data/analysis/paper_repro/03_output_contract_diagnostics/ablation/IC-a/ICa_gpt54mini_p50_live_seed1/nearest_candidate_projection_native/ablation_policy_summary.csv | C6 | free_form_10d | B20: ='SOURCE'!D63
A21: data/analysis/paper_repro/03_output_contract_diagnostics/ablation/IC-a/ICa_gpt54mini_p50_live_seed1/row_shuffle_vector_null_native/ablation_policy_summary.csv | C4 | candidate_selection | B21: ='SOURCE'!D75
A22: data/analysis/paper_repro/03_output_contract_diagnostics/ablation/IC-a/ICa_gpt54mini_p50_live_seed1/row_shuffle_vector_null_native/ablation_policy_summary.csv | C4 | free_form_10d | B22: ='SOURCE'!D76
A23: data/analysis/paper_repro/03_output_contract_diagnostics/ablation/IC-a/ICa_gpt54mini_p50_live_seed1/row_shuffle_vector_null_native/ablation_policy_summary.csv | C6 | candidate_selection | B23: ='SOURCE'!D79
A24: data/analysis/paper_repro/03_output_contract_diagnostics/ablation/IC-a/ICa_gpt54mini_p50_live_seed1/row_shuffle_vector_null_native/ablation_policy_summary.csv | C6 | free_form_10d | B24: ='SOURCE'!D80
A25: data/analysis/paper_repro/03_output_contract_diagnostics/ablation/IC-a/ICa_gpt54mini_p50_live_seed1/row_shuffle_vector_null_native_industry/ablation_policy_summary.csv | C4 | candidate_selection | B25: ='SOURCE'!D92
A26: data/analysis/paper_repro/03_output_contract_diagnostics/ablation/IC-a/ICa_gpt54mini_p50_live_seed1/row_shuffle_vector_null_native_industry/ablation_policy_summary.csv | C4 | free_form_10d | B26: ='SOURCE'!D93
A27: data/analysis/paper_repro/03_output_contract_diagnostics/ablation/IC-a/ICa_gpt54mini_p50_live_seed1/row_shuffle_vector_null_native_industry/ablation_policy_summary.csv | C6 | candidate_selection | B27: ='SOURCE'!D96
A28: data/analysis/paper_repro/03_output_contract_diagnostics/ablation/IC-a/ICa_gpt54mini_p50_live_seed1/row_shuffle_vector_null_native_industry/ablation_policy_summary.csv | C6 | free_form_10d | B28: ='SOURCE'!D97
A29: data/analysis/paper_repro/03_output_contract_diagnostics/ablation/IC-a/ICa_gpt54mini_p50_live_seed1/row_shuffle_vector_null_native_rating_band/ablation_policy_summary.csv | C4 | candidate_selection | B29: ='SOURCE'!D109
A30: data/analysis/paper_repro/03_output_contract_diagnostics/ablation/IC-a/ICa_gpt54mini_p50_live_seed1/row_shuffle_vector_null_native_rating_band/ablation_policy_summary.csv | C4 | free_form_10d | B30: ='SOURCE'!D110
A31: data/analysis/paper_repro/03_output_contract_diagnostics/ablation/IC-a/ICa_gpt54mini_p50_live_seed1/row_shuffle_vector_null_native_rating_band/ablation_policy_summary.csv | C6 | candidate_selection | B31: ='SOURCE'!D113
A32: data/analysis/paper_repro/03_output_contract_diagnostics/ablation/IC-a/ICa_gpt54mini_p50_live_seed1/row_shuffle_vector_null_native_rating_band/ablation_policy_summary.csv | C6 | free_form_10d | B32: ='SOURCE'!D114
A33: data/analysis/paper_repro/03_output_contract_diagnostics/ablation/IC-a/ICa_gpt54mini_p50_live_seed1/row_shuffle_vector_null_same_policy_candidate_mean/ablation_policy_summary.csv | C4 | candidate_selection | B33: ='SOURCE'!D126
A34: data/analysis/paper_repro/03_output_contract_diagnostics/ablation/IC-a/ICa_gpt54mini_p50_live_seed1/row_shuffle_vector_null_same_policy_candidate_mean/ablation_policy_summary.csv | C4 | free_form_10d | B34: ='SOURCE'!D127
A35: data/analysis/paper_repro/03_output_contract_diagnostics/ablation/IC-a/ICa_gpt54mini_p50_live_seed1/row_shuffle_vector_null_same_policy_candidate_mean/ablation_policy_summary.csv | C6 | candidate_selection | B35: ='SOURCE'!D130
A36: data/analysis/paper_repro/03_output_contract_diagnostics/ablation/IC-a/ICa_gpt54mini_p50_live_seed1/row_shuffle_vector_null_same_policy_candidate_mean/ablation_policy_summary.csv | C6 | free_form_10d | B36: ='SOURCE'!D131
A37: data/analysis/paper_repro/03_output_contract_diagnostics/ablation/IC-b/ICb_gpt54mini_p50_live_seed1/global_mean_vector_null_native/ablation_policy_summary.csv | C4 | candidate_selection | B37: ='SOURCE'!D143
A38: data/analysis/paper_repro/03_output_contract_diagnostics/ablation/IC-b/ICb_gpt54mini_p50_live_seed1/global_mean_vector_null_native/ablation_policy_summary.csv | C4 | free_form_10d | B38: ='SOURCE'!D144
A39: data/analysis/paper_repro/03_output_contract_diagnostics/ablation/IC-b/ICb_gpt54mini_p50_live_seed1/global_mean_vector_null_native/ablation_policy_summary.csv | C6 | candidate_selection | B39: ='SOURCE'!D147
A40: data/analysis/paper_repro/03_output_contract_diagnostics/ablation/IC-b/ICb_gpt54mini_p50_live_seed1/global_mean_vector_null_native/ablation_policy_summary.csv | C6 | free_form_10d | B40: ='SOURCE'!D148
A41: data/analysis/paper_repro/03_output_contract_diagnostics/ablation/IC-b/ICb_gpt54mini_p50_live_seed1/global_mean_vector_null_same_policy_candidate_mean/ablation_policy_summary.csv | C4 | candidate_selection | B41: ='SOURCE'!D160
...

Sheet CHART
A1: F7 · 그림 7. 기업별 연결·행동크기·재무항목 조합에 따른 정책가치(IC-b, Oracle-α)
A2: CHART_DATA를 참조하는 편집 가능한 Excel 차트입니다.
